Workbook

Sheet Chat Transcript
B1: Please copy the transcript from Salesforce starting at the line that says "Chat Started"
C2: 0.0013888889
A3: Line # | B3: Chat Transcript | C3: Time difference | D3: Evaluator's notes | E3: Time | F3: Hour | G3: Minute | H3: Second | I3: Line ID | J3: Blank | K3: ID | L3: Time | M3: Difference
A4: 1 | C4: =IF(J4="No",M4,"") | E4: =IF(ISERROR(LEFT(B4,FIND(")",B4))),"",LEFT(B4,FIND(")",B4))) | F4: =IF(ISERROR(MID($E4,FIND("h",$E4)-2,2)+0),0,MID($E4,FIND("h",$E4)-2,2)+0) -> 0 | G4: =IF(ISERROR(MID($E4,FIND("m",$E4)-2,2)+0),0,MID($E4,FIND("m",$E4)-2,2)+0) -> 0 | H4: =IF(ISERROR(MID($E4,FIND("s",$E4)-2,2)+0),0,MID($E4,FIND("s",$E4)-2,2)+0) -> 0 | I4: 1 | J4: =IF(AND(F4=0,G4=0),"Yes","No") -> Yes | K4: No1 | L4: =TIME(F4,G4,H4) -> 0 | M4: =INDEX(L:L,MATCH("No"&I4,K:K,0)) -> 0
A5: =A4+1 -> 2 | C5: =IF(J5="No",M5,"") | E5: =IF(ISERROR(LEFT(B5,FIND(")",B5))),"",LEFT(B5,FIND(")",B5))) | F5: =IF(ISERROR(MID($E5,FIND("h",$E5)-2,2)+0),0,MID($E5,FIND("h",$E5)-2,2)+0) -> 0 | G5: =IF(ISERROR(MID($E5,FIND("m",$E5)-2,2)+0),0,MID($E5,FIND("m",$E5)-2,2)+0) -> 0 | H5: =IF(ISERROR(MID($E5,FIND("s",$E5)-2,2)+0),0,MID($E5,FIND("s",$E5)-2,2)+0) -> 0 | I5: =IF(J5="No",I4+1,I4) -> 1 | J5: =IF(AND(F5=0,G5=0),"Yes","No") -> Yes | K5: =IF(J5="No",J5&I5,"") | L5: =TIME(F5,G5,H5) -> 0 | M5: =IF(I5=1,0,INDEX(L:L,MATCH("No"&I5,K:K,0))-INDEX(L:L,MATCH("No"&I5-1,K:K,0))) -> 0
A6: =A5+1 -> 3 | C6: =IF(J6="No",M6,"") | E6: =IF(ISERROR(LEFT(B6,FIND(")",B6))),"",LEFT(B6,FIND(")",B6))) | F6: =IF(ISERROR(MID($E6,FIND("h",$E6)-2,2)+0),0,MID($E6,FIND("h",$E6)-2,2)+0) -> 0 | G6: =IF(ISERROR(MID($E6,FIND("m",$E6)-2,2)+0),0,MID($E6,FIND("m",$E6)-2,2)+0) -> 0 | H6: =IF(ISERROR(MID($E6,FIND("s",$E6)-2,2)+0),0,MID($E6,FIND("s",$E6)-2,2)+0) -> 0 | I6: =IF(J6="No",I5+1,I5) -> 1 | J6: =IF(AND(F6=0,G6=0),"Yes","No") -> Yes | K6: =IF(J6="No",J6&I6,"") | L6: =TIME(F6,G6,H6) -> 0 | M6: =IF(I6=1,0,INDEX(L:L,MATCH("No"&I6,K:K,0))-INDEX(L:L,MATCH("No"&I6-1,K:K,0))) -> 0
A7: =A6+1 -> 4 | C7: =IF(J7="No",M7,"") | E7: =IF(ISERROR(LEFT(B7,FIND(")",B7))),"",LEFT(B7,FIND(")",B7))) | F7: =IF(ISERROR(MID($E7,FIND("h",$E7)-2,2)+0),0,MID($E7,FIND("h",$E7)-2,2)+0) -> 0 | G7: =IF(ISERROR(MID($E7,FIND("m",$E7)-2,2)+0),0,MID($E7,FIND("m",$E7)-2,2)+0) -> 0 | H7: =IF(ISERROR(MID($E7,FIND("s",$E7)-2,2)+0),0,MID($E7,FIND("s",$E7)-2,2)+0) -> 0 | I7: =IF(J7="No",I6+1,I6) -> 1 | J7: =IF(AND(F7=0,G7=0),"Yes","No") -> Yes | K7: =IF(J7="No",J7&I7,"") | L7: =TIME(F7,G7,H7) -> 0 | M7: =IF(I7=1,0,INDEX(L:L,MATCH("No"&I7,K:K,0))-INDEX(L:L,MATCH("No"&I7-1,K:K,0))) -> 0
A8: =A7+1 -> 5 | C8: =IF(J8="No",M8,"") | E8: =IF(ISERROR(LEFT(B8,FIND(")",B8))),"",LEFT(B8,FIND(")",B8))) | F8: =IF(ISERROR(MID($E8,FIND("h",$E8)-2,2)+0),0,MID($E8,FIND("h",$E8)-2,2)+0) -> 0 | G8: =IF(ISERROR(MID($E8,FIND("m",$E8)-2,2)+0),0,MID($E8,FIND("m",$E8)-2,2)+0) -> 0 | H8: =IF(ISERROR(MID($E8,FIND("s",$E8)-2,2)+0),0,MID($E8,FIND("s",$E8)-2,2)+0) -> 0 | I8: =IF(J8="No",I7+1,I7) -> 1 | J8: =IF(AND(F8=0,G8=0),"Yes","No") -> Yes | K8: =IF(J8="No",J8&I8,"") | L8: =TIME(F8,G8,H8) -> 0 | M8: =IF(I8=1,0,INDEX(L:L,MATCH("No"&I8,K:K,0))-INDEX(L:L,MATCH("No"&I8-1,K:K,0))) -> 0
A9: =A8+1 -> 6 | C9: =IF(J9="No",M9,"") | E9: =IF(ISERROR(LEFT(B9,FIND(")",B9))),"",LEFT(B9,FIND(")",B9))) | F9: =IF(ISERROR(MID($E9,FIND("h",$E9)-2,2)+0),0,MID($E9,FIND("h",$E9)-2,2)+0) -> 0 | G9: =IF(ISERROR(MID($E9,FIND("m",$E9)-2,2)+0),0,MID($E9,FIND("m",$E9)-2,2)+0) -> 0 | H9: =IF(ISERROR(MID($E9,FIND("s",$E9)-2,2)+0),0,MID($E9,FIND("s",$E9)-2,2)+0) -> 0 | I9: =IF(J9="No",I8+1,I8) -> 1 | J9: =IF(AND(F9=0,G9=0),"Yes","No") -> Yes | K9: =IF(J9="No",J9&I9,"") | L9: =TIME(F9,G9,H9) -> 0 | M9: =IF(I9=1,0,INDEX(L:L,MATCH("No"&I9,K:K,0))-INDEX(L:L,MATCH("No"&I9-1,K:K,0))) -> 0
A10: =A9+1 -> 7 | C10: =IF(J10="No",M10,"") | E10: =IF(ISERROR(LEFT(B10,FIND(")",B10))),"",LEFT(B10,FIND(")",B10))) | F10: =IF(ISERROR(MID($E10,FIND("h",$E10)-2,2)+0),0,MID($E10,FIND("h",$E10)-2,2)+0) -> 0 | G10: =IF(ISERROR(MID($E10,FIND("m",$E10)-2,2)+0),0,MID($E10,FIND("m",$E10)-2,2)+0) -> 0 | H10: =IF(ISERROR(MID($E10,FIND("s",$E10)-2,2)+0),0,MID($E10,FIND("s",$E10)-2,2)+0) -> 0 | I10: =IF(J10="No",I9+1,I9) -> 1 | J10: =IF(AND(F10=0,G10=0),"Yes","No") -> Yes | K10: =IF(J10="No",J10&I10,"") | L10: =TIME(F10,G10,H10) -> 0 | M10: =IF(I10=1,0,INDEX(L:L,MATCH("No"&I10,K:K,0))-INDEX(L:L,MATCH("No"&I10-1,K:K,0))) -> 0
A11: =A10+1 -> 8 | C11: =IF(J11="No",M11,"") | E11: =IF(ISERROR(LEFT(B11,FIND(")",B11))),"",LEFT(B11,FIND(")",B11))) | F11: =IF(ISERROR(MID($E11,FIND("h",$E11)-2,2)+0),0,MID($E11,FIND("h",$E11)-2,2)+0) -> 0 | G11: =IF(ISERROR(MID($E11,FIND("m",$E11)-2,2)+0),0,MID($E11,FIND("m",$E11)-2,2)+0) -> 0 | H11: =IF(ISERROR(MID($E11,FIND("s",$E11)-2,2)+0),0,MID($E11,FIND("s",$E11)-2,2)+0) -> 0 | I11: =IF(J11="No",I10+1,I10) -> 1 | J11: =IF(AND(F11=0,G11=0),"Yes","No") -> Yes | K11: =IF(J11="No",J11&I11,"") | L11: =TIME(F11,G11,H11) -> 0 | M11: =IF(I11=1,0,INDEX(L:L,MATCH("No"&I11,K:K,0))-INDEX(L:L,MATCH("No"&I11-1,K:K,0))) -> 0
A12: =A11+1 -> 9 | C12: =IF(J12="No",M12,"") | E12: =IF(ISERROR(LEFT(B12,FIND(")",B12))),"",LEFT(B12,FIND(")",B12))) | F12: =IF(ISERROR(MID($E12,FIND("h",$E12)-2,2)+0),0,MID($E12,FIND("h",$E12)-2,2)+0) -> 0 | G12: =IF(ISERROR(MID($E12,FIND("m",$E12)-2,2)+0),0,MID($E12,FIND("m",$E12)-2,2)+0) -> 0 | H12: =IF(ISERROR(MID($E12,FIND("s",$E12)-2,2)+0),0,MID($E12,FIND("s",$E12)-2,2)+0) -> 0 | I12: =IF(J12="No",I11+1,I11) -> 1 | J12: =IF(AND(F12=0,G12=0),"Yes","No") -> Yes | K12: =IF(J12="No",J12&I12,"") | L12: =TIME(F12,G12,H12) -> 0 | M12: =IF(I12=1,0,INDEX(L:L,MATCH("No"&I12,K:K,0))-INDEX(L:L,MATCH("No"&I12-1,K:K,0))) -> 0
A13: =A12+1 -> 10 | C13: =IF(J13="No",M13,"") | E13: =IF(ISERROR(LEFT(B13,FIND(")",B13))),"",LEFT(B13,FIND(")",B13))) | F13: =IF(ISERROR(MID($E13,FIND("h",$E13)-2,2)+0),0,MID($E13,FIND("h",$E13)-2,2)+0) -> 0 | G13: =IF(ISERROR(MID($E13,FIND("m",$E13)-2,2)+0),0,MID($E13,FIND("m",$E13)-2,2)+0) -> 0 | H13: =IF(ISERROR(MID($E13,FIND("s",$E13)-2,2)+0),0,MID($E13,FIND("s",$E13)-2,2)+0) -> 0 | I13: =IF(J13="No",I12+1,I12) -> 1 | J13: =IF(AND(F13=0,G13=0),"Yes","No") -> Yes | K13: =IF(J13="No",J13&I13,"") | L13: =TIME(F13,G13,H13) -> 0 | M13: =IF(I13=1,0,INDEX(L:L,MATCH("No"&I13,K:K,0))-INDEX(L:L,MATCH("No"&I13-1,K:K,0))) -> 0
A14: =A13+1 -> 11 | C14: =IF(J14="No",M14,"") | E14: =IF(ISERROR(LEFT(B14,FIND(")",B14))),"",LEFT(B14,FIND(")",B14))) | F14: =IF(ISERROR(MID($E14,FIND("h",$E14)-2,2)+0),0,MID($E14,FIND("h",$E14)-2,2)+0) -> 0 | G14: =IF(ISERROR(MID($E14,FIND("m",$E14)-2,2)+0),0,MID($E14,FIND("m",$E14)-2,2)+0) -> 0 | H14: =IF(ISERROR(MID($E14,FIND("s",$E14)-2,2)+0),0,MID($E14,FIND("s",$E14)-2,2)+0) -> 0 | I14: =IF(J14="No",I13+1,I13) -> 1 | J14: =IF(AND(F14=0,G14=0),"Yes","No") -> Yes | K14: =IF(J14="No",J14&I14,"") | L14: =TIME(F14,G14,H14) -> 0 | M14: =IF(I14=1,0,INDEX(L:L,MATCH("No"&I14,K:K,0))-INDEX(L:L,MATCH("No"&I14-1,K:K,0))) -> 0
A15: =A14+1 -> 12 | C15: =IF(J15="No",M15,"") | E15: =IF(ISERROR(LEFT(B15,FIND(")",B15))),"",LEFT(B15,FIND(")",B15))) | F15: =IF(ISERROR(MID($E15,FIND("h",$E15)-2,2)+0),0,MID($E15,FIND("h",$E15)-2,2)+0) -> 0 | G15: =IF(ISERROR(MID($E15,FIND("m",$E15)-2,2)+0),0,MID($E15,FIND("m",$E15)-2,2)+0) -> 0 | H15: =IF(ISERROR(MID($E15,FIND("s",$E15)-2,2)+0),0,MID($E15,FIND("s",$E15)-2,2)+0) -> 0 | I15: =IF(J15="No",I14+1,I14) -> 1 | J15: =IF(AND(F15=0,G15=0),"Yes","No") -> Yes | K15: =IF(J15="No",J15&I15,"") | L15: =TIME(F15,G15,H15) -> 0 | M15: =IF(I15=1,0,INDEX(L:L,MATCH("No"&I15,K:K,0))-INDEX(L:L,MATCH("No"&I15-1,K:K,0))) -> 0
A16: =A15+1 -> 13 | C16: =IF(J16="No",M16,"") | E16: =IF(ISERROR(LEFT(B16,FIND(")",B16))),"",LEFT(B16,FIND(")",B16))) | F16: =IF(ISERROR(MID($E16,FIND("h",$E16)-2,2)+0),0,MID($E16,FIND("h",$E16)-2,2)+0) -> 0 | G16: =IF(ISERROR(MID($E16,FIND("m",$E16)-2,2)+0),0,MID($E16,FIND("m",$E16)-2,2)+0) -> 0 | H16: =IF(ISERROR(MID($E16,FIND("s",$E16)-2,2)+0),0,MID($E16,FIND("s",$E16)-2,2)+0) -> 0 | I16: =IF(J16="No",I15+1,I15) -> 1 | J16: =IF(AND(F16=0,G16=0),"Yes","No") -> Yes | K16: =IF(J16="No",J16&I16,"") | L16: =TIME(F16,G16,H16) -> 0 | M16: =IF(I16=1,0,INDEX(L:L,MATCH("No"&I16,K:K,0))-INDEX(L:L,MATCH("No"&I16-1,K:K,0))) -> 0
... A141: =A140+1 -> 138 | C141: =IF(J141="No",M141,"") | E141: =IF(ISERROR(LEFT(B141,FIND(")",B141))),"",LEFT(B141,FIND(")",B141))) | F141: =IF(ISERROR(MID($E141,FIND("h",$E141)-2,2)+0),0,MID($E141,FIND("h",$E141)-2,2)+0) -> 0 | G141: =IF(ISERROR(MID($E141,FIND("m",$E141)-2,2)+0),0,MID($E141,FIND("m",$E141)-2,2)+0) -> 0 | H141: =IF(ISERROR(MID($E141,FIND("s",$E141)-2,2)+0),0,MID($E141,FIND("s",$E141)-2,2)+0) -> 0 | I141: =IF(J141="No",I140+1,I140) -> 1 | J141: =IF(AND(F141=0,G141=0),"Yes","No") -> Yes | K141: =IF(J141="No",J141&I141,"") | L141: =TIME(F141,G141,H141) -> 0 | M141: =IF(I141=1,0,INDEX(L:L,MATCH("No"&I141,K:K,0))-INDEX(L:L,MATCH("No"&I141-1,K:K,0))) -> 0
A142: =A141+1 -> 139 | C142: =IF(J142="No",M142,"") | E142: =IF(ISERROR(LEFT(B142,FIND(")",B142))),"",LEFT(B142,FIND(")",B142))) | F142: =IF(ISERROR(MID($E142,FIND("h",$E142)-2,2)+0),0,MID($E142,FIND("h",$E142)-2,2)+0) -> 0 | G142: =IF(ISERROR(MID($E142,FIND("m",$E142)-2,2)+0),0,MID($E142,FIND("m",$E142)-2,2)+0) -> 0 | H142: =IF(ISERROR(MID($E142,FIND("s",$E142)-2,2)+0),0,MID($E142,FIND("s",$E142)-2,2)+0) -> 0 | I142: =IF(J142="No",I141+1,I141) -> 1 | J142: =IF(G142=0,"Yes","No") -> Yes | K142: =IF(J142="No",J142&I142,"") | L142: =TIME(F142,G142,H142) -> 0 | M142: =IF(I142=1,0,INDEX(L:L,MATCH("No"&I142,K:K,0))-INDEX(L:L,MATCH("No"&I142-1,K:K,0))) -> 0
A143: =A142+1 -> 140 | C143: =IF(J143="No",M143,"") | E143: =IF(ISERROR(LEFT(B143,FIND(")",B143))),"",LEFT(B143,FIND(")",B143))) | F143: =IF(ISERROR(MID($E143,FIND("h",$E143)-2,2)+0),0,MID($E143,FIND("h",$E143)-2,2)+0) -> 0 | G143: =IF(ISERROR(MID($E143,FIND("m",$E143)-2,2)+0),0,MID($E143,FIND("m",$E143)-2,2)+0) -> 0 | H143: =IF(ISERROR(MID($E143,FIND("s",$E143)-2,2)+0),0,MID($E143,FIND("s",$E143)-2,2)+0) -> 0 | I143: =IF(J143="No",I142+1,I142) -> 1 | J143: =IF(G143=0,"Yes","No") -> Yes | K143: =IF(J143="No",J143&I143,"") | L143: =TIME(F143,G143,H143) -> 0 | M143: =IF(I143=1,0,INDEX(L:L,MATCH("No"&I143,K:K,0))-INDEX(L:L,MATCH("No"&I143-1,K:K,0))) -> 0
A144: =A143+1 -> 141 | C144: =IF(J144="No",M144,"") | E144: =IF(ISERROR(LEFT(B144,FIND(")",B144))),"",LEFT(B144,FIND(")",B144))) | F144: =IF(ISERROR(MID($E144,FIND("h",$E144)-2,2)+0),0,MID($E144,FIND("h",$E144)-2,2)+0) -> 0 | G144: =IF(ISERROR(MID($E144,FIND("m",$E144)-2,2)+0),0,MID($E144,FIND("m",$E144)-2,2)+0) -> 0 | H144: =IF(ISERROR(MID($E144,FIND("s",$E144)-2,2)+0),0,MID($E144,FIND("s",$E144)-2,2)+0) -> 0 | I144: =IF(J144="No",I143+1,I143) -> 1 | J144: =IF(G144=0,"Yes","No") -> Yes | K144: =IF(J144="No",J144&I144,"") | L144: =TIME(F144,G144,H144) -> 0 | M144: =IF(I144=1,0,INDEX(L:L,MATCH("No"&I144,K:K,0))-INDEX(L:L,MATCH("No"&I144-1,K:K,0))) -> 0
A145: =A144+1 -> 142 | C145: =IF(J145="No",M145,"") | E145: =IF(ISERROR(LEFT(B145,FIND(")",B145))),"",LEFT(B145,FIND(")",B145))) | F145: =IF(ISERROR(MID($E145,FIND("h",$E145)-2,2)+0),0,MID($E145,FIND("h",$E145)-2,2)+0) -> 0 | G145: =IF(ISERROR(MID($E145,FIND("m",$E145)-2,2)+0),0,MID($E145,FIND("m",$E145)-2,2)+0) -> 0 | H145: =IF(ISERROR(MID($E145,FIND("s",$E145)-2,2)+0),0,MID($E145,FIND("s",$E145)-2,2)+0) -> 0 | I145: =IF(J145="No",I144+1,I144) -> 1 | J145: =IF(G145=0,"Yes","No") -> Yes | K145: =IF(J145="No",J145&I145,"") | L145: =TIME(F145,G145,H145) -> 0 | M145: =IF(I145=1,0,INDEX(L:L,MATCH("No"&I145,K:K,0))-INDEX(L:L,MATCH("No"&I145-1,K:K,0))) -> 0
A146: =A145+1 -> 143 | C146: =IF(J146="No",M146,"") | E146: =IF(ISERROR(LEFT(B146,FIND(")",B146))),"",LEFT(B146,FIND(")",B146))) | F146: =IF(ISERROR(MID($E146,FIND("h",$E146)-2,2)+0),0,MID($E146,FIND("h",$E146)-2,2)+0) -> 0 | G146: =IF(ISERROR(MID($E146,FIND("m",$E146)-2,2)+0),0,MID($E146,FIND("m",$E146)-2,2)+0) -> 0 | H146: =IF(ISERROR(MID($E146,FIND("s",$E146)-2,2)+0),0,MID($E146,FIND("s",$E146)-2,2)+0) -> 0 | I146: =IF(J146="No",I145+1,I145) -> 1 | J146: =IF(G146=0,"Yes","No") -> Yes | K146: =IF(J146="No",J146&I146,"") | L146: =TIME(F146,G146,H146) -> 0 | M146: =IF(I146=1,0,INDEX(L:L,MATCH("No"&I146,K:K,0))-INDEX(L:L,MATCH("No"&I146-1,K:K,0))) -> 0
A147: =A146+1 -> 144 | C147: =IF(J147="No",M147,"") | E147: =IF(ISERROR(LEFT(B147,FIND(")",B147))),"",LEFT(B147,FIND(")",B147))) | F147: =IF(ISERROR(MID($E147,FIND("h",$E147)-2,2)+0),0,MID($E147,FIND("h",$E147)-2,2)+0) -> 0 | G147: =IF(ISERROR(MID($E147,FIND("m",$E147)-2,2)+0),0,MID($E147,FIND("m",$E147)-2,2)+0) -> 0 | H147: =IF(ISERROR(MID($E147,FIND("s",$E147)-2,2)+0),0,MID($E147,FIND("s",$E147)-2,2)+0) -> 0 | I147: =IF(J147="No",I146+1,I146) -> 1 | J147: =IF(G147=0,"Yes","No") -> Yes | K147: =IF(J147="No",J147&I147,"") | L147: =TIME(F147,G147,H147) -> 0 | M147: =IF(I147=1,0,INDEX(L:L,MATCH("No"&I147,K:K,0))-INDEX(L:L,MATCH("No"&I147-1,K:K,0))) -> 0
A148: =A147+1 -> 145 | C148: =IF(J148="No",M148,"") | E148: =IF(ISERROR(LEFT(B148,FIND(")",B148))),"",LEFT(B148,FIND(")",B148))) | F148: =IF(ISERROR(MID($E148,FIND("h",$E148)-2,2)+0),0,MID($E148,FIND("h",$E148)-2,2)+0) -> 0 | G148: =IF(ISERROR(MID($E148,FIND("m",$E148)-2,2)+0),0,MID($E148,FIND("m",$E148)-2,2)+0) -> 0 | H148: =IF(ISERROR(MID($E148,FIND("s",$E148)-2,2)+0),0,MID($E148,FIND("s",$E148)-2,2)+0) -> 0 | I148: =IF(J148="No",I147+1,I147) -> 1 | J148: =IF(G148=0,"Yes","No") -> Yes | K148: =IF(J148="No",J148&I148,"") | L148: =TIME(F148,G148,H148) -> 0 | M148: =IF(I148=1,0,INDEX(L:L,MATCH("No"&I148,K:K,0))-INDEX(L:L,MATCH("No"&I148-1,K:K,0))) -> 0
A149: =A148+1 -> 146 | C149: =IF(J149="No",M149,"") | E149: =IF(ISERROR(LEFT(B149,FIND(")",B149))),"",LEFT(B149,FIND(")",B149))) | F149: =IF(ISERROR(MID($E149,FIND("h",$E149)-2,2)+0),0,MID($E149,FIND("h",$E149)-2,2)+0) -> 0 | G149: =IF(ISERROR(MID($E149,FIND("m",$E149)-2,2)+0),0,MID($E149,FIND("m",$E149)-2,2)+0) -> 0 | H149: =IF(ISERROR(MID($E149,FIND("s",$E149)-2,2)+0),0,MID($E149,FIND("s",$E149)-2,2)+0) -> 0 | I149: =IF(J149="No",I148+1,I148) -> 1 | J149: =IF(G149=0,"Yes","No") -> Yes | K149: =IF(J149="No",J149&I149,"") | L149: =TIME(F149,G149,H149) -> 0 | M149: =IF(I149=1,0,INDEX(L:L,MATCH("No"&I149,K:K,0))-INDEX(L:L,MATCH("No"&I149-1,K:K,0))) -> 0
A150: =A149+1 -> 147 | C150: =IF(J150="No",M150,"") | E150: =IF(ISERROR(LEFT(B150,FIND(")",B150))),"",LEFT(B150,FIND(")",B150))) | F150: =IF(ISERROR(MID($E150,FIND("h",$E150)-2,2)+0),0,MID($E150,FIND("h",$E150)-2,2)+0) -> 0 | G150: =IF(ISERROR(MID($E150,FIND("m",$E150)-2,2)+0),0,MID($E150,FIND("m",$E150)-2,2)+0) -> 0 | H150: =IF(ISERROR(MID($E150,FIND("s",$E150)-2,2)+0),0,MID($E150,FIND("s",$E150)-2,2)+0) -> 0 | I150: =IF(J150="No",I149+1,I149) -> 1 | J150: =IF(G150=0,"Yes","No") -> Yes | K150: =IF(J150="No",J150&I150,"") | L150: =TIME(F150,G150,H150) -> 0 | M150: =IF(I150=1,0,INDEX(L:L,MATCH("No"&I150,K:K,0))-INDEX(L:L,MATCH("No"&I150-1,K:K,0))) -> 0
A151: =A150+1 -> 148 | C151: =IF(J151="No",M151,"") | E151: =IF(ISERROR(LEFT(B151,FIND(")",B151))),"",LEFT(B151,FIND(")",B151))) | F151: =IF(ISERROR(MID($E151,FIND("h",$E151)-2,2)+0),0,MID($E151,FIND("h",$E151)-2,2)+0) -> 0 | G151: =IF(ISERROR(MID($E151,FIND("m",$E151)-2,2)+0),0,MID($E151,FIND("m",$E151)-2,2)+0) -> 0 | H151: =IF(ISERROR(MID($E151,FIND("s",$E151)-2,2)+0),0,MID($E151,FIND("s",$E151)-2,2)+0) -> 0 | I151: =IF(J151="No",I150+1,I150) -> 1 | J151: =IF(G151=0,"Yes","No") -> Yes | K151: =IF(J151="No",J151&I151,"") | L151: =TIME(F151,G151,H151) -> 0 | M151: =IF(I151=1,0,INDEX(L:L,MATCH("No"&I151,K:K,0))-INDEX(L:L,MATCH("No"&I151-1,K:K,0))) -> 0
A152: =A151+1 -> 149 | C152: =IF(J152="No",M152,"") | E152: =IF(ISERROR(LEFT(B152,FIND(")",B152))),"",LEFT(B152,FIND(")",B152))) | F152: =IF(ISERROR(MID($E152,FIND("h",$E152)-2,2)+0),0,MID($E152,FIND("h",$E152)-2,2)+0) -> 0 | G152: =IF(ISERROR(MID($E152,FIND("m",$E152)-2,2)+0),0,MID($E152,FIND("m",$E152)-2,2)+0) -> 0 | H152: =IF(ISERROR(MID($E152,FIND("s",$E152)-2,2)+0),0,MID($E152,FIND("s",$E152)-2,2)+0) -> 0 | I152: =IF(J152="No",I151+1,I151) -> 1 | J152: =IF(G152=0,"Yes","No") -> Yes | K152: =IF(J152="No",J152&I152,"") | L152: =TIME(F152,G152,H152) -> 0 | M152: =IF(I152=1,0,INDEX(L:L,MATCH("No"&I152,K:K,0))-INDEX(L:L,MATCH("No"&I152-1,K:K,0))) -> 0
A153: =A152+1 -> 150 | C153: =IF(J153="No",M153,"") | E153: =IF(ISERROR(LEFT(B153,FIND(")",B153))),"",LEFT(B153,FIND(")",B153))) | F153: =IF(ISERROR(MID($E153,FIND("h",$E153)-2,2)+0),0,MID($E153,FIND("h",$E153)-2,2)+0) -> 0 | G153: =IF(ISERROR(MID($E153,FIND("m",$E153)-2,2)+0),0,MID($E153,FIND("m",$E153)-2,2)+0) -> 0 | H153: =IF(ISERROR(MID($E153,FIND("s",$E153)-2,2)+0),0,MID($E153,FIND("s",$E153)-2,2)+0) -> 0 | I153: =IF(J153="No",I152+1,I152) -> 1 | J153: =IF(G153=0,"Yes","No") -> Yes | K153: =IF(J153="No",J153&I153,"") | L153: =TIME(F153,G153,H153) -> 0 | M153: =IF(I153=1,0,INDEX(L:L,MATCH("No"&I153,K:K,0))-INDEX(L:L,MATCH("No"&I153-1,K:K,0))) -> 0
... A203: =A202+1 -> 200 | C203: =IF(J203="No",M203,"") | E203: =IF(ISERROR(LEFT(B203,FIND(")",B203))),"",LEFT(B203,FIND(")",B203))) | F203: =IF(ISERROR(MID($E203,FIND("h",$E203)-2,2)+0),0,MID($E203,FIND("h",$E203)-2,2)+0) -> 0 | G203: =IF(ISERROR(MID($E203,FIND("m",$E203)-2,2)+0),0,MID($E203,FIND("m",$E203)-2,2)+0) -> 0 | H203: =IF(ISERROR(MID($E203,FIND("s",$E203)-2,2)+0),0,MID($E203,FIND("s",$E203)-2,2)+0) -> 0 | I203: =IF(J203="No",I202+1,I202) -> 1 | J203: =IF(G203=0,"Yes","No") -> Yes | K203: =IF(J203="No",J203&I203,"") | L203: =TIME(F203,G203,H203) -> 0 | M203: =IF(I203=1,0,INDEX(L:L,MATCH("No"&I203,K:K,0))-INDEX(L:L,MATCH("No"&I203-1,K:K,0))) -> 0
E204: =IF(ISERROR(LEFT(B204,FIND(")",B204))),"",LEFT(B204,FIND(")",B204))) | F204: =IF(ISERROR(MID($E204,FIND("h",$E204)-2,2)+0),0,MID($E204,FIND("h",$E204)-2,2)+0) -> 0 | G204: =IF(ISERROR(MID($E204,FIND("m",$E204)-2,2)+0),0,MID($E204,FIND("m",$E204)-2,2)+0) -> 0 | H204: =IF(ISERROR(MID($E204,FIND("s",$E204)-2,2)+0),0,MID($E204,FIND("s",$E204)-2,2)+0) -> 0 | I204: =IF(J204="No",I203+1,I203) -> 1 | J204: =IF(G204=0,"Yes","No") -> Yes | K204: =IF(J204="No",J204&I204,"") | L204: =TIME(F204,G204,H204) -> 0 | M204: =IF(I204=1,0,INDEX(L:L,MATCH("No"&I204,K:K,0))-INDEX(L:L,MATCH("No"&I204-1,K:K,0))) -> 0
E205: =IF(ISERROR(LEFT(B205,FIND(")",B205))),"",LEFT(B205,FIND(")",B205))) | F205: =IF(ISERROR(MID($E205,FIND("h",$E205)-2,2)+0),0,MID($E205,FIND("h",$E205)-2,2)+0) -> 0 | G205: =IF(ISERROR(MID($E205,FIND("m",$E205)-2,2)+0),0,MID($E205,FIND("m",$E205)-2,2)+0) -> 0 | H205: =IF(ISERROR(MID($E205,FIND("s",$E205)-2,2)+0),0,MID($E205,FIND("s",$E205)-2,2)+0) -> 0 | I205: =IF(J205="No",I204+1,I204) -> 1 | J205: =IF(G205=0,"Yes","No") -> Yes | K205: =IF(J205="No",J205&I205,"") | L205: =TIME(F205,G205,H205) -> 0 | M205: =IF(I205=1,0,INDEX(L:L,MATCH("No"&I205,K:K,0))-INDEX(L:L,MATCH("No"&I205-1,K:K,0))) -> 0
E206: =IF(ISERROR(LEFT(B206,FIND(")",B206))),"",LEFT(B206,FIND(")",B206))) | F206: =IF(ISERROR(MID($E206,FIND("h",$E206)-2,2)+0),0,MID($E206,FIND("h",$E206)-2,2)+0) -> 0 | G206: =IF(ISERROR(MID($E206,FIND("m",$E206)-2,2)+0),0,MID($E206,FIND("m",$E206)-2,2)+0) -> 0 | H206: =IF(ISERROR(MID($E206,FIND("s",$E206)-2,2)+0),0,MID($E206,FIND("s",$E206)-2,2)+0) -> 0 | I206: =IF(J206="No",I205+1,I205) -> 1 | J206: =IF(G206=0,"Yes","No") -> Yes | K206: =IF(J206="No",J206&I206,"") | L206: =TIME(F206,G206,H206) -> 0 | M206: =IF(I206=1,0,INDEX(L:L,MATCH("No"&I206,K:K,0))-INDEX(L:L,MATCH("No"&I206-1,K:K,0))) -> 0
E207: =IF(ISERROR(LEFT(B207,FIND(")",B207))),"",LEFT(B207,FIND(")",B207))) | F207: =IF(ISERROR(MID($E207,FIND("h",$E207)-2,2)+0),0,MID($E207,FIND("h",$E207)-2,2)+0) -> 0 | G207: =IF(ISERROR(MID($E207,FIND("m",$E207)-2,2)+0),0,MID($E207,FIND("m",$E207)-2,2)+0) -> 0 | H207: =IF(ISERROR(MID($E207,FIND("s",$E207)-2,2)+0),0,MID($E207,FIND("s",$E207)-2,2)+0) -> 0 | I207: =IF(J207="No",I206+1,I206) -> 1 | J207: =IF(G207=0,"Yes","No") -> Yes | K207: =IF(J207="No",J207&I207,"") | L207: =TIME(F207,G207,H207) -> 0 | M207: =IF(I207=1,0,INDEX(L:L,MATCH("No"&I207,K:K,0))-INDEX(L:L,MATCH("No"&I207-1,K:K,0))) -> 0
E208: =IF(ISERROR(LEFT(B208,FIND(")",B208))),"",LEFT(B208,FIND(")",B208))) | F208: =IF(ISERROR(MID($E208,FIND("h",$E208)-2,2)+0),0,MID($E208,FIND("h",$E208)-2,2)+0) -> 0 | G208: =IF(ISERROR(MID($E208,FIND("m",$E208)-2,2)+0),0,MID($E208,FIND("m",$E208)-2,2)+0) -> 0 | H208: =IF(ISERROR(MID($E208,FIND("s",$E208)-2,2)+0),0,MID($E208,FIND("s",$E208)-2,2)+0) -> 0 | I208: =IF(J208="No",I207+1,I207) -> 1 | J208: =IF(G208=0,"Yes","No") -> Yes | K208: =IF(J208="No",J208&I208,"") | L208: =TIME(F208,G208,H208) -> 0 | M208: =IF(I208=1,0,INDEX(L:L,MATCH("No"&I208,K:K,0))-INDEX(L:L,MATCH("No"&I208-1,K:K,0))) -> 0
E209: =IF(ISERROR(LEFT(B209,FIND(")",B209))),"",LEFT(B209,FIND(")",B209))) | F209: =IF(ISERROR(MID($E209,FIND("h",$E209)-2,2)+0),0,MID($E209,FIND("h",$E209)-2,2)+0) -> 0 | G209: =IF(ISERROR(MID($E209,FIND("m",$E209)-2,2)+0),0,MID($E209,FIND("m",$E209)-2,2)+0) -> 0 | H209: =IF(ISERROR(MID($E209,FIND("s",$E209)-2,2)+0),0,MID($E209,FIND("s",$E209)-2,2)+0) -> 0 | I209: =IF(J209="No",I208+1,I208) -> 1 | J209: =IF(G209=0,"Yes","No") -> Yes | K209: =IF(J209="No",J209&I209,"") | L209: =TIME(F209,G209,H209) -> 0 | M209: =IF(I209=1,0,INDEX(L:L,MATCH("No"&I209,K:K,0))-INDEX(L:L,MATCH("No"&I209-1,K:K,0))) -> 0
E210: =IF(ISERROR(LEFT(B210,FIND(")",B210))),"",LEFT(B210,FIND(")",B210))) | F210: =IF(ISERROR(MID($E210,FIND("h",$E210)-2,2)+0),0,MID($E210,FIND("h",$E210)-2,2)+0) -> 0 | G210: =IF(ISERROR(MID($E210,FIND("m",$E210)-2,2)+0),0,MID($E210,FIND("m",$E210)-2,2)+0) -> 0 | H210: =IF(ISERROR(MID($E210,FIND("s",$E210)-2,2)+0),0,MID($E210,FIND("s",$E210)-2,2)+0) -> 0 | I210: =IF(J210="No",I209+1,I209) -> 1 | J210: =IF(G210=0,"Yes","No") -> Yes | K210: =IF(J210="No",J210&I210,"") | L210: =TIME(F210,G210,H210) -> 0 | M210: =IF(I210=1,0,INDEX(L:L,MATCH("No"&I210,K:K,0))-INDEX(L:L,MATCH("No"&I210-1,K:K,0))) -> 0
E211: =IF(ISERROR(LEFT(B211,FIND(")",B211))),"",LEFT(B211,FIND(")",B211))) | F211: =IF(ISERROR(MID($E211,FIND("h",$E211)-2,2)+0),0,MID($E211,FIND("h",$E211)-2,2)+0) -> 0 | G211: =IF(ISERROR(MID($E211,FIND("m",$E211)-2,2)+0),0,MID($E211,FIND("m",$E211)-2,2)+0) -> 0 | H211: =IF(ISERROR(MID($E211,FIND("s",$E211)-2,2)+0),0,MID($E211,FIND("s",$E211)-2,2)+0) -> 0 | I211: =IF(J211="No",I210+1,I210) -> 1 | J211: =IF(G211=0,"Yes","No") -> Yes | K211: =IF(J211="No",J211&I211,"") | L211: =TIME(F211,G211,H211) -> 0 | M211: =IF(I211=1,0,INDEX(L:L,MATCH("No"&I211,K:K,0))-INDEX(L:L,MATCH("No"&I211-1,K:K,0))) -> 0
E212: =IF(ISERROR(LEFT(B212,FIND(")",B212))),"",LEFT(B212,FIND(")",B212))) | F212: =IF(ISERROR(MID($E212,FIND("h",$E212)-2,2)+0),0,MID($E212,FIND("h",$E212)-2,2)+0) -> 0 | G212: =IF(ISERROR(MID($E212,FIND("m",$E212)-2,2)+0),0,MID($E212,FIND("m",$E212)-2,2)+0) -> 0 | H212: =IF(ISERROR(MID($E212,FIND("s",$E212)-2,2)+0),0,MID($E212,FIND("s",$E212)-2,2)+0) -> 0 | I212: =IF(J212="No",I211+1,I211) -> 1 | J212: =IF(G212=0,"Yes","No") -> Yes | K212: =IF(J212="No",J212&I212,"") | L212: =TIME(F212,G212,H212) -> 0 | M212: =IF(I212=1,0,INDEX(L:L,MATCH("No"&I212,K:K,0))-INDEX(L:L,MATCH("No"&I212-1,K:K,0))) -> 0
E213: =IF(ISERROR(LEFT(B213,FIND(")",B213))),"",LEFT(B213,FIND(")",B213))) | F213: =IF(ISERROR(MID($E213,FIND("h",$E213)-2,2)+0),0,MID($E213,FIND("h",$E213)-2,2)+0) -> 0 | G213: =IF(ISERROR(MID($E213,FIND("m",$E213)-2,2)+0),0,MID($E213,FIND("m",$E213)-2,2)+0) -> 0 | H213: =IF(ISERROR(MID($E213,FIND("s",$E213)-2,2)+0),0,MID($E213,FIND("s",$E213)-2,2)+0) -> 0 | I213: =IF(J213="No",I212+1,I212) -> 1 | J213: =IF(G213=0,"Yes","No") -> Yes | K213: =IF(J213="No",J213&I213,"") | L213: =TIME(F213,G213,H213) -> 0 | M213: =IF(I213=1,0,INDEX(L:L,MATCH("No"&I213,K:K,0))-INDEX(L:L,MATCH("No"&I213-1,K:K,0))) -> 0
...

Sheet Source
C1: IRREGULARITY | F1: Support Team Options | G1: Audit type | H1: RESOLUTION STATUS | I1: CASE STATUS TYPE | L1: OPS Team Compo | N1: WEMmmDDYYYY | T1: Evaluator Team Compo
C2: None | F2: Belkin | G2: @Company Email Usage Spot Check | H2: RESOLVED | I2: First about the concern | L2: Badge ID | M2: NAME | N2: TEAM | O2: SUPERVISOR | P2: MANAGER | Q2: CMS LOGIN | R2: STATUS | S2: TENURE | T2: Badge ID | U2: NAME | V2: Type | W2: Evaluator's Name | X2: TPR Name
C3: Mixed | F3: CAT | G3: ARR | H3: UNRESOLVED (properly isolated) | I3: Second about the concern | U3: DOGENO, MERVYN | V3: QA | W3: =V3&"_"&U3 -> QA_DOGENO, MERVYN | X3: =LOWER(SUBSTITUTE(LEFT(U3,FIND(",",U3)+2),", ","")) -> dogenom
C4: Any act of Fraud | F4: Chat | G4: Bounceback Spot Check | H4: UNRESOLVED (with Missing Steps) | I4: Third about the concern | U4: DE SALES, RAIAN | V4: QA | W4: =V4&"_"&U4 -> QA_DE SALES, RAIAN | X4: =LOWER(SUBSTITUTE(LEFT(U4,FIND(",",U4)+2),", ","")) -> de salesr
C5: Discourtesy | F5: Customer Service | G5: Calibration | H5: UNRESOLVED (Wrong Troubleshooting path) | I5: More than 3x about the concern | U5: LOBERANES, SUNSHINE | V5: QA | W5: =V5&"_"&U5 -> QA_LOBERANES, SUNSHINE | X5: =LOWER(SUBSTITUTE(LEFT(U5,FIND(",",U5)+2),", ","")) -> loberaness
C6: Documenting Confidential Information (all else) | F6: Homestore | G6: Complaint | H6: Unresolved (Declined Sales Pitch valid) | T6: 12345 | U6: DUHAYLUNGSOD, LOWELLA | V6: QA | W6: =V6&"_"&U6 -> QA_DUHAYLUNGSOD, LOWELLA | X6: =LOWER(SUBSTITUTE(LEFT(U6,FIND(",",U6)+2),", ","")) -> duhaylungsodl
C7: Documenting Confidential Information (full CC number + CVN) | F7: International | G7: CSAT | H7: Unresolved (Declined Sales Pitch - Invalid) | T7: 22105 | U7: BEDRO, RHEA | V7: QA | W7: =V7&"_"&U7 -> QA_BEDRO, RHEA | X7: =LOWER(SUBSTITUTE(LEFT(U7,FIND(",",U7)+2),", ","")) -> bedror
C8: Engaging in Non-Productive Work | F8: Linksys | G8: DSAT | H8: Unresolved (Disconnected/Line Release) | T8: 23294 | U8: LOPEZ, MARIA LOURDES | V8: QA | W8: =V8&"_"&U8 -> QA_LOPEZ, MARIA LOURDES | X8: =LOWER(SUBSTITUTE(LEFT(U8,FIND(",",U8)+2),", ","")) -> lopezm
C9: Inaccurate Documentation (@Company Address) | F9: SET | G9: Email Alteration Spot Check | T9: 26929 | U9: LANGAM, JOVILYN | V9: QA | W9: =V9&"_"&U9 -> QA_LANGAM, JOVILYN | X9: =LOWER(SUBSTITUTE(LEFT(U9,FIND(",",U9)+2),", ","")) -> langamj
C10: Inaccurate Documentation (Account Name, Phone Number) | F10: SMB | G10: FCR | T10: 21306 | U10: COLIMA, CHRIS | V10: QA | W10: =V10&"_"&U10 -> QA_COLIMA, CHRIS | X10: =LOWER(SUBSTITUTE(LEFT(U10,FIND(",",U10)+2),", ","")) -> colimac
C11: Inaccurate Documentation (All other fields) | F11: Social Media | G11: Ghost or Disconnected Contact Spot Check | T11: 28556 | U11: RAYMUNDO, LALAINE | V11: QA | W11: =V11&"_"&U11 -> QA_RAYMUNDO, LALAINE | X11: =LOWER(SUBSTITUTE(LEFT(U11,FIND(",",U11)+2),", ","")) -> raymundol
C12: Inaccurate Documentation (ISP and OS) | F12: Velop | G12: Investigation | T12: 19546 | U12: GALES, VENUS | V12: QA | W12: =V12&"_"&U12 -> QA_GALES, VENUS | X12: =LOWER(SUBSTITUTE(LEFT(U12,FIND(",",U12)+2),", ","")) -> galesv
C13: Inaccurate Documentation (Problem Categories) | F13: Wemo | G13: Misdirected Contact Spot Check | T13: 19851 | U13: TUBA, EXEQUIEL DOONE | V13: QA | W13: =V13&"_"&U13 -> QA_TUBA, EXEQUIEL DOONE | X13: =LOWER(SUBSTITUTE(LEFT(U13,FIND(",",U13)+2),", ","")) -> tubae
C14: Inaccurate Documentation (Product Information) | F14: Support Channel Options | G14: Random Call | T14: 21593 | U14: DECENA, IMIE GRACE | V14: QA | W14: =V14&"_"&U14 -> QA_DECENA, IMIE GRACE | X14: =LOWER(SUBSTITUTE(LEFT(U14,FIND(",",U14)+2),", ","")) -> decenai
C15: Inaccurate Documentation (Service Offering) | F15: Amazon Q&A | G15: Refunds Spot Check | T15: 28639 | U15: MARAVILLAS, CATHERINE | V15: QA | W15: =V15&"_"&U15 -> QA_MARAVILLAS, CATHERINE | X15: =LOWER(SUBSTITUTE(LEFT(U15,FIND(",",U15)+2),", ","")) -> maravillasc
C16: Inaccurate Documentation (Solution Category) | F16: Backoffice | G16: Scheduled/Side-by-side | T16: 10969 | U16: WABE, CHRISTIAN PAUL | V16: QA | W16: =V16&"_"&U16 -> QA_WABE, CHRISTIAN PAUL | X16: =LOWER(SUBSTITUTE(LEFT(U16,FIND(",",U16)+2),", ","")) -> wabec
C17: Inaccurate Documentation (Unique Email Address) | F17: Chat | G17: Service Offering Spot Check | T17: 14963 | U17: VERONILLA, ELLAINE | V17: QA | W17: =V17&"_"&U17 -> QA_VERONILLA, ELLAINE | X17: =LOWER(SUBSTITUTE(LEFT(U17,FIND(",",U17)+2),", ","")) -> veronillae
C18: Line Release | F18: Community Forum | G18: Spot check for Newbies | T18: 21186 | U18: VALMORES, ANGELICA | V18: QA | W18: =V18&"_"&U18 -> QA_VALMORES, ANGELICA | X18: =LOWER(SUBSTITUTE(LEFT(U18,FIND(",",U18)+2),", ","")) -> valmoresa
C19: Non-Adherence to Callback/ Follow-through Process | F19: Email | T19: 21496 | U19: GUCOR, ARGIE | V19: QA | W19: =V19&"_"&U19 -> QA_GUCOR, ARGIE | X19: =LOWER(SUBSTITUTE(LEFT(U19,FIND(",",U19)+2),", ","")) -> gucora
C20: Non-Adherence to Escalation Process | F20: Facebook | T20: 11091 | U20: PETALLAR, MARY JOY | V20: QA | W20: =V20&"_"&U20 -> QA_PETALLAR, MARY JOY | X20: =LOWER(SUBSTITUTE(LEFT(U20,FIND(",",U20)+2),", ","")) -> petallarm
C21: Non-Adherence to Refund Process | F21: Reviews | T21: 21733 | U21: MAESTRADO, PAMELA BIANCA | V21: QA | W21: =V21&"_"&U21 -> QA_MAESTRADO, PAMELA BIANCA | X21: =LOWER(SUBSTITUTE(LEFT(U21,FIND(",",U21)+2),", ","")) -> maestradop
C22: Non-Adherence to RMA Process | F22: Twitter | T22: 15003 | U22: ARBON, CLAUDINE FRANCES | V22: QA | W22: =V22&"_"&U22 -> QA_ARBON, CLAUDINE FRANCES | X22: =LOWER(SUBSTITUTE(LEFT(U22,FIND(",",U22)+2),", ","")) -> arbonc
C23: Non-compliance to Account Norms | F23: Voice | T23: 20840 | U23: ROMA, ABIGAIL | V23: QA | W23: =V23&"_"&U23 -> QA_ROMA, ABIGAIL | X23: =LOWER(SUBSTITUTE(LEFT(U23,FIND(",",U23)+2),", ","")) -> romaa
C24: Non-Documentation | T24: 14695 | U24: AZARON, APPLE JANE | V24: QA | W24: =V24&"_"&U24 -> QA_AZARON, APPLE JANE | X24: =LOWER(SUBSTITUTE(LEFT(U24,FIND(",",U24)+2),", ","")) -> azarona
C25: Non-Resolution | T25: 25585 | U25: VALDERRAMA, JARA | V25: QA | W25: =V25&"_"&U25 -> QA_VALDERRAMA, JARA | X25: =LOWER(SUBSTITUTE(LEFT(U25,FIND(",",U25)+2),", ","")) -> valderramaj
C26: Not Providing Important Information
C27: Offense Against Confidentiality Of CNX/Client Information
C28: Providing Misleading Information
C29: Sales-Related Irregularities
C30: Survey Manipulation
C31: Transaction Abandonment
C32: Transaction Avoidance
C33: Transaction Evasion
C34: Unauthorized Credit Card Use
C35: Using An Unofficial Email Address When Replying To The Customer
C36: None

Sheet 360 Form
D4: Select Account | E4: Linksys | I4: QUALITY SCORE | J4: =IF(OR($H$28="NO",$H$29="NO",SUM($G$38:$G$48)>0),0%,SUM($G$30:$G$37)/SUM($F$30:$F$37)) -> 1 | M4: Filename format
D5: Support Team / LOB | E5: Linksys | I5: Date Monitored (PST) | J5: 46184 | L5: =IF(NOW()<$J5,"ALERT: Date is in the future","") | M5: (agent's last name & first name initial)_(evaluator's last name & first name initial)_date monitored (YYMMDD)_product model
D6: Support Channel | E6: Voice | I6: BADGE ID | J6: 11039 | M6: =LOWER(SUBSTITUTE(LEFT($J$7,FIND(",",$J$7)+2),", ",""))&"_"&INDEX(Source!$X$3:$X$56,MATCH($J$17,Source!$U$3:$U$56,0))&"_"&TEXT($J$5,"MmmDDYY")&"_"&$E$12 -> #VALUE!
D7: Call Type | E7: Outbound | I7: AGENT NAME | J7: Paolo Ebora
D8: Support Type | E8: Tech Support | I8: SITE | J8: CX-CDO
I9: Team | J9: CNX CDO CHAT - Connectivity Champions | U9: Hlookup lookup_value | V9: =HLOOKUP($E$5,$V$13:$AG$25,13,0) -> Linksys | X9: Target QA Score | Y9: =HLOOKUP($V$9,$U$25:$AG$26,2,0) -> 0.8
D10: CASE NUMBER | E10: TE00132422 | I10: Supervisor | J10: Marc Joseph M. Baynos
D11: THEATRE | E11: NA | I11: Manager | J11: Joey Agao | U11: ITEM WEIGHT REFERENCE | AI11: ITEM WEIGHT %
D12: Product Model & Version No. | E12: MX6200
D13: WARRANTY | E13: 3 years | I13: IRREGULARITY | J13: None | L13: =IF(COUNTIF($J$89:$J$93,$J13)>0,"ALERT: Duplicate","") | V13: Belkin | W13: CAT | X13: Chat | Y13: Customer Service | Z13: Homestore | AA13: International | AB13: Linksys | AC13: SET | AD13: SMB | AE13: Social Media | AF13: Velop | AG13: Wemo | AJ13: =V13 -> Belkin | AK13: =W13 -> CAT | AL13: =X13 -> Chat | AM13: =Y13 -> Customer Service | AN13: =Z13 -> Homestore | AO13: =AA13 -> International | AP13: =AB13 -> Linksys | AQ13: =AC13 -> SET | ... AU13: =AG13 -> Wemo
D14: Product's Warranty Status | E14: Eligible | I14: QA SCORE without Auto-Zero | U14: Process | V14: =SUM(V$28:V$32) -> 20 | W14: =SUM(W$28:W$32) -> 20 | X14: =SUM(X$28:X$32) -> 22 | Y14: =SUM(Y$28:Y$32) -> 22 | Z14: =SUM(Z$28:Z$32) -> 22 | AA14: =SUM(AA$28:AA$32) -> 20 | AB14: =SUM(AB$28:AB$32) -> 22 | AC14: =SUM(AC$28:AC$32) -> 20 | ... AG14: =SUM(AG$28:AG$32) -> 20 | AI14: Process | AJ14: =SUM(AJ$28:AJ$32) -> 0.2 | AK14: =SUM(AK$28:AK$32) -> 0.2 | AL14: =SUM(AL$28:AL$32) -> 0.22 | AM14: =SUM(AM$28:AM$32) -> 0.22 | AN14: =SUM(AN$28:AN$32) -> 0.22 | AO14: =SUM(AO$28:AO$32) -> 0.2 | AP14: =SUM(AP$28:AP$32) -> 0.22 | AQ14: =SUM(AQ$28:AQ$32) -> 0.2 | ... AU14: =SUM(AU$28:AU$32) -> 0.2
U15: Communication | V15: =SUM(V$33:V$34) -> 10 | W15: =SUM(W$33:W$34) -> 10 | X15: =SUM(X$33:X$34) -> 10 | Y15: =SUM(Y$33:Y$34) -> 10 | Z15: =SUM(Z$33:Z$34) -> 10 | AA15: =SUM(AA$33:AA$34) -> 10 | AB15: =SUM(AB$33:AB$34) -> 10 | AC15: =SUM(AC$33:AC$34) -> 10 | ... AG15: =SUM(AG$33:AG$34) -> 10 | AI15: Communication | AJ15: =SUM(AJ$33:AJ$34) -> 0.1 | AK15: =SUM(AK$33:AK$34) -> 0.1 | AL15: =SUM(AL$33:AL$34) -> 0.1 | AM15: =SUM(AM$33:AM$34) -> 0.1 | AN15: =SUM(AN$33:AN$34) -> 0.1 | AO15: =SUM(AO$33:AO$34) -> 0.1 | AP15: =SUM(AP$33:AP$34) -> 0.1 | AQ15: =SUM(AQ$33:AQ$34) -> 0.1 | ... AU15: =SUM(AU$33:AU$34) -> 0.1
D16: Problem Details | E16: Initial set up | I16: Evaluator's Badge Number | J16: 2196 | U16: Customer Service | V16: =V35 -> 10 | W16: =W35 -> 10 | X16: =X35 -> 8 | Y16: =Y35 -> 8 | Z16: =Z35 -> 8 | AA16: =AA35 -> 10 | AB16: =AB35 -> 8 | AC16: =AC35 -> 10 | ... AG16: =AG35 -> 10 | AI16: Customer Service | AJ16: =AJ35 -> 0.1 | AK16: =AK35 -> 0.1 | AL16: =AL35 -> 0.08 | AM16: =AM35 -> 0.08 | AN16: =AN35 -> 0.08 | AO16: =AO35 -> 0.1 | AP16: =AP35 -> 0.08 | AQ16: =AQ35 -> 0.1 | ... AU16: =AU35 -> 0.1
D17: Customer Demographics | E17: Male | I17: EVALUATOR'S NAME | J17: QA_GUCOR, ARGIE | U17: Resolution | V17: =SUM(V$36:V$37) -> 60 | W17: =SUM(W$36:W$37) -> 60 | X17: =SUM(X$36:X$37) -> 60 | Y17: =SUM(Y$36:Y$37) -> 60 | Z17: =SUM(Z$36:Z$37) -> 60 | AA17: =SUM(AA$36:AA$37) -> 60 | AB17: =SUM(AB$36:AB$37) -> 60 | AC17: =SUM(AC$36:AC$37) -> 60 | ... AG17: =SUM(AG$36:AG$37) -> 60 | AI17: Resolution | AJ17: =SUM(AJ$36:AJ$37) -> 0.6 | AK17: =SUM(AK$36:AK$37) -> 0.6 | AL17: =SUM(AL$36:AL$37) -> 0.6 | AM17: =SUM(AM$36:AM$37) -> 0.6 | AN17: =SUM(AN$36:AN$37) -> 0.6 | AO17: =SUM(AO$36:AO$37) -> 0.6 | AP17: =SUM(AP$36:AP$37) -> 0.6 | AQ17: =SUM(AQ$36:AQ$37) -> 0.6 | ... AU17: =SUM(AU$36:AU$37) -> 0.6
D18: Interaction Type | E18: Customer Call Out | I18: AUDIT TYPE | J18: Random Call | U18: Total | V18: =SUM(V14:V17) -> 100 | W18: =SUM(W14:W17) -> 100 | X18: =SUM(X14:X17) -> 100 | Y18: =SUM(Y14:Y17) -> 100 | Z18: =SUM(Z14:Z17) -> 100 | AA18: =SUM(AA14:AA17) -> 100 | AB18: =SUM(AB14:AB17) -> 100 | AC18: =SUM(AC14:AC17) -> 100 | ... AG18: =SUM(AG14:AG17) -> 100 | AI18: Total | AJ18: =SUM(AJ14:AJ17) -> 1 | AK18: =SUM(AK14:AK17) -> 1 | AL18: =SUM(AL14:AL17) -> 1 | AM18: =SUM(AM14:AM17) -> 1 | AN18: =SUM(AN14:AN17) -> 1 | AO18: =SUM(AO14:AO17) -> 1 | AP18: =SUM(AP14:AP17) -> 1 | AQ18: =SUM(AQ14:AQ17) -> 1 | ... AU18: =SUM(AU14:AU17) -> 1
I19: RECORDING FILENAME | J19: internal-10138-+19402300087-20260609-091821-1781021937.7683686
D20: Device deemed defective? | E20: No | I20: Transaction Date (PST) | J20: 46178 | L20: =IF(NOW()<$J20,"ALERT: Transaction date is in the future","")
D21: Replacement approved? | E21: No | I21: Transaction Time (PST) | J21: 0.68194444
D22: Valid RMA? | E22: No | I22: Transaction duration | J22: 0.039212963
D23: Problem Category | E23: N/A | I23: Skill/Split | J23: N/A
T24: Hlookup ID#
T25: 1 | U25: Name range | V25: Belkin | W25: CAT | X25: Chat | Y25: CS | Z25: Homestore | AA25: International | AB25: Linksys | AC25: SET | AD25: SMB | AE25: SMRT | AF25: Velop | AG25: Wemo | AJ25: =V25 -> Belkin | AK25: =W25 -> CAT | AL25: =X25 -> Chat | AM25: =Y25 -> CS | AN25: =Z25 -> Homestore | AO25: =AA25 -> International | AP25: =AB25 -> Linksys | AQ25: =AC25 -> SET | ... AU25: =AG25 -> Wemo
D26: PEOPLE | T26: =T25+1 -> 2 | U26: Target QA score | V26: 0.8 | W26: 0.9 | X26: 0.8 | Y26: 0.8 | Z26: 0.8 | AA26: 0.8 | AB26: 0.8 | AC26: 0.9 | AD26: 0.9 | AE26: 0.9 | AF26: 0.9 | AG26: 0.8 | AJ26: 0.8 | AK26: 0.8 | AL26: 0.8 | AM26: 0.8 | AN26: 0.8 | AO26: 0.8 | AP26: 0.8 | AQ26: 0.8 | AR26: 0.8 | AS26: 0.8 | AT26: 0.9 | AU26: 0.8
D27: COMPETENCY | E27: QUALITY ITEM | F27: TARGET SCORE | G27: ACTUAL SCORE | H27: RATING | I27: REMARKS | L27: CHECK SPECIFIC OPPORTUNITIES | Q27: TARGET SCORE | R27: ITEM WEIGHT | S27: MD Category | T27: =T26+1 -> 3 | U27: Line item | V27: Belkin | W27: CAT | X27: Chat | Y27: Customer Service | Z27: Homestore | AA27: International | AB27: Linksys | AC27: SET | AD27: SMB | AE27: Social Media | AF27: Velop | AG27: Wemo | AI27: Line item | AJ27: =V27 -> Belkin | AK27: =W27 -> CAT | AL27: =X27 -> Chat | AM27: =Y27 -> Customer Service | AN27: =Z27 -> Homestore | AO27: =AA27 -> International | AP27: =AB27 -> Linksys | AQ27: =AC27 -> SET | ... AU27: =AG27 -> Wemo | AX27: CHECKBOX CATEGORY NAMES | DA27: Areas for improvement reference | DB27: SPECIFIC OPPORTUNITIES | FF27: SPECIFIC OPPORTUNITIES COMMENTS | HJ27: SUMMARY of SPECIFIC OPPORTUNITIES
C28: 1 | D28: Process | E28: Adherence to Callback Hours | F28: =IF($E$5="","",0%) -> 0 | G28: =IF($E$5="","",0%) -> 0 | H28: YES | I28: This is not applicable to this call. There was no callback initiated by the agent since it was not necessary. | Q28: =IFERROR(IF(H28="N/A",0,R28),"") -> 0 | R28: =IFERROR(HLOOKUP($V$9,$AJ$25:$AU$37,$T28,0),"") -> 0 | S28: =IF(OR($H28="NO",ISNUMBER($DA28)),$E28&"; ","") | T28: =T27+1 -> 4 | U28: Adherence to Callback Hours | V28: 0 | W28: 0 | X28: 0 | Y28: 0 | Z28: 0 | AA28: 0 | AB28: 0 | AC28: 0 | AD28: 0 | AE28: 0 | AF28: 0 | AG28: 0 | AI28: Adherence to Callback Hours | AJ28: =IFERROR(V28/SUM(V$28:V$37),"") -> 0 | AK28: =IFERROR(W28/SUM(W$28:W$37),"") -> 0 | AL28: =IFERROR(X28/SUM(X$28:X$37),"") -> 0 | AM28: =IFERROR(Y28/SUM(Y$28:Y$37),"") -> 0 | AN28: =IFERROR(Z28/SUM(Z$28:Z$37),"") -> 0 | AO28: =IFERROR(AA28/SUM(AA$28:AA$37),"") -> 0 | AP28: =IFERROR(AB28/SUM(AB$28:AB$37),"") -> 0 | AQ28: =IFERROR(AC28/SUM(AC$28:AC$37),"") -> 0 | ... AU28: =IFERROR(AG28/SUM(AG$28:AG$37),"") -> 0 | AX28: Process - Adherence to Callback Hours | DA28: =MATCH(TRUE,DB28:FD28,0) -> #N/A | FF28: =IF(DB28=TRUE,AX28&"; ","") | FG28: =IF(DC28=TRUE,AY28&"; ","") | FH28: =IF(DD28=TRUE,AZ28&"; ","") | FI28: =IF(DE28=TRUE,BA28&"; ","") | FJ28: =IF(DF28=TRUE,BB28&"; ","") | FK28: =IF(DG28=TRUE,BC28&"; ","") | FL28: =IF(DH28=TRUE,BD28&"; ","") | FM28: =IF(DI28=TRUE,BE28&"; ","") | ... HH28: =IF(FD28=TRUE,CZ28&"; ","") | HJ28: =IFERROR(LEFT(FF28&FG28&FH28&FI28&FJ28&FK28&FL28&FM28&FN28&FO28&FP28&FQ28&FR28&FS28&FT28&FU28&FV28&FW28&FX28&FY28&FZ28&GA28&GB28&GC28&GD28&GE28&GF28&GG28&GH28&GI28&GJ28&GK28&GL28&GM28&GN28&GO28&GP28&GQ28&GR28&GS28&GT28&GU28&GV28&GW28&GX28&GY28&GZ28&HA28&HB28&HC28&HD28&HE28&HF28&HG28&HH28,LEN(FF28&FG28&FH28&FI28&FJ28&FK28&FL28&FM28&FN28&FO28&FP28&FQ28&FR28&FS28&FT28&FU28&FV28&FW28&FX28&FY28&FZ28&GA28&GB28&GC28&GD28&GE28&GF28&GG28&GH28&GI28&GJ28&GK28&GL28&GM28&GN28&GO28&GP28&GQ28&GR28&GS28&GT28&GU28&GV28&GW28&GX28&GY28&GZ28&HA28&HB28&HC28&HD28&HE28&HF28&HG28&HH28)-2),"")
C29: 2 | E29: Adherence to PCI | F29: =IF($E$5="","",0%) -> 0 | G29: =IF($E$5="","",0%) -> 0 | H29: YES | I29: There were no confidential information related to credit card shared, stored and verbalised during the call. | Q29: =IFERROR(IF(H29="N/A",0,R29),"") -> 0 | R29: =IFERROR(HLOOKUP($V$9,$AJ$25:$AU$37,$T29,0),"") -> 0 | S29: =IF(OR($H29="NO",ISNUMBER($DA29)),$E29&"; ","") | T29: =T28+1 -> 5 | U29: Adherence to PCI | V29: 0 | W29: 0 | X29: 0 | Y29: 0 | Z29: 0 | AA29: 0 | AB29: 0 | AC29: 0 | AD29: 0 | AE29: 0 | AF29: 0 | AG29: 0 | AI29: Adherence to PCI | AJ29: =IFERROR(V29/SUM(V$28:V$37),"") -> 0 | AK29: =IFERROR(W29/SUM(W$28:W$37),"") -> 0 | AL29: =IFERROR(X29/SUM(X$28:X$37),"") -> 0 | AM29: =IFERROR(Y29/SUM(Y$28:Y$37),"") -> 0 | AN29: =IFERROR(Z29/SUM(Z$28:Z$37),"") -> 0 | AO29: =IFERROR(AA29/SUM(AA$28:AA$37),"") -> 0 | AP29: =IFERROR(AB29/SUM(AB$28:AB$37),"") -> 0 | AQ29: =IFERROR(AC29/SUM(AC$28:AC$37),"") -> 0 | ... AU29: =IFERROR(AG29/SUM(AG$28:AG$37),"") -> 0 | AX29: Documented confidential information | AY29: Repeated confidential information | AZ29: Unauthorized Processing of Sales | DA29: =MATCH(TRUE,DB29:FD29,0) -> #N/A | FF29: =IF(DB29=TRUE,AX29&"; ","") | FG29: =IF(DC29=TRUE,AY29&"; ","") | FH29: =IF(DD29=TRUE,AZ29&"; ","") | FI29: =IF(DE29=TRUE,BA29&"; ","") | FJ29: =IF(DF29=TRUE,BB29&"; ","") | FK29: =IF(DG29=TRUE,BC29&"; ","") | FL29: =IF(DH29=TRUE,BD29&"; ","") | FM29: =IF(DI29=TRUE,BE29&"; ","") | ... HH29: =IF(FD29=TRUE,CZ29&"; ","") | HJ29: =IFERROR(LEFT(FF29&FG29&FH29&FI29&FJ29&FK29&FL29&FM29&FN29&FO29&FP29&FQ29&FR29&FS29&FT29&FU29&FV29&FW29&FX29&FY29&FZ29&GA29&GB29&GC29&GD29&GE29&GF29&GG29&GH29&GI29&GJ29&GK29&GL29&GM29&GN29&GO29&GP29&GQ29&GR29&GS29&GT29&GU29&GV29&GW29&GX29&GY29&GZ29&HA29&HB29&HC29&HD29&HE29&HF29&HG29&HH29,LEN(FF29&FG29&FH29&FI29&FJ29&FK29&FL29&FM29&FN29&FO29&FP29&FQ29&FR29&FS29&FT29&FU29&FV29&FW29&FX29&FY29&FZ29&GA29&GB29&GC29&GD29&GE29&GF29&GG29&GH29&GI29&GJ29&GK29&GL29&GM29&GN29&GO29&GP29&GQ29&GR29&GS29&GT29&GU29&GV29&GW29&GX29&GY29&GZ29&HA29&HB29&HC29&HD29&HE29&HF29&HG29&HH29)-2),"")
C30: 3 | E30: Case Tagging | F30: =$Q30 -> 0.1 | G30: =IF($H30="YES",$Q30,IF($H30="","",0)) -> 0.1 | H30: YES | I30: No opportunities were observed with case documentation and tagging accuracy. All relevant and applicable HappyFox fields were properly completed, including the necessary product details and issue categorization, reflecting compliance with documentation standards. | Q30: =IFERROR(IF(H30="N/A",0,R30),"") -> 0.1 | R30: =IFERROR(HLOOKUP($V$9,$AJ$25:$AU$37,$T30,0),"") -> 0.1 | S30: =IF(OR($H30="NO",ISNUMBER($DA30)),$E30&"; ","") | T30: =T29+1 -> 6 | U30: Case Tagging | V30: 10 | W30: 10 | X30: 10 | Y30: 10 | Z30: 10 | AA30: 10 | AB30: 10 | AC30: 10 | AD30: 10 | AE30: 10 | AF30: 10 | AG30: 10 | AI30: Case Tagging | AJ30: =IFERROR(V30/SUM(V$28:V$37),"") -> 0.1 | AK30: =IFERROR(W30/SUM(W$28:W$37),"") -> 0.1 | AL30: =IFERROR(X30/SUM(X$28:X$37),"") -> 0.1 | AM30: =IFERROR(Y30/SUM(Y$28:Y$37),"") -> 0.1 | AN30: =IFERROR(Z30/SUM(Z$28:Z$37),"") -> 0.1 | AO30: =IFERROR(AA30/SUM(AA$28:AA$37),"") -> 0.1 | AP30: =IFERROR(AB30/SUM(AB$28:AB$37),"") -> 0.1 | AQ30: =IFERROR(AC30/SUM(AC$28:AC$37),"") -> 0.1 | ... AU30: =IFERROR(AG30/SUM(AG$28:AG$37),"") -> 0.1 | AX30: Asset | AY30: Warranty Start Date | AZ30: Hardware Warranty | BA30: Service Offering | BB30: Place of Purchase | BC30: Subscription Return Call | BD30: Problem Categories levels | BE30: Initial Installation | BF30: Velop Web UI | BG30: Solution Categories | BH30: ISP | BI30: Interaction Log Type | BJ30: Bubble up tick box | BK30: Bubble up Category | BL30: Escalation Type Reason and Priority level | BM30: Status | BN30: Case Record Type | BO30: Case Origin | BP30: Theatre | BQ30: Brand | BR30: RMA Activation | BS30: Product Details | BT30: Social Media Memo | BU30: Sentiment | DA30: =MATCH(TRUE,DB30:FD30,0) -> #N/A | DB30: FALSE | DC30: FALSE | DD30: FALSE | DE30: FALSE | DF30: FALSE | DG30: FALSE | DH30: FALSE | DI30: FALSE | DJ30: FALSE | DK30: FALSE | DL30: FALSE | DM30: FALSE | DN30: FALSE | DO30: FALSE | DP30: FALSE | DQ30: FALSE | DR30: FALSE | DS30: FALSE | DT30: FALSE | DU30: FALSE | DV30: FALSE | DW30: FALSE | DX30: FALSE | DY30: FALSE | FF30: =IF(DB30=TRUE,AX30&"; ","") | FG30: =IF(DC30=TRUE,AY30&"; ","") | FH30: =IF(DD30=TRUE,AZ30&"; ","") | FI30: =IF(DE30=TRUE,BA30&"; ","") | FJ30: =IF(DF30=TRUE,BB30&"; ","") | FK30: =IF(DG30=TRUE,BC30&"; ","") | FL30: =IF(DH30=TRUE,BD30&"; ","") | FM30: =IF(DI30=TRUE,BE30&"; ","") | ... HH30: =IF(FD30=TRUE,CZ30&"; ","") | HJ30: =IFERROR(LEFT(FF30&FG30&FH30&FI30&FJ30&FK30&FL30&FM30&FN30&FO30&FP30&FQ30&FR30&FS30&FT30&FU30&FV30&FW30&FX30&FY30&FZ30&GA30&GB30&GC30&GD30&GE30&GF30&GG30&GH30&GI30&GJ30&GK30&GL30&GM30&GN30&GO30&GP30&GQ30&GR30&GS30&GT30&GU30&GV30&GW30&GX30&GY30&GZ30&HA30&HB30&HC30&HD30&HE30&HF30&HG30&HH30,LEN(FF30&FG30&FH30&FI30&FJ30&FK30&FL30&FM30&FN30&FO30&FP30&FQ30&FR30&FS30&FT30&FU30&FV30&FW30&FX30&FY30&FZ30&GA30&GB30&GC30&GD30&GE30&GF30&GG30&GH30&GI30&GJ30&GK30&GL30&GM30&GN30&GO30&GP30&GQ30&GR30&GS30&GT30&GU30&GV30&GW30&GX30&GY30&GZ30&HA30&HB30&HC30&HD30&HE30&HF30&HG30&HH30)-2),"")
C31: 4 | E31: Case Documentation | F31: =$Q31 -> 0.1 | G31: =IF($H31="YES",$Q31,IF($H31="","",0)) -> 0.1 | H31: YES | I31: There were no opportunities observed. All the applicable fields were accurately documented based on this transaction. This includes the customer's details and case notes documentation. | Q31: =IFERROR(IF(H31="N/A",0,R31),"") -> 0.1 | R31: =IFERROR(HLOOKUP($V$9,$AJ$25:$AU$37,$T31,0),"") -> 0.1 | S31: =IF(OR($H31="NO",ISNUMBER($DA31)),$E31&"; ","") | T31: =T30+1 -> 7 | U31: Case Documentation | V31: 10 | W31: 10 | X31: 10 | Y31: 10 | Z31: 10 | AA31: 10 | AB31: 10 | AC31: 10 | AD31: 10 | AE31: 10 | AF31: 10 | AG31: 10 | AI31: Case Documentation | AJ31: =IFERROR(V31/SUM(V$28:V$37),"") -> 0.1 | AK31: =IFERROR(W31/SUM(W$28:W$37),"") -> 0.1 | AL31: =IFERROR(X31/SUM(X$28:X$37),"") -> 0.1 | AM31: =IFERROR(Y31/SUM(Y$28:Y$37),"") -> 0.1 | AN31: =IFERROR(Z31/SUM(Z$28:Z$37),"") -> 0.1 | AO31: =IFERROR(AA31/SUM(AA$28:AA$37),"") -> 0.1 | AP31: =IFERROR(AB31/SUM(AB$28:AB$37),"") -> 0.1 | AQ31: =IFERROR(AC31/SUM(AC$28:AC$37),"") -> 0.1 | ... AU31: =IFERROR(AG31/SUM(AG$28:AG$37),"") -> 0.1 | AX31: Customer name | AY31: Customer phone number | AZ31: Customer email address | BA31: Device Serial Number | BB31: Webex Session ID | BC31: Subject line | BD31: IR number | BE31: Parent case ID | BF31: ISP Other | BG31: Agent assist PIN | BH31: Coupon provided | BI31: Escalation Notes | BJ31: Mailing address | BK31: Case notes (content focused) | BL31: Billing address | BM31: Shipping address | DA31: =MATCH(TRUE,DB31:FD31,0) -> #N/A | DB31: FALSE | DC31: FALSE | DG31: FALSE | DL31: FALSE | FF31: =IF(DB31=TRUE,AX31&"; ","") | FG31: =IF(DC31=TRUE,AY31&"; ","") | FH31: =IF(DD31=TRUE,AZ31&"; ","") | FI31: =IF(DE31=TRUE,BA31&"; ","") | FJ31: =IF(DF31=TRUE,BB31&"; ","") | FK31: =IF(DG31=TRUE,BC31&"; ","") | FL31: =IF(DH31=TRUE,BD31&"; ","") | FM31: =IF(DI31=TRUE,BE31&"; ","") | ... HH31: =IF(FD31=TRUE,CZ31&"; ","") | HJ31: =IFERROR(LEFT(FF31&FG31&FH31&FI31&FJ31&FK31&FL31&FM31&FN31&FO31&FP31&FQ31&FR31&FS31&FT31&FU31&FV31&FW31&FX31&FY31&FZ31&GA31&GB31&GC31&GD31&GE31&GF31&GG31&GH31&GI31&GJ31&GK31&GL31&GM31&GN31&GO31&GP31&GQ31&GR31&GS31&GT31&GU31&GV31&GW31&GX31&GY31&GZ31&HA31&HB31&HC31&HD31&HE31&HF31&HG31&HH31,LEN(FF31&FG31&FH31&FI31&FJ31&FK31&FL31&FM31&FN31&FO31&FP31&FQ31&FR31&FS31&FT31&FU31&FV31&FW31&FX31&FY31&FZ31&GA31&GB31&GC31&GD31&GE31&GF31&GG31&GH31&GI31&GJ31&GK31&GL31&GM31&GN31&GO31&GP31&GQ31&GR31&GS31&GT31&GU31&GV31&GW31&GX31&GY31&GZ31&HA31&HB31&HC31&HD31&HE31&HF31&HG31&HH31)-2),"")
C32: 5 | E32: Sales | F32: =$Q32 -> 0.02 | G32: =IF($H32="YES",$Q32,IF($H32="","",0)) -> 0.02 | H32: YES | I32: There were no opportunities observed from this call. The concern is not related to sales. | Q32: =IFERROR(IF(H32="N/A",0,R32),"") -> 0.02 | R32: =IFERROR(HLOOKUP($V$9,$AJ$25:$AU$37,$T32,0),"") -> 0.02 | S32: =IF(OR($H32="NO",ISNUMBER($DA32)),$E32&"; ","") | T32: =T31+1 -> 8 | U32: Sales | X32: 2 | Y32: 2 | Z32: 2 | AB32: 2 | AI32: Sales | AJ32: =IFERROR(V32/SUM(V$28:V$37),"") -> 0 | AK32: =IFERROR(W32/SUM(W$28:W$37),"") -> 0 | AL32: =IFERROR(X32/SUM(X$28:X$37),"") -> 0.02 | AM32: =IFERROR(Y32/SUM(Y$28:Y$37),"") -> 0.02 | AN32: =IFERROR(Z32/SUM(Z$28:Z$37),"") -> 0.02 | AO32: =IFERROR(AA32/SUM(AA$28:AA$37),"") -> 0 | AP32: =IFERROR(AB32/SUM(AB$28:AB$37),"") -> 0.02 | AQ32: =IFERROR(AC32/SUM(AC$28:AC$37),"") -> 0 | ... AU32: =IFERROR(AG32/SUM(AG$28:AG$37),"") -> 0 | DA32: =MATCH(TRUE,DB32:FD32,0) -> #N/A | FF32: =IF(DB32=TRUE,AX32&"; ","") | FG32: =IF(DC32=TRUE,AY32&"; ","") | FH32: =IF(DD32=TRUE,AZ32&"; ","") | FI32: =IF(DE32=TRUE,BA32&"; ","") | FJ32: =IF(DF32=TRUE,BB32&"; ","") | FK32: =IF(DG32=TRUE,BC32&"; ","") | FL32: =IF(DH32=TRUE,BD32&"; ","") | FM32: =IF(DI32=TRUE,BE32&"; ","") | ... HH32: =IF(FD32=TRUE,CZ32&"; ","") | HJ32: =IFERROR(LEFT(FF32&FG32&FH32&FI32&FJ32&FK32&FL32&FM32&FN32&FO32&FP32&FQ32&FR32&FS32&FT32&FU32&FV32&FW32&FX32&FY32&FZ32&GA32&GB32&GC32&GD32&GE32&GF32&GG32&GH32&GI32&GJ32&GK32&GL32&GM32&GN32&GO32&GP32&GQ32&GR32&GS32&GT32&GU32&GV32&GW32&GX32&GY32&GZ32&HA32&HB32&HC32&HD32&HE32&HF32&HG32&HH32,LEN(FF32&FG32&FH32&FI32&FJ32&FK32&FL32&FM32&FN32&FO32&FP32&FQ32&FR32&FS32&FT32&FU32&FV32&FW32&FX32&FY32&FZ32&GA32&GB32&GC32&GD32&GE32&GF32&GG32&GH32&GI32&GJ32&GK32&GL32&GM32&GN32&GO32&GP32&GQ32&GR32&GS32&GT32&GU32&GV32&GW32&GX32&GY32&GZ32&HA32&HB32&HC32&HD32&HE32&HF32&HG32&HH32)-2),"")
C33: 6 | D33: Communication | E33: Message | F33: =$Q33 -> 0.05 | G33: =IF($H33="YES",$Q33,IF($H33="","",0)) -> 0.05 | H33: YES | I33: There were some grammar errors and informal language observed in the agent's responses. For example, phrases like "you can ignore them" and "I thought you don’t have that" could be phrased more formally. Additionally, some sentences were incomplete or lacked proper structure. However, the meaning was generally clear despite these issues. | Q33: =IFERROR(IF(H33="N/A",0,R33),"") -> 0.05 | R33: =IFERROR(HLOOKUP($V$9,$AJ$25:$AU$37,$T33,0),"") -> 0.05 | S33: =IF(OR($H33="NO",ISNUMBER($DA33)),$E33&"; ","") | T33: =T32+1 -> 9 | U33: Message | V33: 5 | W33: 5 | X33: 5 | Y33: 5 | Z33: 5 | AA33: 5 | AB33: 5 | AC33: 5 | AD33: 5 | AE33: 5 | AF33: 5 | AG33: 5 | AI33: Message | AJ33: =IFERROR(V33/SUM(V$28:V$37),"") -> 0.05 | AK33: =IFERROR(W33/SUM(W$28:W$37),"") -> 0.05 | AL33: =IFERROR(X33/SUM(X$28:X$37),"") -> 0.05 | AM33: =IFERROR(Y33/SUM(Y$28:Y$37),"") -> 0.05 | AN33: =IFERROR(Z33/SUM(Z$28:Z$37),"") -> 0.05 | AO33: =IFERROR(AA33/SUM(AA$28:AA$37),"") -> 0.05 | AP33: =IFERROR(AB33/SUM(AB$28:AB$37),"") -> 0.05 | AQ33: =IFERROR(AC33/SUM(AC$28:AC$37),"") -> 0.05 | ... AU33: =IFERROR(AG33/SUM(AG$28:AG$37),"") -> 0.05 | AX33: Poor sentence structure causing confusion | DA33: =MATCH(TRUE,DB33:FD33,0) -> #N/A | FF33: =IF(DB33=TRUE,AX33&"; ","") | FG33: =IF(DC33=TRUE,AY33&"; ","") | FH33: =IF(DD33=TRUE,AZ33&"; ","") | FI33: =IF(DE33=TRUE,BA33&"; ","") | FJ33: =IF(DF33=TRUE,BB33&"; ","") | FK33: =IF(DG33=TRUE,BC33&"; ","") | FL33: =IF(DH33=TRUE,BD33&"; ","") | FM33: =IF(DI33=TRUE,BE33&"; ","") | ... HH33: =IF(FD33=TRUE,CZ33&"; ","") | HJ33: =IFERROR(LEFT(FF33&FG33&FH33&FI33&FJ33&FK33&FL33&FM33&FN33&FO33&FP33&FQ33&FR33&FS33&FT33&FU33&FV33&FW33&FX33&FY33&FZ33&GA33&GB33&GC33&GD33&GE33&GF33&GG33&GH33&GI33&GJ33&GK33&GL33&GM33&GN33&GO33&GP33&GQ33&GR33&GS33&GT33&GU33&GV33&GW33&GX33&GY33&GZ33&HA33&HB33&HC33&HD33&HE33&HF33&HG33&HH33,LEN(FF33&FG33&FH33&FI33&FJ33&FK33&FL33&FM33&FN33&FO33&FP33&FQ33&FR33&FS33&FT33&FU33&FV33&FW33&FX33&FY33&FZ33&GA33&GB33&GC33&GD33&GE33&GF33&GG33&GH33&GI33&GJ33&GK33&GL33&GM33&GN33&GO33&GP33&GQ33&GR33&GS33&GT33&GU33&GV33&GW33&GX33&GY33&GZ33&HA33&HB33&HC33&HD33&HE33&HF33&HG33&HH33)-2),"")
C34: 7 | E34: Manner | F34: =$Q34 -> 0.05 | G34: =IF($H34="YES",$Q34,IF($H34="","",0)) -> 0.05 | H34: YES | I34: The agent demonstrated confidence and competence in their message delivery. They spoke clearly and fluently without any stammering, stuttering, or mumbling. The agent's tone was professional, and there is no indication that their accent negatively affected the customer's understanding. Overall, the communication was effective and contributed to a positive experience for the caller. | Q34: =IFERROR(IF(H34="N/A",0,R34),"") -> 0.05 | R34: =IFERROR(HLOOKUP($V$9,$AJ$25:$AU$37,$T34,0),"") -> 0.05 | S34: =IF(OR($H34="NO",ISNUMBER($DA34)),$E34&"; ","") | T34: =T33+1 -> 10 | U34: Manner | V34: 5 | W34: 5 | X34: 5 | Y34: 5 | Z34: 5 | AA34: 5 | AB34: 5 | AC34: 5 | AD34: 5 | AE34: 5 | AF34: 5 | AG34: 5 | AI34: Manner | AJ34: =IFERROR(V34/SUM(V$28:V$37),"") -> 0.05 | AK34: =IFERROR(W34/SUM(W$28:W$37),"") -> 0.05 | AL34: =IFERROR(X34/SUM(X$28:X$37),"") -> 0.05 | AM34: =IFERROR(Y34/SUM(Y$28:Y$37),"") -> 0.05 | AN34: =IFERROR(Z34/SUM(Z$28:Z$37),"") -> 0.05 | AO34: =IFERROR(AA34/SUM(AA$28:AA$37),"") -> 0.05 | AP34: =IFERROR(AB34/SUM(AB$28:AB$37),"") -> 0.05 | AQ34: =IFERROR(AC34/SUM(AC$28:AC$37),"") -> 0.05 | ... AU34: =IFERROR(AG34/SUM(AG$28:AG$37),"") -> 0.05 | AX34: Lacked confidence | AY34: Displayed poor competence | DA34: =MATCH(TRUE,DB34:FD34,0) -> #N/A | FF34: =IF(DB34=TRUE,AX34&"; ","") | FG34: =IF(DC34=TRUE,AY34&"; ","") | FH34: =IF(DD34=TRUE,AZ34&"; ","") | FI34: =IF(DE34=TRUE,BA34&"; ","") | FJ34: =IF(DF34=TRUE,BB34&"; ","") | FK34: =IF(DG34=TRUE,BC34&"; ","") | FL34: =IF(DH34=TRUE,BD34&"; ","") | FM34: =IF(DI34=TRUE,BE34&"; ","") | ... HH34: =IF(FD34=TRUE,CZ34&"; ","") | HJ34: =IFERROR(LEFT(FF34&FG34&FH34&FI34&FJ34&FK34&FL34&FM34&FN34&FO34&FP34&FQ34&FR34&FS34&FT34&FU34&FV34&FW34&FX34&FY34&FZ34&GA34&GB34&GC34&GD34&GE34&GF34&GG34&GH34&GI34&GJ34&GK34&GL34&GM34&GN34&GO34&GP34&GQ34&GR34&GS34&GT34&GU34&GV34&GW34&GX34&GY34&GZ34&HA34&HB34&HC34&HD34&HE34&HF34&HG34&HH34,LEN(FF34&FG34&FH34&FI34&FJ34&FK34&FL34&FM34&FN34&FO34&FP34&FQ34&FR34&FS34&FT34&FU34&FV34&FW34&FX34&FY34&FZ34&GA34&GB34&GC34&GD34&GE34&GF34&GG34&GH34&GI34&GJ34&GK34&GL34&GM34&GN34&GO34&GP34&GQ34&GR34&GS34&GT34&GU34&GV34&GW34&GX34&GY34&GZ34&HA34&HB34&HC34&HD34&HE34&HF34&HG34&HH34)-2),"")
C35: 8 | D35: Customer Service | E35: Professionalism | F35: =$Q35 -> 0.08 | G35: =IF($H35="YES",$Q35,IF($H35="","",0)) -> 0.08 | H35: YES | I35: The agent consistently demonstrated politeness and professionalism throughout the interaction. They used respectful language, addressed the caller appropriately, and provided clear guidance while maintaining a supportive tone. The agent also expressed appreciation for the caller's patience and ensured they understood the setup process. | Q35: =IFERROR(IF(H35="N/A",0,R35),"") -> 0.08 | R35: =IFERROR(HLOOKUP($V$9,$AJ$25:$AU$37,$T35,0),"") -> 0.08 | S35: =IF(OR($H35="NO",ISNUMBER($DA35)),$E35&"; ","") | T35: =T34+1 -> 11 | U35: Professionalism | V35: 10 | W35: 10 | X35: 8 | Y35: 8 | Z35: 8 | AA35: 10 | AB35: 8 | AC35: 10 | AD35: 10 | AE35: 10 | AF35: 10 | AG35: 10 | AI35: Professionalism | AJ35: =IFERROR(V35/SUM(V$28:V$37),"") -> 0.1 | AK35: =IFERROR(W35/SUM(W$28:W$37),"") -> 0.1 | AL35: =IFERROR(X35/SUM(X$28:X$37),"") -> 0.08 | AM35: =IFERROR(Y35/SUM(Y$28:Y$37),"") -> 0.08 | AN35: =IFERROR(Z35/SUM(Z$28:Z$37),"") -> 0.08 | AO35: =IFERROR(AA35/SUM(AA$28:AA$37),"") -> 0.1 | AP35: =IFERROR(AB35/SUM(AB$28:AB$37),"") -> 0.08 | AQ35: =IFERROR(AC35/SUM(AC$28:AC$37),"") -> 0.1 | ... AU35: =IFERROR(AG35/SUM(AG$28:AG$37),"") -> 0.1 | AX35: Indifference and/or any form of rudeness | AY35: Unauthorized call release | AZ35: Performing non-business activities | DA35: =MATCH(TRUE,DB35:FD35,0) -> #N/A | FF35: =IF(DB35=TRUE,AX35&"; ","") | FG35: =IF(DC35=TRUE,AY35&"; ","") | FH35: =IF(DD35=TRUE,AZ35&"; ","") | FI35: =IF(DE35=TRUE,BA35&"; ","") | FJ35: =IF(DF35=TRUE,BB35&"; ","") | FK35: =IF(DG35=TRUE,BC35&"; ","") | FL35: =IF(DH35=TRUE,BD35&"; ","") | FM35: =IF(DI35=TRUE,BE35&"; ","") | ... HH35: =IF(FD35=TRUE,CZ35&"; ","") | HJ35: =IFERROR(LEFT(FF35&FG35&FH35&FI35&FJ35&FK35&FL35&FM35&FN35&FO35&FP35&FQ35&FR35&FS35&FT35&FU35&FV35&FW35&FX35&FY35&FZ35&GA35&GB35&GC35&GD35&GE35&GF35&GG35&GH35&GI35&GJ35&GK35&GL35&GM35&GN35&GO35&GP35&GQ35&GR35&GS35&GT35&GU35&GV35&GW35&GX35&GY35&GZ35&HA35&HB35&HC35&HD35&HE35&HF35&HG35&HH35,LEN(FF35&FG35&FH35&FI35&FJ35&FK35&FL35&FM35&FN35&FO35&FP35&FQ35&FR35&FS35&FT35&FU35&FV35&FW35&FX35&FY35&FZ35&GA35&GB35&GC35&GD35&GE35&GF35&GG35&GH35&GI35&GJ35&GK35&GL35&GM35&GN35&GO35&GP35&GQ35&GR35&GS35&GT35&GU35&GV35&GW35&GX35&GY35&GZ35&HA35&HB35&HC35&HD35&HE35&HF35&HG35&HH35)-2),"")
C36: 9 | D36: Resolution | E36: Process Adherence | F36: =$Q36 -> 0.3 | G36: =IF($H36="YES",$Q36,IF($H36="","",0)) -> 0.3 | H36: YES | I36: The agent generally adhered to standards in follow-through and provided appropriate guidance throughout the interaction. He effectively guided the caller through the setup process and addressed concerns about the product. However, there were a few minor clarity gaps, particularly in the technical explanations regarding the node statuses and the setup process. There was no mention of RMA/refund disclosure or specific product safety guidelines in the conversation, so it’s unclear if those standards were addressed. Overall, the agent maintained a supportive approach while providing assistance. | Q36: =IFERROR(IF(H36="N/A",0,R36),"") -> 0.3 | R36: =IFERROR(HLOOKUP($V$9,$AJ$25:$AU$37,$T36,0),"") -> 0.3 | S36: =IF(OR($H36="NO",ISNUMBER($DA36)),$E36&"; ","") | T36: =T35+1 -> 12 | U36: Process Adherence | V36: 30 | W36: 30 | X36: 30 | Y36: 30 | Z36: 30 | AA36: 30 | AB36: 30 | AC36: 30 | AD36: 30 | AE36: 30 | AF36: 30 | AG36: 30 | AI36: Process Adherence | AJ36: =IFERROR(V36/SUM(V$28:V$37),"") -> 0.3 | AK36: =IFERROR(W36/SUM(W$28:W$37),"") -> 0.3 | AL36: =IFERROR(X36/SUM(X$28:X$37),"") -> 0.3 | AM36: =IFERROR(Y36/SUM(Y$28:Y$37),"") -> 0.3 | AN36: =IFERROR(Z36/SUM(Z$28:Z$37),"") -> 0.3 | AO36: =IFERROR(AA36/SUM(AA$28:AA$37),"") -> 0.3 | AP36: =IFERROR(AB36/SUM(AB$28:AB$37),"") -> 0.3 | AQ36: =IFERROR(AC36/SUM(AC$28:AC$37),"") -> 0.3 | ... AU36: =IFERROR(AG36/SUM(AG$28:AG$37),"") -> 0.3 | AX36: Delayed SLA for action and/or follow through | AY36: Escalation RMA Refund Product Safety Process | DA36: =MATCH(TRUE,DB36:FD36,0) -> #N/A | FF36: =IF(DB36=TRUE,AX36&"; ","") | FG36: =IF(DC36=TRUE,AY36&"; ","") | FH36: =IF(DD36=TRUE,AZ36&"; ","") | FI36: =IF(DE36=TRUE,BA36&"; ","") | FJ36: =IF(DF36=TRUE,BB36&"; ","") | FK36: =IF(DG36=TRUE,BC36&"; ","") | FL36: =IF(DH36=TRUE,BD36&"; ","") | FM36: =IF(DI36=TRUE,BE36&"; ","") | ... HH36: =IF(FD36=TRUE,CZ36&"; ","") | HJ36: =IFERROR(LEFT(FF36&FG36&FH36&FI36&FJ36&FK36&FL36&FM36&FN36&FO36&FP36&FQ36&FR36&FS36&FT36&FU36&FV36&FW36&FX36&FY36&FZ36&GA36&GB36&GC36&GD36&GE36&GF36&GG36&GH36&GI36&GJ36&GK36&GL36&GM36&GN36&GO36&GP36&GQ36&GR36&GS36&GT36&GU36&GV36&GW36&GX36&GY36&GZ36&HA36&HB36&HC36&HD36&HE36&HF36&HG36&HH36,LEN(FF36&FG36&FH36&FI36&FJ36&FK36&FL36&FM36&FN36&FO36&FP36&FQ36&FR36&FS36&FT36&FU36&FV36&FW36&FX36&FY36&FZ36&GA36&GB36&GC36&GD36&GE36&GF36&GG36&GH36&GI36&GJ36&GK36&GL36&GM36&GN36&GO36&GP36&GQ36&GR36&GS36&GT36&GU36&GV36&GW36&GX36&GY36&GZ36&HA36&HB36&HC36&HD36&HE36&HF36&HG36&HH36)-2),"")
