Workbook

Sheet Quick Start
B1: QA SCORING WORKBOOK — QUICK START GUIDE
B2: Resolution-focused coaching QA: one form per interaction, evidence-based indicator ratings, weighted 0-5 scoring, journey-level tracking and TEAM scoring for multi-touch cases. Yellow cells are YOUR inputs — everything else calculates or is reference.
B4: 1 · THE WORKING SHEETS
B5: Scoring Form | C5: The blank form you fill for EVERY interaction you review. Make a copy of this sheet per review (right-click tab → Move or Copy → Create a copy) so the master stays blank.
B6: Scoring Guide | C6: Reference: how-to steps, the 0-5 score anchors, what Met/Partial/Missed/N.A. mean, category objectives and watch-fors, and the result bands. Read once before your first review; return whenever unsure.
B7: Multi-Touch Guide | C7: Rules for cases handled by multiple agents: how to score each touch fairly, who owns handoff failures, plus a full real-case walkthrough (the Stell journey) showing where a support chain broke and recovered.
B8: Team Scoring | C8: The team layer: the Team Score formula component by component, how to read the gap between execution and outcome, a LIVE category heatmap showing where the team is weak, the 8 team opportunities identified from the Stell journey with owners, and a 6-step recipe to run a team review on your own journeys.
B9: Example (Filled) | C9: A complete, real worked review — the final touch of the Stell case (Eric Marbella). Shows exactly how detailed your evidence should be, how indicator ratings map to a final score, and how critical failures are written up. Copy its style.
B10: Case Tracker | C10: The log. One row per reviewed touch (date, agent, 7 scores, auto weighted % and band). Reuse a Case ID across rows for multi-touch journeys. Team Average at row 51; Team/Journey Scores section at row 53.
B12: 2 · HOW TO SCORE ONE INTERACTION (Scoring Form, ~15 min)
B13: Step 1 — Case Information | C13: Fill the yellow cells: agent, ticket, dates, product. Dropdowns: Warranty, Channel, Case Type, SLA. Write a 2-3 sentence Case Summary. Multi-touch? Set Touch # and fill 'Inherited context' (what this agent received from prior touches).
B14: Step 2 — Rate the indicators | C14: Each of the 7 categories lists 5-8 behaviors. Rate each: Met / Partial / Missed / N.A. (dropdown). N.A. = genuinely not applicable (e.g., no escalation involved) — it is excluded from the math, never a shortcut.
B15: Step 3 — Capture evidence | C15: Next to every rating, write WHY: a quote, timestamp, or note excerpt. 'Customer said X at 28:10' beats 'communication was good'. The Example sheet shows the standard.
B16: Step 4 — Set the final score | C16: A suggested score appears automatically (Met=5, Partial=2.5, Missed=0, averaged). You may override it — your judgment prevails — but the anchor text that appears beside your score tells you what a 4 vs a 3 means. Apply the rubric's automatic deductions (e.g., missed callback) even if indicators average higher.
B17: Step 5 — Outcome & disconnect | C17: Classify the Resolution Outcome (dropdown) and the primary positive outcome achieved. If the call disconnected, record the follow-up taken — 'Yes disconnect + no follow-up' auto-flags a missed ownership opportunity in red.
B18: Step 6 — Critical failures | C18: Answer Yes/No on all 11 conditions. ANY Yes turns the banner red: automatic review, regardless of the score. These include premature RESOLVED closure, PCI/compliance breaches, and unescalated management/legal requests.
B19: Step 7 — Coaching sections | C19: 3 strengths, 3 improvements, a specific coaching recommendation (at least one is mandatory per review), organizational insights, journey notes (multi-touch), and the final assessment.
B20: Step 8 — Log it | C20: Add one row in the Case Tracker: date, Case ID, agent, touch #, and your 7 final scores. Weighted % and band compute themselves.
B22: 3 · WHAT YOU TYPE vs WHAT CALCULATES ITSELF
B23: You type (yellow cells) | C23: Case info · indicator ratings (dropdowns) · evidence text · the 7 final 0-5 scores · outcome dropdowns · critical-failure Yes/No · coaching text · tracker rows · Team Score's Outcome and Continuity (0-5).
B24: Calculates automatically | C24: Suggested score per category · anchor description beside each score · Score Summary table · Weighted Total = Σ(score÷5 × weight) with weights 30/20/15/15/10/5/5 · result band · disconnect flag · critical-failure banner · tracker Weighted % and band · Team Average · Team Score = 50% avg touches + 30% Outcome/5 + 20% Continuity/5 · the Team Scoring sheet's category heatmap.
B25: Color language | C25: GREEN = strong (scores 4-5, total ≥85%) · YELLOW = developing (score 3, total 70-84%) · RED = needs focus (scores 0-2, total <70%, any critical failure, missed disconnect follow-up). Indicator cells: Met=green, Partial=yellow, Missed=red. Heatmap: category avg <2.75 red = team coaching theme.
B27: 4 · MULTI-TOUCH CASES IN SIX LINES (full rules: Multi-Touch Guide + Team Scoring)
B28: One form per touch | C28: Every agent gets their own form. Read all prior touches first; record what the agent inherited.
B29: Score the contribution | C29: Did THIS touch move the customer forward, given what it inherited? Agents aren't punished for inherited messes — only for what they pass downstream (thin notes, false RESOLVED, missed callbacks).
B30: Handoffs belong to the sender | C30: Bad notes that force rework = deduction for the earlier agent. Ignoring good notes and re-asking everything = deduction for the later agent.
B31: Log every touch, same Case ID | C31: Tracker rows side by side show exactly where the chain broke or recovered.
B32: Score the chain | C32: Bottom of the Case Tracker: type the Case ID in a Team/Journey row, judge Outcome (0-5) and Continuity (0-5) — the Team Score computes. Drives process fixes and team recognition, never individual discipline.
B33: Find the TEAM opportunities | C33: Team Scoring sheet: build the category heatmap over the journey's rows, take the bottom two categories as team coaching themes, scan for patterns repeating across 3+ agents, and write the action plan with named owners (section 5 there is the model).
B35: 5 · GOLDEN RULES
B36: • A closed case is NOT automatically a resolved case — and RESOLVED on a known-unresolved issue is a critical failure.
B37: • Any critical failure = automatic review, no matter how good the weighted score looks.
B38: • Resolution isn't only 'fixed': a proper RMA, a valid escalation, or an accurately explained limitation all count as positive outcomes.
B39: • Every review must produce at least one actionable coaching opportunity — and an operational improvement recommendation where applicable.
B40: • Evidence over opinion: every rating should be defensible with a quote, timestamp, or note excerpt.
B41: • Documentation supports outcomes but never outweighs troubleshooting, communication, or ownership — continuity, not compliance.
B42: • Reward judgment: an unresolved case with correct next steps and full ownership can still score well.
B43: • Team Scores coach the chain; individual forms coach the agent. Never mix the two purposes.
B45: Questions while reviewing? Order of reference: this sheet → Scoring Guide (anchors & criteria) → Multi-Touch Guide (journey rules) → Team Scoring (team layer & heatmap) → Example (Filled) (what good looks like).

Sheet Scoring Form - Jeneth Villanil
B1: SUPPORT QUALITY ASSURANCE — SCORING FORM
B2: Resolution-Focused Coaching & Performance Framework | Rate each behavior: Met / Partial / Missed / N.A. — then assign the 0-5 category score (suggested score is advisory).
B4: 1 · CASE INFORMATION
B5: Agent Name | C5: Jeneth Villanil | D5: Case / Ticket ID | E5: TE00089221 (Touch 1)
B6: Evaluator (QA) | C6: QA Review (per PMO Zither Calvin request) | D6: Interaction Date | E6: 2025-08-04 (Touch 1)
B7: Product | C7: Velop Pro 7 (mesh - 4th node) | D7: Channel | E7: Phone / Voice
B8: Warranty Status | C8: In Warranty | D8: Review Date | E8: Jun 15, 2026
B9: Case Type | C9: Technical - mesh node pairing / setup | D9: Interaction Duration | E9: Not specified
B10: Touch # (multi-touch case) | C10: 1 of 21 | D10: Prior touches reviewed? | E10: N/A - first touch in journey
B11: CSAT / Survey result | C11: Not captured | D11: FCR / total contacts | E11: FCR for this contact
B12: Total case time | C12: ~8 months / 21 touches (full journey) | D12: SLA status | E12: Within SLA
B13: Case Summary (customer issue & goal) | C13: Customer adding/pairing a 4th node to a Velop Pro 7 mesh system; needed setup assistance.
B14: Inherited context (what this agent received from prior touches) | C14: First touch - no inherited context.
B16: 2 · CATEGORY ASSESSMENTS
B17: 1. RESOLUTION / PROGRESS TOWARD RESOLUTION | F17: Weight: 30%
B18: Objective: Determine whether the interaction moved the customer meaningfully closer to resolution.
B19: Behavioral Indicator | C19: Assessment | D19: Evidence / Observation (quote or timestamp where possible)
B20: Issue resolved, or the strongest available outcome was achieved (RMA, valid escalation, limitation explained, education) | C20: Met | D20: 4th node paired successfully with Velop Pro 7; customer reported no issues.
B21: Reasonable troubleshooting was completed before any conclusion was reached | C21: Met
B22: Clear, actionable next steps were provided to the customer | C22: Met
B23: Resolution path was appropriate for the situation and warranty status | C23: Met
B24: Customer was moved meaningfully closer to a solution | C24: Met
B25: ⚠ Does NOT count: customer simply ends call; generic KB sent without troubleshooting; warranty used as reason to stop helping; escalation as shortcut; unsupported ISP blame; 'monitor & call back' with no plan; ownership transferred without expectations or documentation.
B26: Suggested score (auto from indicators — advisory only; evaluator judgment prevails) | C26: =IF((COUNTIF(C20:C24,"Met")+COUNTIF(C20:C24,"Partial")+COUNTIF(C20:C24,"Missed"))=0,"",ROUND((COUNTIF(C20:C24,"Met")*5+COUNTIF(C20:C24,"Partial")*2.5)/(COUNTIF(C20:C24,"Met")+COUNTIF(C20:C24,"Partial")+COUNTIF(C20:C24,"Missed")),1))
B27: FINAL CATEGORY SCORE (0–5) | C27: 5 | D27: =IF(C27="","← enter score; anchor description appears here",CHOOSE(C27+1,"Agent actions delayed, prevented, or negatively impacted resolution","Little or no meaningful progress","Limited progress despite available troubleshooting paths","Partial progress made but opportunities missed","Significant progress made with clear next steps","Issue resolved or strongest available outcome achieved"))
B28: Score reflects the cumulative effect of this touch within the 8-month journey: the Nov 24, 2025 hardware/RMA determination remains undelivered, and the case culminates here in executive-level escalation with no path forward offered. | C28: Clean, complete resolution at first contact - the strongest touch of the journey.
B30: 2. TECHNICAL ACCURACY | F30: Weight: 20%
B31: Objective: Evaluate the quality of troubleshooting and technical guidance.
B32: Behavioral Indicator | C32: Assessment | D32: Evidence / Observation (quote or timestamp where possible)
B33: Symptoms were identified correctly | C33: Met | D33: Symptom (node not paired) correctly identified and addressed.
B34: Relevant diagnostic questions were asked | C34: Met
B35: Logical troubleshooting methodology was followed | C35: Met
B36: Available tools were used appropriately | C36: Met
B37: Information provided was technically accurate | C37: Met
B38: Assumptions were validated; no unsupported conclusions | C38: Met
B39: Root cause (or likely cause) was identified when possible | C39: Met
B40: ⚠ Deduct for: incorrect technical information; skipped critical troubleshooting; misdiagnosis; unnecessary actions recommended; ISP or customer blamed without evidence; repeating basic steps the customer already completed.
B41: Suggested score (auto from indicators — advisory only; evaluator judgment prevails) | C41: =IF((COUNTIF(C33:C39,"Met")+COUNTIF(C33:C39,"Partial")+COUNTIF(C33:C39,"Missed"))=0,"",ROUND((COUNTIF(C33:C39,"Met")*5+COUNTIF(C33:C39,"Partial")*2.5)/(COUNTIF(C33:C39,"Met")+COUNTIF(C33:C39,"Partial")+COUNTIF(C33:C39,"Missed")),1))
B42: FINAL CATEGORY SCORE (0–5) | C42: 5 | D42: =IF(C42="","← enter score; anchor description appears here",CHOOSE(C42+1,"Agent actions delayed, prevented, or negatively impacted resolution","Little or no meaningful progress","Limited progress despite available troubleshooting paths","Partial progress made but opportunities missed","Significant progress made with clear next steps","Issue resolved or strongest available outcome achieved"))
B43: Individual diagnostic steps (signal/backhaul check, swap-test proposal) were sound, but the unvalidated reversal of a prior CAT-level conclusion undermines technical credibility. | C43: Pairing handled correctly with no rework needed.
...

Sheet Scoring Form - Deneive Luar
B1: SUPPORT QUALITY ASSURANCE — SCORING FORM
B2: Resolution-Focused Coaching & Performance Framework | Rate each behavior: Met / Partial / Missed / N.A. — then assign the 0-5 category score (suggested score is advisory).
B4: 1 · CASE INFORMATION
B5: Agent Name | C5: Deneive Luar | D5: Case / Ticket ID | E5: TE00089221 (Touch 2)
B6: Evaluator (QA) | C6: QA Review (per PMO Zither Calvin request) | D6: Interaction Date | E6: 2025-10-13 (Touch 2)
B7: Product | C7: Velop Pro 7 (mesh) | D7: Channel | E7: Phone / Voice
B8: Warranty Status | C8: In Warranty | D8: Review Date | E8: Jun 15, 2026
B9: Case Type | C9: Technical - connectivity / disconnection troubleshooting | D9: Interaction Duration | E9: Not specified
B10: Touch # (multi-touch case) | C10: 2 of 21 | D10: Prior touches reviewed? | E10: Yes - reviewed in full journey
B11: CSAT / Survey result | C11: Not captured | D11: FCR / total contacts | E11: Not FCR - issue recurs later
B12: Total case time | C12: ~8 months / 21 touches (full journey) | D12: SLA status | E12: Within SLA
B13: Case Summary (customer issue & goal) | C13: Customer reporting connectivity/disconnection issues on the mesh; agent performed reset/reposition troubleshooting.
B14: Inherited context (what this agent received from prior touches) | C14: Inherited a working setup from Touch 1; now addressing emerging connectivity instability.
B16: 2 · CATEGORY ASSESSMENTS
B17: 1. RESOLUTION / PROGRESS TOWARD RESOLUTION | F17: Weight: 30%
B18: Objective: Determine whether the interaction moved the customer meaningfully closer to resolution.
B19: Behavioral Indicator | C19: Assessment | D19: Evidence / Observation (quote or timestamp where possible)
B20: Issue resolved, or the strongest available outcome was achieved (RMA, valid escalation, limitation explained, education) | C20: Met | D20: Signal improved to -52 dBm; customer agreed to monitor (not a confirmed fix).
B21: Reasonable troubleshooting was completed before any conclusion was reached | C21: Partial
B22: Clear, actionable next steps were provided to the customer | C22: Met
B23: Resolution path was appropriate for the situation and warranty status | C23: Partial
B24: Customer was moved meaningfully closer to a solution | C24: Met
B25: ⚠ Does NOT count: customer simply ends call; generic KB sent without troubleshooting; warranty used as reason to stop helping; escalation as shortcut; unsupported ISP blame; 'monitor & call back' with no plan; ownership transferred without expectations or documentation.
B26: Suggested score (auto from indicators — advisory only; evaluator judgment prevails) | C26: =IF((COUNTIF(C20:C24,"Met")+COUNTIF(C20:C24,"Partial")+COUNTIF(C20:C24,"Missed"))=0,"",ROUND((COUNTIF(C20:C24,"Met")*5+COUNTIF(C20:C24,"Partial")*2.5)/(COUNTIF(C20:C24,"Met")+COUNTIF(C20:C24,"Partial")+COUNTIF(C20:C24,"Missed")),1))
B27: FINAL CATEGORY SCORE (0–5) | C27: 3 | D27: =IF(C27="","← enter score; anchor description appears here",CHOOSE(C27+1,"Agent actions delayed, prevented, or negatively impacted resolution","Little or no meaningful progress","Limited progress despite available troubleshooting paths","Partial progress made but opportunities missed","Significant progress made with clear next steps","Issue resolved or strongest available outcome achieved"))
B28: Score reflects the cumulative effect of this touch within the 8-month journey: the Nov 24, 2025 hardware/RMA determination remains undelivered, and the case culminates here in executive-level escalation with no path forward offered. | C28: Real progress (signal improved) but ended on 'monitor' rather than a confirmed resolution.
B30: 2. TECHNICAL ACCURACY | F30: Weight: 20%
B31: Objective: Evaluate the quality of troubleshooting and technical guidance.
B32: Behavioral Indicator | C32: Assessment | D32: Evidence / Observation (quote or timestamp where possible)
B33: Symptoms were identified correctly | C33: Met | D33: Diagnosed weak signal; reset/reposition addressed the symptom.
B34: Relevant diagnostic questions were asked | C34: Met
B35: Logical troubleshooting methodology was followed | C35: Met
B36: Available tools were used appropriately | C36: Met
B37: Information provided was technically accurate | C37: Met | D37: Signal reading (-52 dBm) used as objective evidence.
B38: Assumptions were validated; no unsupported conclusions | C38: Met
B39: Root cause (or likely cause) was identified when possible | C39: Partial
B40: ⚠ Deduct for: incorrect technical information; skipped critical troubleshooting; misdiagnosis; unnecessary actions recommended; ISP or customer blamed without evidence; repeating basic steps the customer already completed.
B41: Suggested score (auto from indicators — advisory only; evaluator judgment prevails) | C41: =IF((COUNTIF(C33:C39,"Met")+COUNTIF(C33:C39,"Partial")+COUNTIF(C33:C39,"Missed"))=0,"",ROUND((COUNTIF(C33:C39,"Met")*5+COUNTIF(C33:C39,"Partial")*2.5)/(COUNTIF(C33:C39,"Met")+COUNTIF(C33:C39,"Partial")+COUNTIF(C33:C39,"Missed")),1))
B42: FINAL CATEGORY SCORE (0–5) | C42: 4 | D42: =IF(C42="","← enter score; anchor description appears here",CHOOSE(C42+1,"Agent actions delayed, prevented, or negatively impacted resolution","Little or no meaningful progress","Limited progress despite available troubleshooting paths","Partial progress made but opportunities missed","Significant progress made with clear next steps","Issue resolved or strongest available outcome achieved"))
B43: Individual diagnostic steps (signal/backhaul check, swap-test proposal) were sound, but the unvalidated reversal of a prior CAT-level conclusion undermines technical credibility. | C43: Sound diagnostics - used an objective signal metric (-52 dBm).
...

Sheet Scoring Form - Dorothy Oraiz
B1: SUPPORT QUALITY ASSURANCE — SCORING FORM
B2: Resolution-Focused Coaching & Performance Framework | Rate each behavior: Met / Partial / Missed / N.A. — then assign the 0-5 category score (suggested score is advisory).
B4: 1 · CASE INFORMATION
B5: Agent Name | C5: Dorothy Belle Oraiz | D5: Case / Ticket ID | E5: TE00089221 (Touch 3)
B6: Evaluator (QA) | C6: QA Review (per PMO Zither Calvin request) | D6: Interaction Date | E6: 2025-10-20 (Touch 3)
B7: Product | C7: Velop Pro 7 (mesh) | D7: Channel | E7: Phone / Voice
B8: Warranty Status | C8: In Warranty | D8: Review Date | E8: Jun 15, 2026
B9: Case Type | C9: Technical - persistent disconnection | D9: Interaction Duration | E9: Not specified
B10: Touch # (multi-touch case) | C10: 3 of 21 | D10: Prior touches reviewed? | E10: Yes - reviewed in full journey
B11: CSAT / Survey result | C11: Not captured | D11: FCR / total contacts | E11: Not FCR - escalated
B12: Total case time | C12: ~8 months / 21 touches (full journey) | D12: SLA status | E12: Within SLA (24-48h callback set)
B13: Case Summary (customer issue & goal) | C13: Persistent disconnection on the mesh; agent attempted diagnostics but was blocked by a router admin-password issue, then escalated to L2 with supervisor approval and a 24-48hr callback.
B14: Inherited context (what this agent received from prior touches) | C14: Inherited an unresolved, recurring disconnection issue (monitoring from Touch 2 did not hold).
B16: 2 · CATEGORY ASSESSMENTS
B17: 1. RESOLUTION / PROGRESS TOWARD RESOLUTION | F17: Weight: 30%
B18: Objective: Determine whether the interaction moved the customer meaningfully closer to resolution.
B19: Behavioral Indicator | C19: Assessment | D19: Evidence / Observation (quote or timestamp where possible)
B20: Issue resolved, or the strongest available outcome was achieved (RMA, valid escalation, limitation explained, education) | C20: Met | D20: Strong available outcome given the blocker: valid L2 escalation with supervisor approval and a 24-48hr callback.
B21: Reasonable troubleshooting was completed before any conclusion was reached | C21: Met
B22: Clear, actionable next steps were provided to the customer | C22: Met
B23: Resolution path was appropriate for the situation and warranty status | C23: Met
B24: Customer was moved meaningfully closer to a solution | C24: Partial
B25: ⚠ Does NOT count: customer simply ends call; generic KB sent without troubleshooting; warranty used as reason to stop helping; escalation as shortcut; unsupported ISP blame; 'monitor & call back' with no plan; ownership transferred without expectations or documentation.
B26: Suggested score (auto from indicators — advisory only; evaluator judgment prevails) | C26: =IF((COUNTIF(C20:C24,"Met")+COUNTIF(C20:C24,"Partial")+COUNTIF(C20:C24,"Missed"))=0,"",ROUND((COUNTIF(C20:C24,"Met")*5+COUNTIF(C20:C24,"Partial")*2.5)/(COUNTIF(C20:C24,"Met")+COUNTIF(C20:C24,"Partial")+COUNTIF(C20:C24,"Missed")),1))
B27: FINAL CATEGORY SCORE (0–5) | C27: 4 | D27: =IF(C27="","← enter score; anchor description appears here",CHOOSE(C27+1,"Agent actions delayed, prevented, or negatively impacted resolution","Little or no meaningful progress","Limited progress despite available troubleshooting paths","Partial progress made but opportunities missed","Significant progress made with clear next steps","Issue resolved or strongest available outcome achieved"))
B28: Score reflects the cumulative effect of this touch within the 8-month journey: the Nov 24, 2025 hardware/RMA determination remains undelivered, and the case culminates here in executive-level escalation with no path forward offered. | C28: Made the right call - escalated appropriately when blocked, with a concrete callback path.
B30: 2. TECHNICAL ACCURACY | F30: Weight: 20%
B31: Objective: Evaluate the quality of troubleshooting and technical guidance.
B32: Behavioral Indicator | C32: Assessment | D32: Evidence / Observation (quote or timestamp where possible)
B33: Symptoms were identified correctly | C33: Met | D33: Persistent disconnection correctly characterized.
B34: Relevant diagnostic questions were asked | C34: Partial
B35: Logical troubleshooting methodology was followed | C35: Met
B36: Available tools were used appropriately | C36: Partial | D36: Diagnostics blocked by a router admin-password issue - limited tool access.
B37: Information provided was technically accurate | C37: Met
B38: Assumptions were validated; no unsupported conclusions | C38: Partial
B39: Root cause (or likely cause) was identified when possible | C39: Met
B40: ⚠ Deduct for: incorrect technical information; skipped critical troubleshooting; misdiagnosis; unnecessary actions recommended; ISP or customer blamed without evidence; repeating basic steps the customer already completed.
B41: Suggested score (auto from indicators — advisory only; evaluator judgment prevails) | C41: =IF((COUNTIF(C33:C39,"Met")+COUNTIF(C33:C39,"Partial")+COUNTIF(C33:C39,"Missed"))=0,"",ROUND((COUNTIF(C33:C39,"Met")*5+COUNTIF(C33:C39,"Partial")*2.5)/(COUNTIF(C33:C39,"Met")+COUNTIF(C33:C39,"Partial")+COUNTIF(C33:C39,"Missed")),1))
B42: FINAL CATEGORY SCORE (0–5) | C42: 3 | D42: =IF(C42="","← enter score; anchor description appears here",CHOOSE(C42+1,"Agent actions delayed, prevented, or negatively impacted resolution","Little or no meaningful progress","Limited progress despite available troubleshooting paths","Partial progress made but opportunities missed","Significant progress made with clear next steps","Issue resolved or strongest available outcome achieved"))
B43: Individual diagnostic steps (signal/backhaul check, swap-test proposal) were sound, but the unvalidated reversal of a prior CAT-level conclusion undermines technical credibility. | C43: Diagnosis was sound; depth limited by the password/access blocker (not the agent's fault).
...

Sheet Scoring Form - Eric Marbella
B1: SUPPORT QUALITY ASSURANCE — SCORING FORM
B2: Resolution-Focused Coaching & Performance Framework | Rate each behavior: Met / Partial / Missed / N.A. — then assign the 0-5 category score (suggested score is advisory).
B4: 1 · CASE INFORMATION
B5: Agent Name | C5: Eric Marbella | D5: Case / Ticket ID | E5: TE00089221 (L2: LTS00106915 / LTS00109368)
B6: Evaluator (QA) | C6: QA Review (per PMO Zither Calvin request) | D6: Interaction Date | E6: 2025-10-20 - 2026-02-24 (Touches 4-21)
B7: Product | C7: Velop Pro 7 (mesh - node 4 unstable) | D7: Channel | E7: Phone / Voice + Email
B8: Warranty Status | C8: In Warranty (replacement/RMA pursued) | D8: Review Date | E8: Jun 15, 2026
B9: Case Type | C9: Technical - node instability -> replacement/RMA, entangled with email deliverability | D9: Interaction Duration | E9: 16 touches over ~5 months
B10: Touch # (multi-touch case) | C10: 16 touches (T4, T5, T8-T21) - consolidated agent scorecard; dominant agent on the case | D10: Prior touches reviewed? | E10: Yes - full journey reviewed
B11: CSAT / Survey result | C11: Implied very low (customer escalated to CEO) | D11: FCR / total contacts | E11: Not FCR - 16 touches by this agent
B12: Total case time | C12: ~8 months / 21 touches total | D12: SLA status | E12: SLA BREACHED (Mar 2-3 24-48h missed; PMO intervention)
B13: Case Summary (customer issue & goal) | C13: Customer's Velop Pro 7 node 4 remained unstable. Across 16 touches Eric drove signal checks, firmware revert, product-registration fixes, and an RMA/replacement effort - all entangled with an email-deliverability problem isolated to the customer's Earthlink address. The case fragmented across multiple tickets, sysinfo logs were lost twice, an RMA determination was reversed, the final SLA was missed, and the customer escalated to the CEO.
B14: Inherited context (what this agent received from prior touches) | C14: Took over from Dorothy's L2 escalation (Touch 3). Inherited an unresolved node-disconnection case that became a replacement effort; also inherited (undocumented) the email-deliverability problem first seen at Touch 6.
B16: 2 · CATEGORY ASSESSMENTS
B17: 1. RESOLUTION / PROGRESS TOWARD RESOLUTION | F17: Weight: 30%
B18: Objective: Determine whether the interaction moved the customer meaningfully closer to resolution.
B19: Behavioral Indicator | C19: Assessment | D19: Evidence / Observation (quote or timestamp where possible)
B20: Issue resolved, or the strongest available outcome was achieved (RMA, valid escalation, limitation explained, education) | C20: Met | D20: Strong-available outcome NOT achieved: by Touch 21 the case is unresolved, the RMA was reversed (T18), and the customer escalated to the CEO (Mar 16).
B21: Reasonable troubleshooting was completed before any conclusion was reached | C21: Partial | D21: Troubleshooting was often re-introduced (T11) that the customer believed was already done; sysinfo logs were lost twice (T19, reopened T17).
B22: Clear, actionable next steps were provided to the customer | C22: Met
B23: Resolution path was appropriate for the situation and warranty status | C23: Partial
B24: Customer was moved meaningfully closer to a solution | C24: Met
B25: ⚠ Does NOT count: customer simply ends call; generic KB sent without troubleshooting; warranty used as reason to stop helping; escalation as shortcut; unsupported ISP blame; 'monitor & call back' with no plan; ownership transferred without expectations or documentation.
B26: Suggested score (auto from indicators — advisory only; evaluator judgment prevails) | C26: =IF((COUNTIF(C20:C24,"Met")+COUNTIF(C20:C24,"Partial")+COUNTIF(C20:C24,"Missed"))=0,"",ROUND((COUNTIF(C20:C24,"Met")*5+COUNTIF(C20:C24,"Partial")*2.5)/(COUNTIF(C20:C24,"Met")+COUNTIF(C20:C24,"Partial")+COUNTIF(C20:C24,"Missed")),1))
B27: FINAL CATEGORY SCORE (0–5) | C27: 3 | D27: =IF(C27="","← enter score; anchor description appears here",CHOOSE(C27+1,"Agent actions delayed, prevented, or negatively impacted resolution","Little or no meaningful progress","Limited progress despite available troubleshooting paths","Partial progress made but opportunities missed","Significant progress made with clear next steps","Issue resolved or strongest available outcome achieved"))
B28: Score reflects the cumulative effect of this touch within the 8-month journey: the Nov 24, 2025 hardware/RMA determination remains undelivered, and the case culminates here in executive-level escalation with no path forward offered. | C28: Months of genuine effort and some real wins (T12), but the case ends unresolved with a reversed RMA and a CEO escalation - net resolution progress is weak.
B30: 2. TECHNICAL ACCURACY | F30: Weight: 20%
B31: Objective: Evaluate the quality of troubleshooting and technical guidance.
B32: Behavioral Indicator | C32: Assessment | D32: Evidence / Observation (quote or timestamp where possible)
B33: Symptoms were identified correctly | C33: Met | D33: Diagnosis was generally competent mid-journey (T12 registration fix; T14-16 isolating the email issue to Earthlink).
B34: Relevant diagnostic questions were asked | C34: Partial
B35: Logical troubleshooting methodology was followed | C35: Met | D35: Methodology held early/mid but degraded late (T17 escalation before confirming logs were captured; T18 RMA walk-back).
B36: Available tools were used appropriately | C36: Partial
B37: Information provided was technically accurate | C37: Met
B38: Assumptions were validated; no unsupported conclusions | C38: Partial
B39: Root cause (or likely cause) was identified when possible | C39: Met
B40: ⚠ Deduct for: incorrect technical information; skipped critical troubleshooting; misdiagnosis; unnecessary actions recommended; ISP or customer blamed without evidence; repeating basic steps the customer already completed.
B41: Suggested score (auto from indicators — advisory only; evaluator judgment prevails) | C41: =IF((COUNTIF(C33:C39,"Met")+COUNTIF(C33:C39,"Partial")+COUNTIF(C33:C39,"Missed"))=0,"",ROUND((COUNTIF(C33:C39,"Met")*5+COUNTIF(C33:C39,"Partial")*2.5)/(COUNTIF(C33:C39,"Met")+COUNTIF(C33:C39,"Partial")+COUNTIF(C33:C39,"Missed")),1))
B42: FINAL CATEGORY SCORE (0–5) | C42: 3 | D42: =IF(C42="","← enter score; anchor description appears here",CHOOSE(C42+1,"Agent actions delayed, prevented, or negatively impacted resolution","Little or no meaningful progress","Limited progress despite available troubleshooting paths","Partial progress made but opportunities missed","Significant progress made with clear next steps","Issue resolved or strongest available outcome achieved"))
B43: Individual diagnostic steps (signal/backhaul check, swap-test proposal) were sound, but the unvalidated reversal of a prior CAT-level conclusion undermines technical credibility. | C43: Technically capable mid-journey (email-deliverability isolation to Earthlink was good detective work); late-journey accuracy slipped.
...

Sheet Scoring Form - Stephanie Luspo
B1: SUPPORT QUALITY ASSURANCE — SCORING FORM
B2: Resolution-Focused Coaching & Performance Framework | Rate each behavior: Met / Partial / Missed / N.A. — then assign the 0-5 category score (suggested score is advisory).
B4: 1 · CASE INFORMATION
B5: Agent Name | C5: Stephanie 'Belle' Luspo | D5: Case / Ticket ID | E5: TE00089221 (Touch 6)
B6: Evaluator (QA) | C6: QA Review (per PMO Zither Calvin request) | D6: Interaction Date | E6: 2025-11-21 (Touch 6)
B7: Product | C7: Velop Pro 7 (mesh) | D7: Channel | E7: Phone / Voice
B8: Warranty Status | C8: In Warranty | D8: Review Date | E8: Jun 15, 2026
B9: Case Type | C9: Technical - follow-up; missed email/hotline delivery | D9: Interaction Duration | E9: Not specified
B10: Touch # (multi-touch case) | C10: 6 of 21 | D10: Prior touches reviewed? | E10: Yes - reviewed in full journey
B11: CSAT / Survey result | C11: Not captured | D11: FCR / total contacts | E11: Not FCR
B12: Total case time | C12: ~8 months / 21 touches (full journey) | D12: SLA status | E12: Within SLA
B13: Case Summary (customer issue & goal) | C13: Customer called because he never received Eric's Oct 21 follow-up email/hotline. Agent's attempt to resend failed, so she provided the hotline number directly by phone.
B14: Inherited context (what this agent received from prior touches) | C14: Inherited Eric's open follow-up (Touch 5) - but the Oct 21 email never reached the customer (first surfacing of the email-deliverability problem).
B16: 2 · CATEGORY ASSESSMENTS
B17: 1. RESOLUTION / PROGRESS TOWARD RESOLUTION | F17: Weight: 30%
B18: Objective: Determine whether the interaction moved the customer meaningfully closer to resolution.
B19: Behavioral Indicator | C19: Assessment | D19: Evidence / Observation (quote or timestamp where possible)
B20: Issue resolved, or the strongest available outcome was achieved (RMA, valid escalation, limitation explained, education) | C20: Met | D20: Workaround delivered (hotline given verbally) but the underlying email-delivery failure was not resolved.
B21: Reasonable troubleshooting was completed before any conclusion was reached | C21: Partial
B22: Clear, actionable next steps were provided to the customer | C22: Met
B23: Resolution path was appropriate for the situation and warranty status | C23: Partial
B24: Customer was moved meaningfully closer to a solution | C24: Met
B25: ⚠ Does NOT count: customer simply ends call; generic KB sent without troubleshooting; warranty used as reason to stop helping; escalation as shortcut; unsupported ISP blame; 'monitor & call back' with no plan; ownership transferred without expectations or documentation.
B26: Suggested score (auto from indicators — advisory only; evaluator judgment prevails) | C26: =IF((COUNTIF(C20:C24,"Met")+COUNTIF(C20:C24,"Partial")+COUNTIF(C20:C24,"Missed"))=0,"",ROUND((COUNTIF(C20:C24,"Met")*5+COUNTIF(C20:C24,"Partial")*2.5)/(COUNTIF(C20:C24,"Met")+COUNTIF(C20:C24,"Partial")+COUNTIF(C20:C24,"Missed")),1))
B27: FINAL CATEGORY SCORE (0–5) | C27: 3 | D27: =IF(C27="","← enter score; anchor description appears here",CHOOSE(C27+1,"Agent actions delayed, prevented, or negatively impacted resolution","Little or no meaningful progress","Limited progress despite available troubleshooting paths","Partial progress made but opportunities missed","Significant progress made with clear next steps","Issue resolved or strongest available outcome achieved"))
B28: Score reflects the cumulative effect of this touch within the 8-month journey: the Nov 24, 2025 hardware/RMA determination remains undelivered, and the case culminates here in executive-level escalation with no path forward offered. | C28: Recovered the immediate contact gap with a verbal hotline, but the email-delivery root issue was left unaddressed.
B30: 2. TECHNICAL ACCURACY | F30: Weight: 20%
B31: Objective: Evaluate the quality of troubleshooting and technical guidance.
B32: Behavioral Indicator | C32: Assessment | D32: Evidence / Observation (quote or timestamp where possible)
B33: Symptoms were identified correctly | C33: Met | D33: Identified that the customer never received the prior email; resend then failed.
B34: Relevant diagnostic questions were asked | C34: Partial
B35: Logical troubleshooting methodology was followed | C35: Met
B36: Available tools were used appropriately | C36: Partial
B37: Information provided was technically accurate | C37: Met
B38: Assumptions were validated; no unsupported conclusions | C38: Partial
B39: Root cause (or likely cause) was identified when possible | C39: Met
B40: ⚠ Deduct for: incorrect technical information; skipped critical troubleshooting; misdiagnosis; unnecessary actions recommended; ISP or customer blamed without evidence; repeating basic steps the customer already completed.
B41: Suggested score (auto from indicators — advisory only; evaluator judgment prevails) | C41: =IF((COUNTIF(C33:C39,"Met")+COUNTIF(C33:C39,"Partial")+COUNTIF(C33:C39,"Missed"))=0,"",ROUND((COUNTIF(C33:C39,"Met")*5+COUNTIF(C33:C39,"Partial")*2.5)/(COUNTIF(C33:C39,"Met")+COUNTIF(C33:C39,"Partial")+COUNTIF(C33:C39,"Missed")),1))
B42: FINAL CATEGORY SCORE (0–5) | C42: 3 | D42: =IF(C42="","← enter score; anchor description appears here",CHOOSE(C42+1,"Agent actions delayed, prevented, or negatively impacted resolution","Little or no meaningful progress","Limited progress despite available troubleshooting paths","Partial progress made but opportunities missed","Significant progress made with clear next steps","Issue resolved or strongest available outcome achieved"))
B43: Individual diagnostic steps (signal/backhaul check, swap-test proposal) were sound, but the unvalidated reversal of a prior CAT-level conclusion undermines technical credibility. | C43: Spotted the missed-email symptom; did not diagnose why delivery failed.
...

Sheet Scoring Form - John Pagurayan
B1: SUPPORT QUALITY ASSURANCE — SCORING FORM
B2: Resolution-Focused Coaching & Performance Framework | Rate each behavior: Met / Partial / Missed / N.A. — then assign the 0-5 category score (suggested score is advisory).
B4: 1 · CASE INFORMATION
B5: Agent Name | C5: John Pagurayan | D5: Case / Ticket ID | E5: TE00089221 (Touch 7)
B6: Evaluator (QA) | C6: QA Review (per PMO Zither Calvin request) | D6: Interaction Date | E6: 2025-11-21 (Touch 7)
B7: Product | C7: Velop Pro 7 (mesh) | D7: Channel | E7: Phone / Voice
B8: Warranty Status | C8: In Warranty (later pursued for replacement) | D8: Review Date | E8: Jun 15, 2026
B9: Case Type | C9: Technical - status / next-steps contact | D9: Interaction Duration | E9: Not specified
B10: Touch # (multi-touch case) | C10: 7 of 21 | D10: Prior touches reviewed? | E10: Yes - reviewed in full journey
B11: CSAT / Survey result | C11: Not captured | D11: FCR / total contacts | E11: Not FCR
B12: Total case time | C12: ~8 months / 21 touches (full journey) | D12: SLA status | E12: Within SLA
B13: Case Summary (customer issue & goal) | C13: Status/next-steps contact. Customer declined further troubleshooting; agent informed him the unit is EOL and mentioned consulting 'CAT-Eric', but no formal escalation was made or documented.
B14: Inherited context (what this agent received from prior touches) | C14: Inherited an open, recurring node issue with an unresolved email-delivery problem from Touch 6.
B16: 2 · CATEGORY ASSESSMENTS
B17: 1. RESOLUTION / PROGRESS TOWARD RESOLUTION | F17: Weight: 30%
B18: Objective: Determine whether the interaction moved the customer meaningfully closer to resolution.
B19: Behavioral Indicator | C19: Assessment | D19: Evidence / Observation (quote or timestamp where possible)
B20: Issue resolved, or the strongest available outcome was achieved (RMA, valid escalation, limitation explained, education) | C20: Missed | D20: No meaningful progress; customer declined further steps and was told the unit is EOL.
B21: Reasonable troubleshooting was completed before any conclusion was reached | C21: Partial
B22: Clear, actionable next steps were provided to the customer | C22: Missed
B23: Resolution path was appropriate for the situation and warranty status | C23: Partial
B24: Customer was moved meaningfully closer to a solution | C24: Missed
B25: ⚠ Does NOT count: customer simply ends call; generic KB sent without troubleshooting; warranty used as reason to stop helping; escalation as shortcut; unsupported ISP blame; 'monitor & call back' with no plan; ownership transferred without expectations or documentation.
B26: Suggested score (auto from indicators — advisory only; evaluator judgment prevails) | C26: =IF((COUNTIF(C20:C24,"Met")+COUNTIF(C20:C24,"Partial")+COUNTIF(C20:C24,"Missed"))=0,"",ROUND((COUNTIF(C20:C24,"Met")*5+COUNTIF(C20:C24,"Partial")*2.5)/(COUNTIF(C20:C24,"Met")+COUNTIF(C20:C24,"Partial")+COUNTIF(C20:C24,"Missed")),1))
B27: FINAL CATEGORY SCORE (0–5) | C27: 2 | D27: =IF(C27="","← enter score; anchor description appears here",CHOOSE(C27+1,"Agent actions delayed, prevented, or negatively impacted resolution","Little or no meaningful progress","Limited progress despite available troubleshooting paths","Partial progress made but opportunities missed","Significant progress made with clear next steps","Issue resolved or strongest available outcome achieved"))
B28: Score reflects the cumulative effect of this touch within the 8-month journey: the Nov 24, 2025 hardware/RMA determination remains undelivered, and the case culminates here in executive-level escalation with no path forward offered. | C28: Stalled - declined troubleshooting + an EOL message, with no documented path forward.
B30: 2. TECHNICAL ACCURACY | F30: Weight: 20%
B31: Objective: Evaluate the quality of troubleshooting and technical guidance.
B32: Behavioral Indicator | C32: Assessment | D32: Evidence / Observation (quote or timestamp where possible)
B33: Symptoms were identified correctly | C33: Missed | D33: Limited diagnosis; relied on an EOL framing rather than advancing the node issue.
B34: Relevant diagnostic questions were asked | C34: Partial
B35: Logical troubleshooting methodology was followed | C35: Missed
B36: Available tools were used appropriately | C36: Partial
B37: Information provided was technically accurate | C37: Missed
B38: Assumptions were validated; no unsupported conclusions | C38: Partial
B39: Root cause (or likely cause) was identified when possible | C39: Missed
B40: ⚠ Deduct for: incorrect technical information; skipped critical troubleshooting; misdiagnosis; unnecessary actions recommended; ISP or customer blamed without evidence; repeating basic steps the customer already completed.
B41: Suggested score (auto from indicators — advisory only; evaluator judgment prevails) | C41: =IF((COUNTIF(C33:C39,"Met")+COUNTIF(C33:C39,"Partial")+COUNTIF(C33:C39,"Missed"))=0,"",ROUND((COUNTIF(C33:C39,"Met")*5+COUNTIF(C33:C39,"Partial")*2.5)/(COUNTIF(C33:C39,"Met")+COUNTIF(C33:C39,"Partial")+COUNTIF(C33:C39,"Missed")),1))
B42: FINAL CATEGORY SCORE (0–5) | C42: 2 | D42: =IF(C42="","← enter score; anchor description appears here",CHOOSE(C42+1,"Agent actions delayed, prevented, or negatively impacted resolution","Little or no meaningful progress","Limited progress despite available troubleshooting paths","Partial progress made but opportunities missed","Significant progress made with clear next steps","Issue resolved or strongest available outcome achieved"))
B43: Individual diagnostic steps (signal/backhaul check, swap-test proposal) were sound, but the unvalidated reversal of a prior CAT-level conclusion undermines technical credibility. | C43: Thin diagnosis; EOL framing did not move the node issue forward.
...

Sheet Scoring Guide
B1: SCORING GUIDE & CATEGORY CRITERIA
B3: How to use this form
B4: 1. Fill in Case Information, the Case Summary, and (for multi-touch cases) the Inherited Context field.
B5: 2. For each category, rate every behavioral indicator: Met / Partial / Missed / N.A. (N.A. excludes it from the suggested score).
B6: 3. Record evidence — quotes, timestamps, or note excerpts — beside each indicator.
B7: 4. Review the auto-suggested score, then assign the FINAL 0-5 score using evaluator judgment and the anchors below.
B8: 5. Classify the Resolution Outcome and the primary positive outcome achieved.
B9: 6. Complete the Disconnect Follow-Up check and the Critical Failure checklist.
B10: 7. Write coaching feedback: at least one actionable coaching opportunity is required; add an operational improvement recommendation where applicable.
B11: 8. For multi-touch cases, also read the Multi-Touch Guide sheet and log every touch in the Case Tracker under the same Case ID.
B13: Score Anchors (0–5 scale)
B14: Score | C14: Description
B15: 5 | C15: Issue resolved or strongest available outcome achieved
B16: 4 | C16: Significant progress made with clear next steps
B17: 3 | C17: Partial progress made but opportunities missed
B18: 2 | C18: Limited progress despite available troubleshooting paths
B19: 1 | C19: Little or no meaningful progress
B20: 0 | C20: Agent actions delayed, prevented, or negatively impacted resolution
B22: Indicator ratings
B23: Met | C23: Behavior fully demonstrated (counts as 5 toward the suggested score)
B24: Partial | C24: Behavior attempted but incomplete or inconsistent (counts as 2.5)
B25: Missed | C25: Behavior expected but not demonstrated (counts as 0)
B26: N.A. | C26: Not applicable to this interaction (excluded from the suggested score)
B28: Category Objectives & Watch-Fors
B29: Resolution / Progress Toward Resolution (30%) | C29: Determine whether the interaction moved the customer meaningfully closer to resolution. Does NOT count: customer simply ends call; generic KB sent without troubleshooting; warranty used as reason to stop helping; escalation as shortcut; unsupported ISP blame; 'monitor & call back' with no plan; ownership transferred without expectations or documentation.
B30: Technical Accuracy (20%) | C30: Evaluate the quality of troubleshooting and technical guidance. Deduct for: incorrect technical information; skipped critical troubleshooting; misdiagnosis; unnecessary actions recommended; ISP or customer blamed without evidence; repeating basic steps the customer already completed.
B31: Communication & Call Control (15%) | C31: Evaluate how effectively the agent managed the interaction. High performance: customer always knows what is happening and the agent drives the call confidently. One instruction at a time for customers who need it.
B32: Customer Ownership (15%) | C32: Measure the degree to which the agent accepted responsibility for moving the customer forward. Automatic deductions: no documented follow-up after disconnect; unclear next steps; passing responsibility without context; failure to complete promised actions; missed or late callbacks without proactive renegotiation.
B33: Escalation Judgment (10%) | C33: Determine whether escalation decisions were appropriate — including UPWARD escalations the customer requested (management, complaint, legal). Mark all N.A. if no escalation was involved and none was warranted. Low score: premature, avoidable, poorly documented, used as a substitute for troubleshooting — or a warranted escalation (incl. a customer's management request) that was NOT made.
B34: Customer Experience (5%) | C34: Measure the overall customer experience delivered during the interaction. Negative indicators: dismissive responses; robotic interactions; frustration escalation caused by agent behavior; marathon sessions pushed onto vulnerable customers without offering to pause and resume.
B35: Documentation & Notes (5%) | C35: Ensure future agents can quickly understand the case. Purpose is continuity, not compliance. Documentation supports outcomes but should not outweigh troubleshooting quality, communication, or ownership. Notes must carry the FULL history — including pre-ticket contacts — so no agent treats a long-running case as new.
B37: Overall Result Bands
B38: ≥ 85% | C38: Meets / Exceeds — strong support behavior
B39: 70–84% | C39: Developing — coaching opportunities present
B40: < 70% | C40: Needs improvement — prioritized coaching required
B42: A critical failure overrides the band: any flagged condition requires automatic review regardless of the weighted total. Every review must produce at least one actionable coaching opportunity and, where applicable, one operational improvement recommendation.

Sheet Multi-Touch Guide
B1: MULTI-TOUCH CASE SCORING — HOW IT WORKS
B3: THE MECHANICS
B4: 1. One scoring form per touch, not per case | C4: Each agent who handles the case gets their own complete evaluation (indicators, 0-5 scores, weighted total). Set Touch # on the form and mark 'Prior touches reviewed?' = Yes. The rubric requires assessing the entire customer journey, so read the earlier touches before scoring any of them. Use the 'Inherited context' field to record what the agent received.
B5: 2. Score each agent on THEIR contribution, in the context they inherited | C5: Resolution/Progress measures whether THAT touch moved the customer closer — an agent who inherits a mess and makes real progress can score 4-5 even on an old, ugly case. Agents are NOT penalized for problems they inherited, but they ARE penalized for problems they pass downstream: thin handoff notes, undocumented promises, premature RESOLVED statuses, missed callbacks.
B6: 3. Handoff quality is scored on the SENDING agent | C6: Customer Ownership ('ownership transfer without context' = automatic deduction) and Documentation ('could another agent quickly understand the case?') belong to the agent who wrote the notes. If a later agent re-runs all diagnostics because earlier notes were unusable, that hits the EARLIER touch. But if good notes existed and the later agent ignored them and made the customer repeat everything, that hits the LATER agent's Communication (repetitive questioning) and Customer Experience (increased effort).
B7: 4. Critical failures attach to a specific touch | C7: A premature RESOLVED, a missed callback window, a compliance violation, or an unescalated complaint fails THAT touch's review regardless of how the journey ends — and regardless of that touch's weighted score.
B8: 5. The journey rolls up in the Case Tracker | C8: Log every touch under the same Case ID with an incrementing Touch #. Per-touch weighted scores sit side by side so you can pinpoint exactly where the support chain broke or recovered. The journey's final outcome classification comes from the last touch; journey-level findings (process, KB, tooling, product) go into Organizational Insights — not into any single agent's score.
B9: 6. Watch for journey-level failure patterns | C9: Repeated premature closures, shifting callback promises, each agent re-starting from zero, escalation ping-pong, and unacknowledged cumulative customer effort are SYSTEMIC findings. Score the touch that caused each one, then raise the pattern as an organizational insight with a named process owner.
B11: WORKED JOURNEY — TE00124020 / TE00127492 (Richard & Diana Stell, Linksys WHW03 → MX4200, Apr 1 – May 30, 2026)
B12: Sources: Call Analysis Report 2026-05-25 (13 recordings) and Concentrix Case Investigation 2026-05-27. An 80-year-old couple in a 7,000 sq ft home; 7-week journey across 2 tickets, 10+ agents, 15+ hours; ended with CSAT 1/5, an SLA breach (>30 days), a legal threat, and the customer scrapping Linksys for Eero. Per-touch scores are in the Case Tracker; the full scored form for the final touch (Eric Marbella, May 18-19) is on the Example (Filled) sheet.
B13: WHERE THE CHAIN BROKE | C13: Scored against the touch that caused it
B14: Pre-ticket history lost (CRITICAL) | C14: Recordings 1-6 (April 1-23: WHW03 failure, $30 paid session, L2 escalation, compatibility advice that drove the MX4200 purchase) never made it into ticket TE00127492. Every later agent treated a months-long pattern as a new case. → Documentation failure on the early touches; organizational insight on ticket-linking process.
B15: PCI DSS violation (CRITICAL) | C15: Recording 3 (Apr 1, paid support): full card number, CVV, and expiry spoken aloud and captured in plaintext transcript; the $30 charge itself never documented in any ticket. → Critical failure on that touch + immediate compliance escalation.
B16: Receipt-gate before troubleshooting | C16: May 1 (Riojene Ladera): customer with active 5-min drop cycles was refused troubleshooting until a warranty receipt was emailed; note reads 'No trouble shooting made.' → Resolution & Ownership failure: warranty validation must not replace support on an active issue.
B17: Premature RESOLVED ×5 | C17: Ticket marked RESOLVED on Apr 28, May 1, May 4, May 18, May 19 while the streaming-stability complaint was never confirmed fixed. Final closure had no private-note reason. → Documentation/Ownership failures on each closing touch; masks true case age and breaks SLA monitoring.
B18: Callback management collapse | C18: Apr 1: promised 2-3h L2 callback vs the 24-48h process. May 18: customer waited 3+ hours through 3 L1 calls. May 19: agreed 4-5 PM window missed by 42-66 min, with conflicting explanations in notes ('in a meeting' vs 'engaged with another task'). → Ownership failures on the promising/missing touches; systemic trend finding.
B19: Complaint & legal threat not escalated (CRITICAL) | C19: May 19, 3:33 PM: customer email requests management contact 'before I talk to a lawyer.' Response (after TC consult) apologized but never escalated to management; no DSAT/management record until PMO intervened May 27. → Escalation Judgment failure on the final touch.
B20: Accessibility never adapted | C20: Customer stated hearing aids and age on nearly every call; investigation cites the same 'simplify, slow down, one step at a time' opportunity for 4+ different agents. → Communication finding per touch + training-level organizational insight.
B22: WHERE THE CHAIN RECOVERED (recognize these touches)
B23: Venn-Emir Calvin (Apr 23) | C23: Caught the mis-captured email address in under 2 minutes, corrected it, re-sent the guide — clean continuity fix; investigation found no opportunities.
B24: Paolo Ebora (May 4) | C24: 98-minute deep dive: HomeKit isolation, interference analysis, firmware validation, captured sysinfo/network logs via remote access, identified 2 bad-RSSI nodes (-90/-93 dBm), provided L2 hotline. Best diagnostics of the journey.
B25: Eric Marbella (May 18, technical leg) | C25: 3h26m session after the modem swap: correctly isolated the fault away from the ISP to the MX4200 parent node, restored internet, set up 4 child nodes with documented RSSI. The technical work was strong — the ownership collapse came the next day.
B27: JOURNEY-LEVEL ORGANIZATIONAL INSIGHTS (do not assign to any single agent's score)
B28: • Callback management is systemic, not individual: promised windows shifted repeatedly across L1 and L2; the post-case survey says technicians 'never call back as promised.' Recommend enforced callback calendaring and a contingency script when a window is at risk.
B29: • Case Management & Closure Process needs reinforcement (per investigation): RESOLVED requires customer-confirmed resolution or a documented closure reason; CALLBACK/PENDING states must be used while work is open.
B30: • Ticket linking: pre-purchase and pre-ticket history must be attached or cross-referenced when a new ticket is opened for the same customer/issue (TE00124020 → TE00127492 gap).
B31: • Compliance: PCI-safe payment flow required for paid support (no card data spoken on a recorded line); audit recordings/transcripts retention for Rec 3.
B32: • Product/advice loop: the MX4200 mixed-mesh recommendation for a 7,000 sq ft home with legacy WHW03 nodes drove 6 purchases without a coverage/topology consult — feed back to sales-advice scripts and KB.
B33: • Vulnerable-customer handling: a standard for elderly / hard-of-hearing customers (pace, one-step instructions, session-length checkpoints, offer to pause and resume) would have changed this journey's trajectory.
B35: THE TEAM / JOURNEY SCORE — SCORING THE CHAIN, NOT JUST THE LINKS
B36: Per the incentive philosophy (team improvement first, shared accountability), every multi-touch case also receives one Team Score covering all agents who touched it. It lives at the bottom of the Case Tracker. It drives team-level coaching, process fixes, and recognition — it is never used for individual discipline; individual feedback comes only from each agent's own touch form.
B37: Formula | C37: Team Score = 50% × Average Touch Weighted Score + 30% × (Journey Outcome ÷ 5) + 20% × (Continuity & Handoffs ÷ 5). Execution gets half the weight; the other half belongs to what the customer actually experienced — the end result and how well the chain held together. Same result bands as individual scores (≥85% / 70-84% / <70%). Any journey containing a critical failure carries the automatic-review flag regardless of its Team Score.
B38: Journey Outcome anchors (0-5) | C38: 5 = issue resolved AND confirmed with the customer, positive close · 4 = resolved with minor friction · 3 = partial resolution or accepted workaround with a clear path · 2 = unresolved but customer holds a valid, owned next step · 1 = unresolved and the customer disengaged · 0 = customer harmed, churned, or left with legal/compliance exposure.
B39: Continuity & Handoffs anchors (0-5) | C39: 5 = seamless handoffs; no agent restarted from zero; statuses always truthful · 4 = minor gaps, quickly recovered · 3 = some repeated work, but the thread held · 2 = significant rework caused by thin notes or wrong statuses · 1 = chain repeatedly broke (lost history, premature closures, shifting promises) · 0 = continuity collapse itself drove the complaint.
B40: Worked example (Stell journey) | C40: Average of the 13 touch scores ≈ 57% — individually, most touches were mediocre-to-fair and two were strong. But Outcome = 0 (churned, CSAT 1/5, legal threat) and Continuity = 1 (history lost, 5 premature closures). Team Score = 50%×57% + 30%×0 + 20%×(1/5) ≈ 33% — Needs Improvement. That 24-point gap between average execution and the Team Score IS the finding: no single agent failed badly enough to explain losing the customer; the chain did. The fixes are therefore process-level (callback management, closure discipline, ticket linking), which is exactly what the investigation concluded.
B41: Crediting the team | C41: Quality is created collectively (L1, escalation teams, trainers, QA, team leads, operations). When a Team Score is strong, recognize the whole chain — including agents whose touch was a 2-minute continuity save (e.g., Venn-Emir's email fix). When it is weak despite strong individual touches, the coaching target is the handoff process and its owners, not the agents.
B43: CONTRIBUTION TYPE & HANDOFF QUALITY — PER-TOUCH IMPACT TAGS
B44: Two extra columns on the Case Tracker (Contribution Type, Handoff Quality) tag what each touch actually did for the case, separately from its category scores. They make the Team Score's Continuity component an informed judgment instead of a guess, and they stop the first agent on a hard case from being penalised for complexity while the last agent gets all the credit.
B45: Contribution Type (per touch) | C45: Resolver = delivered the final fix, correct escalation, or proper closure for that thread · Progress Builder = advanced diagnosis or troubleshooting that moved the case forward, even if not fully fixed · Maintainer = kept momentum, clarified, documented, escalated appropriately without new ground gained · Regression Contributor = reset progress, misdiagnosed, premature closure, or otherwise caused regression. Use 'N/A' only when a touch is purely administrative with no case impact.
B46: Handoff Quality (0-5, per touch) | C46: Rates the OUTGOING handoff this touch left for whoever (or whatever) came next, across four dimensions: context completeness (did notes explain what was done?), continuity preservation (did it avoid forcing a restart?), expectation alignment (was the customer told something accurate about what happens next?), technical clarity (are logs/findings usable by the next agent?). 5 = clean handoff, nothing to redo · 3-4 = usable with minor gaps · 1-2 = next agent effectively restarts or inherits a broken promise · 0 = handoff itself caused the next failure. Leave blank or mark N/A for a case's final touch.
...

Sheet Team Scoring
B1: TEAM SCORING — METHODOLOGY & TEAM OPPORTUNITY ANALYSIS
