Workbook

Sheet Quick Start
B1: QA SCORING WORKBOOK — QUICK START GUIDE
B2: Resolution-focused coaching QA: one form per interaction, evidence-based indicator ratings, weighted 0-5 scoring, journey-level tracking and TEAM scoring for multi-touch cases. Yellow cells are YOUR inputs — everything else calculates or is reference.
B4: 1 · THE WORKING SHEETS
B5: Scoring Form | C5: The blank form you fill for EVERY interaction you review. Make a copy of this sheet per review (right-click tab → Move or Copy → Create a copy) so the master stays blank.
B6: Scoring Guide | C6: Reference: how-to steps, the 0-5 score anchors, what Met/Partial/Missed/N.A. mean, category objectives and watch-fors, and the result bands. Read once before your first review; return whenever unsure.
B7: Multi-Touch Guide | C7: Rules for cases handled by multiple agents: how to score each touch fairly, who owns handoff failures, plus a full real-case walkthrough (the Stell journey) showing where a support chain broke and recovered.
B8: Team Scoring | C8: The team layer: the Team Score formula component by component, how to read the gap between execution and outcome, a LIVE category heatmap showing where the team is weak, the 8 team opportunities identified from the Stell journey with owners, and a 6-step recipe to run a team review on your own journeys.
B9: Example (Filled) | C9: A complete, real worked review — the final touch of the Stell case (Eric Marbella). Shows exactly how detailed your evidence should be, how indicator ratings map to a final score, and how critical failures are written up. Copy its style.
B10: Case Tracker | C10: The log. One row per reviewed touch (date, agent, 7 scores, auto weighted % and band). Reuse a Case ID across rows for multi-touch journeys. Team Average at row 51; Team/Journey Scores section at row 53.
B12: 2 · HOW TO SCORE ONE INTERACTION (Scoring Form, ~15 min)
B13: Step 1 — Case Information | C13: Fill the yellow cells: agent, ticket, dates, product. Dropdowns: Warranty, Channel, Case Type, SLA. Write a 2-3 sentence Case Summary. Multi-touch? Set Touch # and fill 'Inherited context' (what this agent received from prior touches).
B14: Step 2 — Rate the indicators | C14: Each of the 7 categories lists 5-8 behaviors. Rate each: Met / Partial / Missed / N.A. (dropdown). N.A. = genuinely not applicable (e.g., no escalation involved) — it is excluded from the math, never a shortcut.
B15: Step 3 — Capture evidence | C15: Next to every rating, write WHY: a quote, timestamp, or note excerpt. 'Customer said X at 28:10' beats 'communication was good'. The Example sheet shows the standard.
B16: Step 4 — Set the final score | C16: A suggested score appears automatically (Met=5, Partial=2.5, Missed=0, averaged). You may override it — your judgment prevails — but the anchor text that appears beside your score tells you what a 4 vs a 3 means. Apply the rubric's automatic deductions (e.g., missed callback) even if indicators average higher.
B17: Step 5 — Outcome & disconnect | C17: Classify the Resolution Outcome (dropdown) and the primary positive outcome achieved. If the call disconnected, record the follow-up taken — 'Yes disconnect + no follow-up' auto-flags a missed ownership opportunity in red.
B18: Step 6 — Critical failures | C18: Answer Yes/No on all 11 conditions. ANY Yes turns the banner red: automatic review, regardless of the score. These include premature RESOLVED closure, PCI/compliance breaches, and unescalated management/legal requests.
B19: Step 7 — Coaching sections | C19: 3 strengths, 3 improvements, a specific coaching recommendation (at least one is mandatory per review), organizational insights, journey notes (multi-touch), and the final assessment.
B20: Step 8 — Log it | C20: Add one row in the Case Tracker: date, Case ID, agent, touch #, and your 7 final scores. Weighted % and band compute themselves.
B22: 3 · WHAT YOU TYPE vs WHAT CALCULATES ITSELF
B23: You type (yellow cells) | C23: Case info · indicator ratings (dropdowns) · evidence text · the 7 final 0-5 scores · outcome dropdowns · critical-failure Yes/No · coaching text · tracker rows · Team Score's Outcome and Continuity (0-5).
B24: Calculates automatically | C24: Suggested score per category · anchor description beside each score · Score Summary table · Weighted Total = Σ(score÷5 × weight) with weights 30/20/15/15/10/5/5 · result band · disconnect flag · critical-failure banner · tracker Weighted % and band · Team Average · Team Score = 50% avg touches + 30% Outcome/5 + 20% Continuity/5 · the Team Scoring sheet's category heatmap.
B25: Color language | C25: GREEN = strong (scores 4-5, total ≥85%) · YELLOW = developing (score 3, total 70-84%) · RED = needs focus (scores 0-2, total <70%, any critical failure, missed disconnect follow-up). Indicator cells: Met=green, Partial=yellow, Missed=red. Heatmap: category avg <2.75 red = team coaching theme.
B27: 4 · MULTI-TOUCH CASES IN SIX LINES (full rules: Multi-Touch Guide + Team Scoring)
B28: One form per touch | C28: Every agent gets their own form. Read all prior touches first; record what the agent inherited.
B29: Score the contribution | C29: Did THIS touch move the customer forward, given what it inherited? Agents aren't punished for inherited messes — only for what they pass downstream (thin notes, false RESOLVED, missed callbacks).
B30: Handoffs belong to the sender | C30: Bad notes that force rework = deduction for the earlier agent. Ignoring good notes and re-asking everything = deduction for the later agent.
B31: Log every touch, same Case ID | C31: Tracker rows side by side show exactly where the chain broke or recovered.
B32: Score the chain | C32: Bottom of the Case Tracker: type the Case ID in a Team/Journey row, judge Outcome (0-5) and Continuity (0-5) — the Team Score computes. Drives process fixes and team recognition, never individual discipline.
B33: Find the TEAM opportunities | C33: Team Scoring sheet: build the category heatmap over the journey's rows, take the bottom two categories as team coaching themes, scan for patterns repeating across 3+ agents, and write the action plan with named owners (section 5 there is the model).
B35: 5 · GOLDEN RULES
B36: • A closed case is NOT automatically a resolved case — and RESOLVED on a known-unresolved issue is a critical failure.
B37: • Any critical failure = automatic review, no matter how good the weighted score looks.
B38: • Resolution isn't only 'fixed': a proper RMA, a valid escalation, or an accurately explained limitation all count as positive outcomes.
B39: • Every review must produce at least one actionable coaching opportunity — and an operational improvement recommendation where applicable.
B40: • Evidence over opinion: every rating should be defensible with a quote, timestamp, or note excerpt.
B41: • Documentation supports outcomes but never outweighs troubleshooting, communication, or ownership — continuity, not compliance.
B42: • Reward judgment: an unresolved case with correct next steps and full ownership can still score well.
B43: • Team Scores coach the chain; individual forms coach the agent. Never mix the two purposes.
B45: Questions while reviewing? Order of reference: this sheet → Scoring Guide (anchors & criteria) → Multi-Touch Guide (journey rules) → Team Scoring (team layer & heatmap) → Example (Filled) (what good looks like).

Sheet Scoring Form
B1: SUPPORT QUALITY ASSURANCE — SCORING FORM
B2: Resolution-Focused Coaching & Performance Framework | Rate each behavior: Met / Partial / Missed / N.A. — then assign the 0-5 category score (suggested score is advisory).
B4: 1 · CASE INFORMATION
B5: Agent Name | D5: Case / Ticket ID
B6: Evaluator (QA) | D6: Interaction Date
B7: Product | D7: Channel
B8: Warranty Status | D8: Review Date
B9: Case Type | D9: Interaction Duration
B10: Touch # (multi-touch case) | D10: Prior touches reviewed?
B11: CSAT / Survey result | D11: FCR / total contacts
B12: Total case time | D12: SLA status
B13: Case Summary (customer issue & goal)
B14: Inherited context (what this agent received from prior touches)
B15: CLASSIFICATION & ROOT-CAUSE (added from the 360 Form model)
B16: Audit / Review Type | D16: Contact iteration (repeat contact)
B17: Resolution status — detailed | D17: Primary root-cause domain
B18: Process driver (if any)
B19: Product driver (if any)
B20: System / tooling driver (if any)
B21: Root-cause / contact-driver notes (feeds Team Scoring → Team Opportunities Identified)
B24: 2 · SCORE SUMMARY
B25: Category | C25: Weight | D25: Score (0-5) | E25: Weighted | F25: Band
B26: Resolution / Progress Toward Resolution | C26: 0.3 | D26: =IF(C46="",C45,C46) | E26: =IF(D26="","",(D26/5)*C26) | F26: =IF(D26="","",IF(D26>=4,"Strong",IF(D26=3,"Developing","Needs Focus")))
B27: Technical Accuracy | C27: 0.2 | D27: =IF(C61="",C60,C61) | E27: =IF(D27="","",(D27/5)*C27) | F27: =IF(D27="","",IF(D27>=4,"Strong",IF(D27=3,"Developing","Needs Focus")))
B28: Communication & Call Control | C28: 0.15 | D28: =IF(C77="",C76,C77) | E28: =IF(D28="","",(D28/5)*C28) | F28: =IF(D28="","",IF(D28>=4,"Strong",IF(D28=3,"Developing","Needs Focus")))
B29: Customer Ownership | C29: 0.15 | D29: =IF(C93="",C92,C93) | E29: =IF(D29="","",(D29/5)*C29) | F29: =IF(D29="","",IF(D29>=4,"Strong",IF(D29=3,"Developing","Needs Focus")))
B30: Escalation Judgment | C30: 0.1 | D30: =IF(C106="",C105,C106) | E30: =IF(D30="","",(D30/5)*C30) | F30: =IF(D30="","",IF(D30>=4,"Strong",IF(D30=3,"Developing","Needs Focus")))
B31: Customer Experience | C31: 0.05 | D31: =IF(C127="",C126,C127) | E31: =IF(D31="","",(D31/5)*C31) | F31: =IF(D31="","",IF(D31>=4,"Strong",IF(D31=3,"Developing","Needs Focus")))
B32: Documentation & Notes | C32: 0.05 | D32: =IF(C142="",C141,C142) | E32: =IF(D32="","",(D32/5)*C32) | F32: =IF(D32="","",IF(D32>=4,"Strong",IF(D32=3,"Developing","Needs Focus")))
B33: WEIGHTED TOTAL SCORE | C33: =SUM(C26:C32) | E33: =IF(OR(C173="No",C174="No",C175="No",COUNTIF(C177:C187,"Yes")>0,COUNTIF(C157:C167,"Yes")>0),0,SUM(E26:E32)) | F33: =IF(E33="","",IF(OR(C173="No",C174="No",C175="No",COUNTIF(C177:C187,"Yes")>0,COUNTIF(C157:C167,"Yes")>0),"AUTO-ZERO (0%)",IF(E33>=0.85,"MEETS / EXCEEDS",IF(E33>=0.7,"DEVELOPING","NEEDS IMPROVEMENT"))))
B35: 3 · CATEGORY ASSESSMENTS
B36: 1. RESOLUTION / PROGRESS TOWARD RESOLUTION | F36: Weight: 30%
B37: Objective: Determine whether the interaction moved the customer meaningfully closer to resolution.
B38: Behavioral Indicator | C38: Assessment | D38: Evidence / Observation (quote or timestamp where possible)
B39: Resolved the issue or achieved the best possible outcome (RMA, valid escalation, limitation explained, education)
B40: Completed reasonable troubleshooting before reaching a conclusion
B41: Used the appropriate resolution path for the situation and warranty status, moving the customer closer to a solution with clear next steps.
B44: ⚠ Does NOT count: customer simply ends call; generic KB sent without troubleshooting; warranty used as reason to stop helping; escalation as shortcut; unsupported ISP blame; 'monitor & call back' with no plan; ownership transferred without expectations or documentation.
B45: Auto score (0–5) from indicator ratings — applies unless overridden | C45: =IF((COUNTIF(C39:C43,"Met")+COUNTIF(C39:C43,"Partial")+COUNTIF(C39:C43,"Missed"))=0,"",ROUND((COUNTIF(C39:C43,"Met")*5+COUNTIF(C39:C43,"Partial")*2.5)/(COUNTIF(C39:C43,"Met")+COUNTIF(C39:C43,"Partial")+COUNTIF(C39:C43,"Missed")),0))
B46: FINAL SCORE — leave blank to use the auto score; type 0–5 to override | D46: =IF(IF(C46="",C45,C46)="","← rate the indicators above (auto-scores), or type an override",CHOOSE(IF(C46="",C45,C46)+1,"Agent actions delayed, prevented, or negatively impacted resolution","Little or no meaningful progress","Limited progress despite available troubleshooting paths","Partial progress made but opportunities missed","Significant progress made with clear next steps","Issue resolved or strongest available outcome achieved"))
...

Sheet Scoring Guide
B1: SCORING GUIDE & CATEGORY CRITERIA
B3: How to use this form
B4: 1. Fill in Case Information, the Case Summary, and (for multi-touch cases) the Inherited Context field.
B5: 2. For each category, rate every behavioral indicator: Met / Partial / Missed / N.A. (N.A. excludes it from the suggested score).
B6: 3. Record evidence — quotes, timestamps, or note excerpts — beside each indicator.
B7: 4. Review the auto-suggested score, then assign the FINAL 0-5 score using evaluator judgment and the anchors below.
B8: 5. Classify the Resolution Outcome and the primary positive outcome achieved.
B9: 6. Complete the Disconnect Follow-Up check and the Critical Failure checklist.
B10: 7. Write coaching feedback: at least one actionable coaching opportunity is required; add an operational improvement recommendation where applicable.
B11: 8. For multi-touch cases, also read the Multi-Touch Guide sheet and log every touch in the Case Tracker under the same Case ID.
B13: Score Anchors (0–5 scale)
B14: Score | C14: Description
B15: 5 | C15: Issue resolved or strongest available outcome achieved
B16: 4 | C16: Significant progress made with clear next steps
B17: 3 | C17: Partial progress made but opportunities missed
B18: 2 | C18: Limited progress despite available troubleshooting paths
B19: 1 | C19: Little or no meaningful progress
B20: 0 | C20: Agent actions delayed, prevented, or negatively impacted resolution
B22: Indicator ratings
B23: Met | C23: Behavior fully demonstrated (counts as 5 toward the suggested score)
B24: Partial | C24: Behavior attempted but incomplete or inconsistent (counts as 2.5)
B25: Missed | C25: Behavior expected but not demonstrated (counts as 0)
B26: N.A. | C26: Not applicable to this interaction (excluded from the suggested score)
B28: Category Objectives & Watch-Fors
B29: Resolution / Progress Toward Resolution (30%) | C29: Determine whether the interaction moved the customer meaningfully closer to resolution. Does NOT count: customer simply ends call; generic KB sent without troubleshooting; warranty used as reason to stop helping; escalation as shortcut; unsupported ISP blame; 'monitor & call back' with no plan; ownership transferred without expectations or documentation.
B30: Technical Accuracy (20%) | C30: Evaluate the quality of troubleshooting and technical guidance. Deduct for: incorrect technical information; skipped critical troubleshooting; misdiagnosis; unnecessary actions recommended; ISP or customer blamed without evidence; repeating basic steps the customer already completed.
B31: Communication & Call Control (15%) | C31: Evaluate how effectively the agent managed the interaction. High performance: customer always knows what is happening and the agent drives the call confidently. One instruction at a time for customers who need it.
B32: Customer Ownership (15%) | C32: Measure the degree to which the agent accepted responsibility for moving the customer forward. Automatic deductions: no documented follow-up after disconnect; unclear next steps; passing responsibility without context; failure to complete promised actions; missed or late callbacks without proactive renegotiation.
B33: Escalation Judgment (10%) | C33: Determine whether escalation decisions were appropriate — including UPWARD escalations the customer requested (management, complaint, legal). Mark all N.A. if no escalation was involved and none was warranted. Low score: premature, avoidable, poorly documented, used as a substitute for troubleshooting — or a warranted escalation (incl. a customer's management request) that was NOT made.
B34: Customer Experience (5%) | C34: Measure the overall customer experience delivered during the interaction. Negative indicators: dismissive responses; robotic interactions; frustration escalation caused by agent behavior; marathon sessions pushed onto vulnerable customers without offering to pause and resume.
B35: Documentation & Notes (5%) | C35: Ensure future agents can quickly understand the case. Purpose is continuity, not compliance. Documentation supports outcomes but should not outweigh troubleshooting quality, communication, or ownership. Notes must carry the FULL history — including pre-ticket contacts — so no agent treats a long-running case as new.
B37: Overall Result Bands
B38: ≥ 85% | C38: Meets / Exceeds — strong support behavior
B39: 70–84% | C39: Developing — coaching opportunities present
B40: < 70% | C40: Needs improvement — prioritized coaching required
B42: A critical failure overrides the band: any flagged condition requires automatic review regardless of the weighted total. Every review must produce at least one actionable coaching opportunity and, where applicable, one operational improvement recommendation.

Sheet Multi-Touch Guide
B1: MULTI-TOUCH CASE SCORING — HOW IT WORKS
B3: THE MECHANICS
B4: 1. One scoring form per touch, not per case | C4: Each agent who handles the case gets their own complete evaluation (indicators, 0-5 scores, weighted total). Set Touch # on the form and mark 'Prior touches reviewed?' = Yes. The rubric requires assessing the entire customer journey, so read the earlier touches before scoring any of them. Use the 'Inherited context' field to record what the agent received.
B5: 2. Score each agent on THEIR contribution, in the context they inherited | C5: Resolution/Progress measures whether THAT touch moved the customer closer — an agent who inherits a mess and makes real progress can score 4-5 even on an old, ugly case. Agents are NOT penalized for problems they inherited, but they ARE penalized for problems they pass downstream: thin handoff notes, undocumented promises, premature RESOLVED statuses, missed callbacks.
B6: 3. Handoff quality is scored on the SENDING agent | C6: Customer Ownership ('ownership transfer without context' = automatic deduction) and Documentation ('could another agent quickly understand the case?') belong to the agent who wrote the notes. If a later agent re-runs all diagnostics because earlier notes were unusable, that hits the EARLIER touch. But if good notes existed and the later agent ignored them and made the customer repeat everything, that hits the LATER agent's Communication (repetitive questioning) and Customer Experience (increased effort).
B7: 4. Critical failures attach to a specific touch | C7: A premature RESOLVED, a missed callback window, a compliance violation, or an unescalated complaint fails THAT touch's review regardless of how the journey ends — and regardless of that touch's weighted score.
B8: 5. The journey rolls up in the Case Tracker | C8: Log every touch under the same Case ID with an incrementing Touch #. Per-touch weighted scores sit side by side so you can pinpoint exactly where the support chain broke or recovered. The journey's final outcome classification comes from the last touch; journey-level findings (process, KB, tooling, product) go into Organizational Insights — not into any single agent's score.
B9: 6. Watch for journey-level failure patterns | C9: Repeated premature closures, shifting callback promises, each agent re-starting from zero, escalation ping-pong, and unacknowledged cumulative customer effort are SYSTEMIC findings. Score the touch that caused each one, then raise the pattern as an organizational insight with a named process owner.
B11: WORKED JOURNEY — TE00124020 / TE00127492 (Richard & Diana Stell, Linksys WHW03 → MX4200, Apr 1 – May 30, 2026)
B12: Sources: Call Analysis Report 2026-05-25 (13 recordings) and Concentrix Case Investigation 2026-05-27. An 80-year-old couple in a 7,000 sq ft home; 7-week journey across 2 tickets, 10+ agents, 15+ hours; ended with CSAT 1/5, an SLA breach (>30 days), a legal threat, and the customer scrapping Linksys for Eero. Per-touch scores are in the Case Tracker; the full scored form for the final touch (Eric Marbella, May 18-19) is on the Example (Filled) sheet.
B13: WHERE THE CHAIN BROKE | C13: Scored against the touch that caused it
B14: Pre-ticket history lost (CRITICAL) | C14: Recordings 1-6 (April 1-23: WHW03 failure, $30 paid session, L2 escalation, compatibility advice that drove the MX4200 purchase) never made it into ticket TE00127492. Every later agent treated a months-long pattern as a new case. → Documentation failure on the early touches; organizational insight on ticket-linking process.
B15: PCI DSS violation (CRITICAL) | C15: Recording 3 (Apr 1, paid support): full card number, CVV, and expiry spoken aloud and captured in plaintext transcript; the $30 charge itself never documented in any ticket. → Critical failure on that touch + immediate compliance escalation.
B16: Receipt-gate before troubleshooting | C16: May 1 (Riojene Ladera): customer with active 5-min drop cycles was refused troubleshooting until a warranty receipt was emailed; note reads 'No trouble shooting made.' → Resolution & Ownership failure: warranty validation must not replace support on an active issue.
B17: Premature RESOLVED ×5 | C17: Ticket marked RESOLVED on Apr 28, May 1, May 4, May 18, May 19 while the streaming-stability complaint was never confirmed fixed. Final closure had no private-note reason. → Documentation/Ownership failures on each closing touch; masks true case age and breaks SLA monitoring.
B18: Callback management collapse | C18: Apr 1: promised 2-3h L2 callback vs the 24-48h process. May 18: customer waited 3+ hours through 3 L1 calls. May 19: agreed 4-5 PM window missed by 42-66 min, with conflicting explanations in notes ('in a meeting' vs 'engaged with another task'). → Ownership failures on the promising/missing touches; systemic trend finding.
B19: Complaint & legal threat not escalated (CRITICAL) | C19: May 19, 3:33 PM: customer email requests management contact 'before I talk to a lawyer.' Response (after TC consult) apologized but never escalated to management; no DSAT/management record until PMO intervened May 27. → Escalation Judgment failure on the final touch.
B20: Accessibility never adapted | C20: Customer stated hearing aids and age on nearly every call; investigation cites the same 'simplify, slow down, one step at a time' opportunity for 4+ different agents. → Communication finding per touch + training-level organizational insight.
B22: WHERE THE CHAIN RECOVERED (recognize these touches)
B23: Venn-Emir Calvin (Apr 23) | C23: Caught the mis-captured email address in under 2 minutes, corrected it, re-sent the guide — clean continuity fix; investigation found no opportunities.
B24: Paolo Ebora (May 4) | C24: 98-minute deep dive: HomeKit isolation, interference analysis, firmware validation, captured sysinfo/network logs via remote access, identified 2 bad-RSSI nodes (-90/-93 dBm), provided L2 hotline. Best diagnostics of the journey.
B25: Eric Marbella (May 18, technical leg) | C25: 3h26m session after the modem swap: correctly isolated the fault away from the ISP to the MX4200 parent node, restored internet, set up 4 child nodes with documented RSSI. The technical work was strong — the ownership collapse came the next day.
B27: JOURNEY-LEVEL ORGANIZATIONAL INSIGHTS (do not assign to any single agent's score)
B28: • Callback management is systemic, not individual: promised windows shifted repeatedly across L1 and L2; the post-case survey says technicians 'never call back as promised.' Recommend enforced callback calendaring and a contingency script when a window is at risk.
B29: • Case Management & Closure Process needs reinforcement (per investigation): RESOLVED requires customer-confirmed resolution or a documented closure reason; CALLBACK/PENDING states must be used while work is open.
B30: • Ticket linking: pre-purchase and pre-ticket history must be attached or cross-referenced when a new ticket is opened for the same customer/issue (TE00124020 → TE00127492 gap).
B31: • Compliance: PCI-safe payment flow required for paid support (no card data spoken on a recorded line); audit recordings/transcripts retention for Rec 3.
B32: • Product/advice loop: the MX4200 mixed-mesh recommendation for a 7,000 sq ft home with legacy WHW03 nodes drove 6 purchases without a coverage/topology consult — feed back to sales-advice scripts and KB.
B33: • Vulnerable-customer handling: a standard for elderly / hard-of-hearing customers (pace, one-step instructions, session-length checkpoints, offer to pause and resume) would have changed this journey's trajectory.
B35: THE TEAM / JOURNEY SCORE — SCORING THE CHAIN, NOT JUST THE LINKS
B36: Per the incentive philosophy (team improvement first, shared accountability), every multi-touch case also receives one Team Score covering all agents who touched it. It lives at the bottom of the Case Tracker. It drives team-level coaching, process fixes, and recognition — it is never used for individual discipline; individual feedback comes only from each agent's own touch form.
B37: Formula | C37: Team Score = 50% × Average Touch Weighted Score + 30% × (Journey Outcome ÷ 5) + 20% × (Continuity & Handoffs ÷ 5). Execution gets half the weight; the other half belongs to what the customer actually experienced — the end result and how well the chain held together. Same result bands as individual scores (≥85% / 70-84% / <70%). Any journey containing a critical failure carries the automatic-review flag regardless of its Team Score.
B38: Journey Outcome anchors (0-5) | C38: 5 = issue resolved AND confirmed with the customer, positive close · 4 = resolved with minor friction · 3 = partial resolution or accepted workaround with a clear path · 2 = unresolved but customer holds a valid, owned next step · 1 = unresolved and the customer disengaged · 0 = customer harmed, churned, or left with legal/compliance exposure.
B39: Continuity & Handoffs anchors (0-5) | C39: 5 = seamless handoffs; no agent restarted from zero; statuses always truthful · 4 = minor gaps, quickly recovered · 3 = some repeated work, but the thread held · 2 = significant rework caused by thin notes or wrong statuses · 1 = chain repeatedly broke (lost history, premature closures, shifting promises) · 0 = continuity collapse itself drove the complaint.
B40: Worked example (Stell journey) | C40: Average of the 13 touch scores ≈ 57% — individually, most touches were mediocre-to-fair and two were strong. But Outcome = 0 (churned, CSAT 1/5, legal threat) and Continuity = 1 (history lost, 5 premature closures). Team Score = 50%×57% + 30%×0 + 20%×(1/5) ≈ 33% — Needs Improvement. That 24-point gap between average execution and the Team Score IS the finding: no single agent failed badly enough to explain losing the customer; the chain did. The fixes are therefore process-level (callback management, closure discipline, ticket linking), which is exactly what the investigation concluded.
B41: Crediting the team | C41: Quality is created collectively (L1, escalation teams, trainers, QA, team leads, operations). When a Team Score is strong, recognize the whole chain — including agents whose touch was a 2-minute continuity save (e.g., Venn-Emir's email fix). When it is weak despite strong individual touches, the coaching target is the handoff process and its owners, not the agents.
B43: CONTRIBUTION TYPE & HANDOFF QUALITY — PER-TOUCH IMPACT TAGS
B44: Two extra columns on the Case Tracker (Contribution Type, Handoff Quality) tag what each touch actually did for the case, separately from its category scores. They make the Team Score's Continuity component an informed judgment instead of a guess, and they stop the first agent on a hard case from being penalised for complexity while the last agent gets all the credit.
B45: Contribution Type (per touch) | C45: Resolver = delivered the final fix, correct escalation, or proper closure for that thread · Progress Builder = advanced diagnosis or troubleshooting that moved the case forward, even if not fully fixed · Maintainer = kept momentum, clarified, documented, escalated appropriately without new ground gained · Regression Contributor = reset progress, misdiagnosed, premature closure, or otherwise caused regression. Use 'N/A' only when a touch is purely administrative with no case impact.
B46: Handoff Quality (0-5, per touch) | C46: Rates the OUTGOING handoff this touch left for whoever (or whatever) came next, across four dimensions: context completeness (did notes explain what was done?), continuity preservation (did it avoid forcing a restart?), expectation alignment (was the customer told something accurate about what happens next?), technical clarity (are logs/findings usable by the next agent?). 5 = clean handoff, nothing to redo · 3-4 = usable with minor gaps · 1-2 = next agent effectively restarts or inherits a broken promise · 0 = handoff itself caused the next failure. Leave blank or mark N/A for a case's final touch.
...

Sheet Team Scoring
B1: TEAM SCORING — METHODOLOGY & TEAM OPPORTUNITY ANALYSIS
B2: Individual forms answer 'how did this agent do?'. Team Scoring answers 'how did the CHAIN perform for the customer?' and 'what should we coach, fix, or build as a TEAM?'. The scorecard below is live from the Case Tracker.
B4: ="◆ LIVE TEAM SCORECARD · "&IF('Case Tracker'!A56="","(enter a Case ID + journey scores in Case Tracker row 56)",'Case Tracker'!A56)&" ◆"
B5: TEAM SCORE | C5: RESULT BAND | D5: CONTAINS CRITICAL FAILURE?
B6: ='Case Tracker'!G56 | C6: =UPPER('Case Tracker'!H56) | D6: See section 6 of each agent's Scoring Form
B7: EXECUTION (50% weight) | C7: JOURNEY OUTCOME (30% weight) | D7: CONTINUITY & HANDOFFS (20% weight)
B8: =IF('Case Tracker'!D56="","—",TEXT('Case Tracker'!D56,"0.0%")&" avg of "&'Case Tracker'!C56&" touches") | C8: =IF('Case Tracker'!E56="","—",'Case Tracker'!E56&" / 5") | D8: =IF('Case Tracker'!F56="","—",'Case Tracker'!F56&" / 5")
B9: =IF('Case Tracker'!D56="","Team Score computes once the journey row (Case Tracker row 56) is filled."," = 50% × "&TEXT('Case Tracker'!D56,"0.0%")&" + 30% × ("&'Case Tracker'!E56&"÷5) + 20% × ("&'Case Tracker'!F56&"÷5)")
B10: ↑ Updates automatically from the Case Tracker (Team/Journey Scores, row 56). Edit Outcome / Continuity there and this scorecard moves with it. For your own journeys, copy this block and point it at the relevant journey row.
B12: 1 · WHY A TEAM SCORE EXISTS
B13: The rubric's incentive philosophy ranks team improvement FIRST, then individual excellence, then shared accountability. Quality is created collectively — L1, escalation teams, trainers, QA, team leads, operations. A multi-touch case is the truest test: the customer experiences ONE journey, not thirteen separate calls. The Team Score makes the chain itself a scored, coachable unit, so process failures stop hiding between individually 'acceptable' touches. Rule: the Team Score drives team coaching, process fixes, and chain-wide recognition. It is NEVER used for individual discipline — individual feedback comes only from each agent's own touch form.
B15: 2 · THE FORMULA, COMPONENT BY COMPONENT
B16: Component | C16: What it measures & why this weight | D16: Journey numbers — auto-computed once touches are logged
B17: EXECUTION — 50% Average of all touch weighted scores | C17: The team's average quality of work, touch by touch. Auto-computed in the tracker (AVERAGE of the Weighted column for the journey's rows). Gets half the weight because good execution is necessary — but deliberately NOT more than half, because a chain of individually fine touches can still lose a customer.
B18: JOURNEY OUTCOME — 30% Evaluator-judged 0-5 | C18: What the customer actually got at the end of the whole journey. Anchors: 5 = resolved AND confirmed, positive close · 4 = resolved, minor friction · 3 = partial/accepted workaround with clear path · 2 = unresolved but customer holds a valid, owned next step · 1 = unresolved, customer disengaged · 0 = customer harmed, churned, or left with legal/compliance exposure. Judged once per journey, against the FINAL state.
B19: CONTINUITY & HANDOFFS — 20% Evaluator-judged 0-5 | C19: How well the chain held together BETWEEN touches: did notes carry forward, were statuses truthful, did promises survive handoffs, did anyone restart from zero? Anchors: 5 = seamless · 4 = minor gaps, quickly recovered · 3 = some repeated work, thread held · 2 = significant rework from thin notes/wrong statuses · 1 = chain repeatedly broke · 0 = the continuity collapse itself drove the complaint.
B20: TEAM SCORE = 50% × Execution + 30% × (Outcome ÷ 5) + 20% × (Continuity ÷ 5). Enter the journey's Outcome & Continuity (0-5) in Case Tracker row 56; Execution auto-computes.
B22: 3 · READING THE RESULT — THE GAP IS THE DIAGNOSIS
B23: Team Score ≈ Execution average | C23: The chain neither helped nor hurt. Coach individuals on their own findings; no major process action.
B24: Team Score WELL ABOVE Execution average | C24: Strong outcome/continuity lifted ordinary touches — the process carried the team. Recognize the chain and the process owners; capture what worked as a standard.
B25: Team Score WELL BELOW Execution average | C25: Individually 'acceptable' agents, collectively a lost customer. The failure lives BETWEEN touches: handoffs, statuses, callbacks, ticket linking. Coaching individuals harder will NOT fix this — the action plan must target process, with named owners and dates.
B27: 4 · TEAM CATEGORY HEATMAP — WHERE THE TEAM IS WEAK (live formulas over the Case Tracker touch rows)
B28: Averaging each category ACROSS all touches turns the individual reviews into one team profile. Compare each to the 0-5 scale; <2.75 is a team coaching theme.
B29: Category (weight) | C29: Team avg (0-5) | D29: What the journey shows
B30: Resolution / Progress (30%) | C30: =IFERROR(ROUND(AVERAGE('Case Tracker'!E5:E49),2),"")
B31: Technical Accuracy (20%) | C31: =IFERROR(ROUND(AVERAGE('Case Tracker'!F5:F49),2),"")
B32: Communication & Call Control (15%) | C32: =IFERROR(ROUND(AVERAGE('Case Tracker'!G5:G49),2),"")
B33: Customer Ownership (15%) | C33: =IFERROR(ROUND(AVERAGE('Case Tracker'!H5:H49),2),"")
B34: Escalation Judgment (10%) | C34: =IFERROR(ROUND(AVERAGE('Case Tracker'!I5:I49),2),"")
B35: Customer Experience (5%) | C35: =IFERROR(ROUND(AVERAGE('Case Tracker'!J5:J49),2),"")
B36: Documentation & Notes (5%) | C36: =IFERROR(ROUND(AVERAGE('Case Tracker'!K5:K49),2),"")
B37: Reading: red (<2.75) = team coaching theme · yellow (2.75-3.49) = monitor & spot-coach · green (≥3.5) = team strength to protect.
B39: 5 · TEAM OPPORTUNITIES IDENTIFIED (the team action plan)
B40: Opportunity (category) | C40: Evidence across touches (why it's a TEAM issue, not one agent) | D40: Team action & suggested owner
B50: 6 · HOW TO RUN A TEAM REVIEW FOR YOUR OWN JOURNEYS (~30 min once touches are scored)
B51: Step 1 | C51: Score every touch individually first (Scoring Form per agent) and log all rows in the Case Tracker under the same Case ID.
B52: Step 2 | C52: In the Team/Journey Scores section (Case Tracker, row 53+), enter the Case ID — Touches and Avg Touch % auto-fill. Judge Outcome (0-5) and Continuity (0-5) with the anchors in section 2. The Team Score computes; the hero scorecard at the top of this sheet mirrors it.
B53: Step 3 | C53: Compare Team Score vs Execution average (section 3). A big negative gap = process problem; flag it as such in your report.
B54: Step 4 | C54: Build the category heatmap: average each category column across the journey's tracker rows (copy the section-4 formulas, adjusting the row range). Bottom two categories = your team coaching themes.
B55: Step 5 | C55: Scan for recurring patterns: same coaching note on 3+ agents (training gap) · same broken-promise type on 2+ touches (process gap) · any premature closure, lost history, or unescalated complaint (critical — name it).
...

Sheet Example (Filled)
B1: SUPPORT QA — SCORING FORM (WORKED EXAMPLE — FINAL TOUCH OF A MULTI-TOUCH CASE)
B2: Resolution-Focused Coaching & Performance Framework | Rate each behavior: Met / Partial / Missed / N.A. — then assign the 0-5 category score (suggested score is advisory).
B4: 1 · CASE INFORMATION
B5: Agent Name | C5: Eric Marbella (L2 / CAT) | D5: Case / Ticket ID | E5: TE00127492 (prior: TE00124020)
B6: Evaluator (QA) | C6: QA Specialist | D6: Interaction Date | E6: 2026-05-18 to 2026-05-19
B7: Product | C7: Linksys MX4200 Velop Mesh (6× MX4200 + 5× WHW03) | D7: Channel | E7: Phone
B8: Warranty Status | C8: In-Warranty | D8: Review Date | E8: 2026-05-25
B9: Case Type | C9: Connectivity | D9: Interaction Duration | E9: 3 hr 26 min (session) + May 19 follow-up
B10: Touch # (multi-touch case) | C10: 13 of 13 (final) | D10: Prior touches reviewed? | E10: Yes
B11: CSAT / Survey result | C11: 1 / 5 — Resolution Rate: No | D11: FCR / total contacts | E11: 4+ contacts (survey); 13+ recorded touches
B12: Total case time | C12: 15 hr 12 min (ticket) | D12: SLA status | E12: Breached
B13: Case Summary (customer issue & goal) | C13: Richard & Diana Stell (80+, hearing aids, 7,000 sq ft Dallas home, AT&T fiber): 7 weeks of mesh instability after Linksys advised replacing a failed WHW03 with MX4200 (6 purchased). Streaming, cameras, and pool equipment kept dropping. May 18: customer had replaced the AT&T modem per prior L2 advice and could not reconnect the mesh.
B14: Inherited context (what this agent received from prior touches) | C14: Escalated CAT case; customer had waited 3+ hours through three L1 calls that day after multiple missed callbacks. Prior L2 (Paolo Ebora) notes: 2 bad-RSSI nodes (-90/-93 dBm), AT&T SSID interference suspected (disabling never confirmed), sysinfo logs on ticket. Pre-ticket history (Recs 1-6, incl. $30 paid session) absent from the ticket.
B16: 2 · CATEGORY ASSESSMENTS
B17: 1. RESOLUTION / PROGRESS TOWARD RESOLUTION | F17: Weight: 30%
B18: Objective: Determine whether the interaction moved the customer meaningfully closer to resolution.
B19: Behavioral Indicator | C19: Assessment | D19: Evidence / Observation (quote or timestamp where possible)
B20: Issue resolved, or the strongest available outcome was achieved (RMA, valid escalation, limitation explained, education) | C20: Partial | D20: Internet restored May 18 (482-530 Mbps down); but primary complaint — streaming stability — never confirmed; TV still flashing red at session end; case closed RESOLVED May 19 anyway
B21: Reasonable troubleshooting was completed before any conclusion was reached | C21: Met | D21: Confirmed modem install, isolated fault away from ISP to MX4200 parent node before acting
B22: Clear, actionable next steps were provided to the customer | C22: Partial | D22: Callback agreed 4-5 PM CT May 19 — then missed; final email only asked customer to propose a new time
B23: Resolution path was appropriate for the situation and warranty status | C23: Partial | D23: Restoration path correct; closure path was not (RESOLVED on an unresolved case)
B24: Customer was moved meaningfully closer to a solution | C24: Met | D24: 4 child nodes added with documented RSSI; 1st-floor optimization and sequence reboot still outstanding
B25: ⚠ Does NOT count: customer simply ends call; generic KB sent without troubleshooting; warranty used as reason to stop helping; escalation as shortcut; unsupported ISP blame; 'monitor & call back' with no plan; ownership transferred without expectations or documentation.
B26: Suggested score (auto from indicators — advisory only; evaluator judgment prevails) | C26: =IF((COUNTIF(C20:C24,"Met")+COUNTIF(C20:C24,"Partial")+COUNTIF(C20:C24,"Missed"))=0,"",ROUND((COUNTIF(C20:C24,"Met")*5+COUNTIF(C20:C24,"Partial")*2.5)/(COUNTIF(C20:C24,"Met")+COUNTIF(C20:C24,"Partial")+COUNTIF(C20:C24,"Missed")),1))
B27: FINAL CATEGORY SCORE (0–5) | C27: 3 | D27: =IF(C27="","← enter score; anchor description appears here",CHOOSE(C27+1,"Agent actions delayed, prevented, or negatively impacted resolution","Little or no meaningful progress","Limited progress despite available troubleshooting paths","Partial progress made but opportunities missed","Significant progress made with clear next steps","Issue resolved or strongest available outcome achieved"))
B28: Category comments / coaching notes | C28: Real technical progress (internet restored) — judged in inherited context, a genuine recovery. Capped by unconfirmed primary complaint and premature closure.
B30: 2. TECHNICAL ACCURACY | F30: Weight: 20%
B31: Objective: Evaluate the quality of troubleshooting and technical guidance.
B32: Behavioral Indicator | C32: Assessment | D32: Evidence / Observation (quote or timestamp where possible)
B33: Symptoms were identified correctly | C33: Met | D33: Correctly framed issue as wireless coverage/stability, not internet speed
B34: Relevant diagnostic questions were asked | C34: Met | D34: Verified inventory (6× MX4200), modem state, node placement before troubleshooting
B35: Logical troubleshooting methodology was followed | C35: Met | D35: Logical narrowing: modem supplying internet → fault domain = parent node config
B36: Available tools were used appropriately | C36: Met | D36: ZOHO remote session 480107042; RSSI per node: 04512 -68, 02733 -61, 02853 -56, 16475 -59 dBm
B37: Information provided was technically accurate | C37: Met | D37: Speed and topology explanations accurate; overlap node (16267, -18 dBm) correctly identified
B38: Assumptions were validated; no unsupported conclusions | C38: Partial | D38: AT&T SSID disabling — prior touch's open isolation step — never confirmed during the session
B39: Root cause (or likely cause) was identified when possible | C39: Partial | D39: Overlap node found, but stability root cause left unconfirmed at close
B40: ⚠ Deduct for: incorrect technical information; skipped critical troubleshooting; misdiagnosis; unnecessary actions recommended; ISP or customer blamed without evidence; repeating basic steps the customer already completed.
B41: Suggested score (auto from indicators — advisory only; evaluator judgment prevails) | C41: =IF((COUNTIF(C33:C39,"Met")+COUNTIF(C33:C39,"Partial")+COUNTIF(C33:C39,"Missed"))=0,"",ROUND((COUNTIF(C33:C39,"Met")*5+COUNTIF(C33:C39,"Partial")*2.5)/(COUNTIF(C33:C39,"Met")+COUNTIF(C33:C39,"Partial")+COUNTIF(C33:C39,"Missed")),1))
B42: FINAL CATEGORY SCORE (0–5) | C42: 4 | D42: =IF(C42="","← enter score; anchor description appears here",CHOOSE(C42+1,"Agent actions delayed, prevented, or negatively impacted resolution","Little or no meaningful progress","Limited progress despite available troubleshooting paths","Partial progress made but opportunities missed","Significant progress made with clear next steps","Issue resolved or strongest available outcome achieved"))
B43: Category comments / coaching notes | C43: Strongest technical touch of the journey alongside Paolo Ebora's May 4 session. Close the loop on inherited open steps (AT&T SSID) next time.
...

Sheet Case Tracker
A1: CASE TRACKER — Multi-Case & Multi-Touch Log
A2: One row per touch. Reuse a Case ID across rows to track a multi-touch journey. Scores 0-5; Weighted % and Result calculate automatically. Pre-loaded: the TE00124020 / TE00127492 journey (see Multi-Touch Guide).
A3: =IF(A56=""," JOURNEY TEAM SCORE ▸ log touches below, then enter a Case ID + Outcome/Continuity in row 56"," LOADED JOURNEY TEAM SCORE ▸ "&A56&": "&TEXT(G56,"0.0%")&" "&UPPER(H56))
A4: Date | B4: Case ID | C4: Agent | D4: Touch # | E4: Res 30% | F4: Tech 20% | G4: Comm 15% | H4: Own 15% | I4: Esc 10% | J4: CX 5% | K4: Doc 5% | L4: Weighted | M4: Result | N4: Outcome / Notes | O4: Contribution Type | P4: Handoff Quality (0-5)
L5: =IF((COUNT(E5)+COUNT(F5)+COUNT(G5)+COUNT(H5)+COUNT(I5)+COUNT(J5)+COUNT(K5))=0,"",IFERROR(E5/5*0.3,0)+IFERROR(F5/5*0.2,0)+IFERROR(G5/5*0.15,0)+IFERROR(H5/5*0.15,0)+IFERROR(I5/5*0.1,0)+IFERROR(J5/5*0.05,0)+IFERROR(K5/5*0.05,0)) | M5: =IF(L5="","",IF(L5>=0.85,"Meets/Exceeds",IF(L5>=0.7,"Developing","Needs Improv.")))
L6: =IF((COUNT(E6)+COUNT(F6)+COUNT(G6)+COUNT(H6)+COUNT(I6)+COUNT(J6)+COUNT(K6))=0,"",IFERROR(E6/5*0.3,0)+IFERROR(F6/5*0.2,0)+IFERROR(G6/5*0.15,0)+IFERROR(H6/5*0.15,0)+IFERROR(I6/5*0.1,0)+IFERROR(J6/5*0.05,0)+IFERROR(K6/5*0.05,0)) | M6: =IF(L6="","",IF(L6>=0.85,"Meets/Exceeds",IF(L6>=0.7,"Developing","Needs Improv.")))
L7: =IF((COUNT(E7)+COUNT(F7)+COUNT(G7)+COUNT(H7)+COUNT(I7)+COUNT(J7)+COUNT(K7))=0,"",IFERROR(E7/5*0.3,0)+IFERROR(F7/5*0.2,0)+IFERROR(G7/5*0.15,0)+IFERROR(H7/5*0.15,0)+IFERROR(I7/5*0.1,0)+IFERROR(J7/5*0.05,0)+IFERROR(K7/5*0.05,0)) | M7: =IF(L7="","",IF(L7>=0.85,"Meets/Exceeds",IF(L7>=0.7,"Developing","Needs Improv.")))
L8: =IF((COUNT(E8)+COUNT(F8)+COUNT(G8)+COUNT(H8)+COUNT(I8)+COUNT(J8)+COUNT(K8))=0,"",IFERROR(E8/5*0.3,0)+IFERROR(F8/5*0.2,0)+IFERROR(G8/5*0.15,0)+IFERROR(H8/5*0.15,0)+IFERROR(I8/5*0.1,0)+IFERROR(J8/5*0.05,0)+IFERROR(K8/5*0.05,0)) | M8: =IF(L8="","",IF(L8>=0.85,"Meets/Exceeds",IF(L8>=0.7,"Developing","Needs Improv.")))
L9: =IF((COUNT(E9)+COUNT(F9)+COUNT(G9)+COUNT(H9)+COUNT(I9)+COUNT(J9)+COUNT(K9))=0,"",IFERROR(E9/5*0.3,0)+IFERROR(F9/5*0.2,0)+IFERROR(G9/5*0.15,0)+IFERROR(H9/5*0.15,0)+IFERROR(I9/5*0.1,0)+IFERROR(J9/5*0.05,0)+IFERROR(K9/5*0.05,0)) | M9: =IF(L9="","",IF(L9>=0.85,"Meets/Exceeds",IF(L9>=0.7,"Developing","Needs Improv.")))
L10: =IF((COUNT(E10)+COUNT(F10)+COUNT(G10)+COUNT(H10)+COUNT(I10)+COUNT(J10)+COUNT(K10))=0,"",IFERROR(E10/5*0.3,0)+IFERROR(F10/5*0.2,0)+IFERROR(G10/5*0.15,0)+IFERROR(H10/5*0.15,0)+IFERROR(I10/5*0.1,0)+IFERROR(J10/5*0.05,0)+IFERROR(K10/5*0.05,0)) | M10: =IF(L10="","",IF(L10>=0.85,"Meets/Exceeds",IF(L10>=0.7,"Developing","Needs Improv.")))
L11: =IF((COUNT(E11)+COUNT(F11)+COUNT(G11)+COUNT(H11)+COUNT(I11)+COUNT(J11)+COUNT(K11))=0,"",IFERROR(E11/5*0.3,0)+IFERROR(F11/5*0.2,0)+IFERROR(G11/5*0.15,0)+IFERROR(H11/5*0.15,0)+IFERROR(I11/5*0.1,0)+IFERROR(J11/5*0.05,0)+IFERROR(K11/5*0.05,0)) | M11: =IF(L11="","",IF(L11>=0.85,"Meets/Exceeds",IF(L11>=0.7,"Developing","Needs Improv.")))
L12: =IF((COUNT(E12)+COUNT(F12)+COUNT(G12)+COUNT(H12)+COUNT(I12)+COUNT(J12)+COUNT(K12))=0,"",IFERROR(E12/5*0.3,0)+IFERROR(F12/5*0.2,0)+IFERROR(G12/5*0.15,0)+IFERROR(H12/5*0.15,0)+IFERROR(I12/5*0.1,0)+IFERROR(J12/5*0.05,0)+IFERROR(K12/5*0.05,0)) | M12: =IF(L12="","",IF(L12>=0.85,"Meets/Exceeds",IF(L12>=0.7,"Developing","Needs Improv.")))
L13: =IF((COUNT(E13)+COUNT(F13)+COUNT(G13)+COUNT(H13)+COUNT(I13)+COUNT(J13)+COUNT(K13))=0,"",IFERROR(E13/5*0.3,0)+IFERROR(F13/5*0.2,0)+IFERROR(G13/5*0.15,0)+IFERROR(H13/5*0.15,0)+IFERROR(I13/5*0.1,0)+IFERROR(J13/5*0.05,0)+IFERROR(K13/5*0.05,0)) | M13: =IF(L13="","",IF(L13>=0.85,"Meets/Exceeds",IF(L13>=0.7,"Developing","Needs Improv.")))
L14: =IF((COUNT(E14)+COUNT(F14)+COUNT(G14)+COUNT(H14)+COUNT(I14)+COUNT(J14)+COUNT(K14))=0,"",IFERROR(E14/5*0.3,0)+IFERROR(F14/5*0.2,0)+IFERROR(G14/5*0.15,0)+IFERROR(H14/5*0.15,0)+IFERROR(I14/5*0.1,0)+IFERROR(J14/5*0.05,0)+IFERROR(K14/5*0.05,0)) | M14: =IF(L14="","",IF(L14>=0.85,"Meets/Exceeds",IF(L14>=0.7,"Developing","Needs Improv.")))
L15: =IF((COUNT(E15)+COUNT(F15)+COUNT(G15)+COUNT(H15)+COUNT(I15)+COUNT(J15)+COUNT(K15))=0,"",IFERROR(E15/5*0.3,0)+IFERROR(F15/5*0.2,0)+IFERROR(G15/5*0.15,0)+IFERROR(H15/5*0.15,0)+IFERROR(I15/5*0.1,0)+IFERROR(J15/5*0.05,0)+IFERROR(K15/5*0.05,0)) | M15: =IF(L15="","",IF(L15>=0.85,"Meets/Exceeds",IF(L15>=0.7,"Developing","Needs Improv.")))
L16: =IF((COUNT(E16)+COUNT(F16)+COUNT(G16)+COUNT(H16)+COUNT(I16)+COUNT(J16)+COUNT(K16))=0,"",IFERROR(E16/5*0.3,0)+IFERROR(F16/5*0.2,0)+IFERROR(G16/5*0.15,0)+IFERROR(H16/5*0.15,0)+IFERROR(I16/5*0.1,0)+IFERROR(J16/5*0.05,0)+IFERROR(K16/5*0.05,0)) | M16: =IF(L16="","",IF(L16>=0.85,"Meets/Exceeds",IF(L16>=0.7,"Developing","Needs Improv.")))
... L49: =IF((COUNT(E49)+COUNT(F49)+COUNT(G49)+COUNT(H49)+COUNT(I49)+COUNT(J49)+COUNT(K49))=0,"",IFERROR(E49/5*0.3,0)+IFERROR(F49/5*0.2,0)+IFERROR(G49/5*0.15,0)+IFERROR(H49/5*0.15,0)+IFERROR(I49/5*0.1,0)+IFERROR(J49/5*0.05,0)+IFERROR(K49/5*0.05,0)) | M49: =IF(L49="","",IF(L49>=0.85,"Meets/Exceeds",IF(L49>=0.7,"Developing","Needs Improv.")))
A51: TEAM AVERAGE | E51: =IFERROR(AVERAGE(E5:E49),"") | F51: =IFERROR(AVERAGE(F5:F49),"") | G51: =IFERROR(AVERAGE(G5:G49),"") | H51: =IFERROR(AVERAGE(H5:H49),"") | I51: =IFERROR(AVERAGE(I5:I49),"") | J51: =IFERROR(AVERAGE(J5:J49),"") | K51: =IFERROR(AVERAGE(K5:K49),"") | L51: =IFERROR(AVERAGE(L5:L49),"") | N51: Average of logged touches
A53: TEAM / JOURNEY SCORES — MULTI-TOUCH CASES
A54: Team Score = 50% × average touch weighted score + 30% × (Journey Outcome ÷ 5) + 20% × (Continuity & Handoffs ÷ 5). Outcome and Continuity are evaluator-judged 0-5 — anchors on the Multi-Touch Guide sheet. The Team Score rates the CHAIN; it feeds team coaching and recognition, never individual discipline.
A55: Journey / Case ID(s) | C55: Touches | D55: Avg Touch % | E55: Outcome (0-5) | F55: Continuity (0-5) | G55: TEAM SCORE | H55: Band | I55: Journey notes (where the chain broke / recovered)
C56: =IF(A56="","",COUNTIF(B5:B49,A56)) | D56: =IF(A56="","",IFERROR(AVERAGEIF(B5:B49,A56,L5:L49),"")) | G56: =IF(OR(A56="",D56="",E56="",F56=""),"",0.5*D56+0.3*(E56/5)+0.2*(F56/5)) | H56: =IF(G56="","",IF(G56>=0.85,"Meets/Exceeds",IF(G56>=0.7,"Developing","Needs Improvement")))
C57: =IF(A57="","",COUNTIF(B5:B49,A57)) | D57: =IF(A57="","",IFERROR(AVERAGEIF(B5:B49,A57,L5:L49),"")) | G57: =IF(OR(A57="",D57="",E57="",F57=""),"",0.5*D57+0.3*(E57/5)+0.2*(F57/5)) | H57: =IF(G57="","",IF(G57>=0.85,"Meets/Exceeds",IF(G57>=0.7,"Developing","Needs Improv.")))
C58: =IF(A58="","",COUNTIF(B5:B49,A58)) | D58: =IF(A58="","",IFERROR(AVERAGEIF(B5:B49,A58,L5:L49),"")) | G58: =IF(OR(A58="",D58="",E58="",F58=""),"",0.5*D58+0.3*(E58/5)+0.2*(F58/5)) | H58: =IF(G58="","",IF(G58>=0.85,"Meets/Exceeds",IF(G58>=0.7,"Developing","Needs Improv.")))
C59: =IF(A59="","",COUNTIF(B5:B49,A59)) | D59: =IF(A59="","",IFERROR(AVERAGEIF(B5:B49,A59,L5:L49),"")) | G59: =IF(OR(A59="",D59="",E59="",F59=""),"",0.5*D59+0.3*(E59/5)+0.2*(F59/5)) | H59: =IF(G59="","",IF(G59>=0.85,"Meets/Exceeds",IF(G59>=0.7,"Developing","Needs Improv.")))
A60: Template rows: type a Case ID in the first column — Touches and Avg Touch % auto-fill from the log above, then judge Outcome and Continuity (0-5). For journeys spanning multiple Case IDs (like the pre-loaded one), enter the Avg Touch % formula over the journey's row range manually.

Sheet Lists
A1: Audit / Review Type | B1: Contact iteration | C1: Resolution status (detailed) | D1: Root-cause domain | E1: Process driver | F1: Product driver | G1: System / tooling driver | J1: Dropdown option source for the Scoring Form (Section 8 + Outcome). Unhide to edit options.
A2: Random Call | B2: 1st about the concern | C2: Resolved | D2: None | E2: None | F2: None | G2: None
A3: Scheduled / Side-by-side | B3: 2nd about the concern | C3: Unresolved (properly isolated) | D3: People | E3: Troubleshooting – Instructions | F3: Performance – Specific IRC | G3: Public – Website
A4: Calibration | B4: 3rd about the concern | C4: Unresolved (with missing steps) | D4: Process | E4: Troubleshooting – Timeline | F4: Performance – Difficult to Install | G4: Public – App/Cloud
A5: Complaint | B5: More than 3x about the concern | C5: Unresolved (wrong troubleshooting path) | D5: Product | E5: RMA – Logistics | F5: Performance – Defective Device | G5: Public – IVR
A6: Investigation | C6: Unresolved (declined sales pitch — valid) | D6: System | E6: RMA – Timeline | F6: Performance – Poor Performance | G6: Internal – Salesforce/CRM
A7: CSAT | C7: Unresolved (declined sales pitch — invalid) | E7: RMA – Terms & Conditions | F7: Design – Aesthetics | G7: Internal – CSC
A8: DSAT | C8: Unresolved (disconnected / line release) | E8: Refund – Logistics | F8: Design – Compatibility | G8: Internal – Oracle
A9: FCR | E9: Refund – Timeline | F9: Beyond Product Support Scope | G9: Internal – Agent Portal
A10: Spot Check | E10: Refund – Terms & Conditions | G10: Internal – SN Look-up
A11: ARR | E11: Follow-through – Callback
A12: Bounceback Spot Check | E12: Follow-through – Timeline
A13: Ghost / Disconnected Contact | E13: Sales – Limited Warranty
A14: Misdirected Contact | E14: Sales – Charging Process
A15: Service Offering Spot Check | E15: Beyond Support Scope
A16: Refunds Spot Check
A17: Newbie Spot Check
